Workbook
Name SECC: TABLAS!$B$7:$B$21
Name DIAM_COND: TABLAS!$O$7:$O$21
Name TABLA2: TABLAS!$C$7:$N$21
Name MET_DESC: TABLAS!$B$26:$B$31
Name MET_COD: TABLAS!$C$26:$C$31
Name FT_T: TABLAS!$B$36:$B$46
Name FT_AIR: TABLAS!$C$36:$C$46
Name FT_TER: TABLAS!$D$36:$D$46
Name FA_N: TABLAS!$B$52:$B$63
Name FA_F: TABLAS!$C$52:$C$63
Name ITM: TABLAS!$B$68:$B$86
Name TUBO_NOM: TABLAS!$B$91:$B$98
Name TUBO_A40: TABLAS!$D$91:$D$98
Name SIS_NOM: TABLAS!$B$104:$B$106
Name SIS_V: TABLAS!$C$104:$C$106
Name SIS_K: TABLAS!$D$104:$D$106
Name SIS_K2: TABLAS!$E$104:$E$106
Name SIS_CARG: TABLAS!$F$104:$F$106
Name SIS_ACT: TABLAS!$G$104:$G$106
Name TRAMO_NOM: TABLAS!$B$112:$B$113
Name TRAMO_LIM: TABLAS!$C$112:$C$113
Name COND_NOM: TABLAS!$B$118:$B$120
Name SMIN: TABLAS!$B$124:$B$129
Name VAR_NOM: TABLAS!$B$135:$B$140
Name VAR_D: TABLAS!$C$135:$C$140
Name VAR_MAT: TABLAS!$D$135:$D$140
Name VAR_DMIN: TABLAS!$E$135:$E$140
Name TRAT_NOM: TABLAS!$B$146:$B$153
Name TRAT_RHO: TABLAS!$C$146:$C$153
Name TRAT_DOS: TABLAS!$D$146:$D$153
Name TRAT_SRC: TABLAS!$E$146:$E$153
Name OBJ_NOM: TABLAS!$B$158:$B$162
Name OBJ_R: TABLAS!$C$158:$C$162
Name OBJ_REF: TABLAS!$D$158:$D$162
Name LAM_N: TABLAS!$B$168:$B$177
Name LAM_L: TABLAS!$C$168:$C$177
Name LAMQ_N: TABLAS!$B$181:$B$189
Name LAMQ_L: TABLAS!$C$181:$C$189
Name T17_HASTA: TABLAS!$B$195:$B$202
Name T17_SEC: TABLAS!$C$195:$C$202
Name FM_NOM: TABLAS!$B$207:$B$210
Name FM_VAL: TABLAS!$C$207:$C$210
Name LUM_NOM: TABLAS!$B$216:$B$227
Name LUM_DIS: TABLAS!$C$216:$C$227
Name LUM_FLU: TABLAS!$D$216:$D$227
Name LUM_W: TABLAS!$E$216:$E$227
Name LUM_RA: TABLAS!$F$216:$F$227
Name CU_TAB: TABLAS!$C$233:$O$252
Name CU_K: TABLAS!$C$253:$O$253
Name REFL_NOM: TABLAS!$B$259:$B$268
Name EM_NOM: TABLAS!$B$274:$B$561
Name EM_E: TABLAS!$C$274:$C$561
Name EM_UGR: TABLAS!$D$274:$D$561
Name EM_UO: TABLAS!$E$274:$E$561
Name EM_RA: TABLAS!$F$274:$F$561
Name EM_KEY: TABLAS!$R$274:$R$561
Name EM_S1: TABLAS!$B$274:$B$288
Name EM_S2: TABLAS!$B$289:$B$316
Name EM_S3: TABLAS!$B$317:$B$361
Name EM_S4: TABLAS!$B$362:$B$496

Sheet INICIO
B2: CALCULADORAS IIEE ALF
B3: Pozo a tierra (Wenner) · Iluminación EM.010-2019 · Caída de tensión y sección de conductor (CNE-U) · v1.0.0
B4: ALF_BIM · www.alfbim.com · Herramienta gratuita
B6: DATOS DEL PROYECTO (aparecen en el encabezado de cada reporte)
B7: Proyecto | D7: EDIFICIO DE VIVIENDA Y OFICINAS DE 4 NIVELES (EJEMPLO)
B8: Propietario | D8: —
B9: Ubicación | D9: Chota, Cajamarca
B10: Proyectista | D10: Ing.
B11: CIP
B12: Fecha | D12: 46317
B14: HOJAS DE CÁLCULO
B15: =HYPERLINK("#'POZO_TIERRA'!A1","→ POZO_TIERRA") | D15: Pozo a tierra: resistividad por el método de Wenner (hasta 8 lecturas en dos direcciones), resistividad de diseño, verificación de la varilla (CNE-U 060-702), resistencia de un pozo con relleno tratado, número de pozos para la resistencia objetivo (060-712, BS 7430), comparación de tratamientos y metrado del relleno.
B16: =HYPERLINK("#'ILUMINACION'!A1","→ ILUMINACION") | D16: Iluminación de un ambiente por el método de los lúmenes con los requisitos de la EM.010-2019 (Em, UGRL, Uo, Ra): índice del local, CU, factor de mantenimiento, número y distribución de luminarias, verificación de Em, de la separación y del Ra, potencia y W/m², y plano de distribución.
B17: =HYPERLINK("#'ILUM_AMBIENTES'!A1","→ ILUM_AMBIENTES") | D17: Cuadro de iluminación de hasta 25 ambientes de un proyecto (listas de la EM.010-2019 y catálogo de luminarias).
B18: =HYPERLINK("#'CAIDA_TENSION'!A1","→ CAIDA_TENSION") | D18: Caída de tensión y sección de un conductor: corriente, ITM, capacidad (Tabla 2, 5A y 5C), sección por caída (050-102), sección adoptada, longitud máxima, conductor de protección, tubería y tabla de verificación.
B19: =HYPERLINK("#'CIRCUITOS'!A1","→ CIRCUITOS") | D19: Cuadro de hasta 25 alimentadores y circuitos con su ITM, sección, caída parcial y acumulada (límite de 4 %).
B20: =HYPERLINK("#'TABLAS'!A1","→ TABLAS") | D20: Tablas del CNE-U, EM.010, BS 7430, rellenos de pozo, luminarias y CU (con su fuente).
B22: CÓMO SE USA
B23: Celda amarilla con texto azul | D23: Dato que usted ingresa (o elige de la lista desplegable).
B24: Celda gris con texto negro | D24: Resultado calculado. No se modifica.
B25: Celda celeste | D25: Resultado principal de la hoja.
B26: CUMPLE / NO CUMPLE / AVISO | D26: Verificación con la norma o con un criterio indicado en la nota de la fila.
B27: Celdas opcionales | D27: Si se dejan vacías se usa el valor de la norma o del catálogo; si se llenan, mandan.
B28: Protección | D28: Las hojas están protegidas SIN contraseña (Revisar > Desproteger hoja) para no borrar fórmulas por error.
B30: REPORTE EN PDF
B31: 1. Llene los datos del proyecto arriba y los de la hoja que va a imprimir.
B32: 2. Archivo → Exportar → Crear documento PDF/XPS (o Archivo → Imprimir → Microsoft Print to PDF).
B33: 3. Cada hoja ya está en A4, ajustada al ancho, con encabezado, número de página y pie de ALF_BIM.
B34: 4. Para un solo PDF con varias hojas: seleccione las pestañas con Ctrl + clic antes de exportar.
B36: NORMAS Y CRITERIOS
B37: CNE-Utilización 2006 (R.M. 037-2006-MEM/DM, mod. R.M. 175-2008-MEM/DM): Regla 050-102 (caída de tensión: 2.5 % alimentador, 2.5 % derivado, 4 % total), Tabla 2 (capacidad de corriente, Cu PVC 70 °C), Tablas 5A y 5C (factores), Regla 030-002 (sección mínima), Reglas 060-702 y 060-712 (electrodos de puesta a tierra, ≤ 25 Ω).
B38: NTE EM.010 Instalaciones Eléctricas Interiores (R.M. 083-2019-VIVIENDA): Art. 5 (definiciones), Art. 6 (requisitos de iluminación y factor de mantenimiento) y Anexo «Requisitos mínimos de iluminación» (Em, UGRL, Uo, Ra). Reemplazó la tabla de iluminancias de 2006 (con calidad A–E) que todavía usan muchas plantillas.
B39: IEEE Std 81 (método de Wenner), IEEE Std 80 (resistencia de varilla y de electrodo con relleno), BS 7430:1998 (varillas en paralelo), IEC 60364-5-54 (conductor de protección).
B40: Las tablas de conductores son las mismas de MaximaDemandaALF (ALF-13), cotejadas con el texto oficial del CNE-U.
B42: AVISO: esta es una herramienta gratuita de apoyo al cálculo. En el Perú, los planos y memorias de instalaciones eléctricas los firma un ingeniero electricista o mecánico electricista colegiado, que debe revisar los datos y los resultados. ALF_BIM no se responsabiliza por el uso que se dé a los resultados.
B44: ¿Necesita el cuadro de cargas, la máxima demanda y la memoria de IIEE completa en Word? MaximaDemandaALF. ¿Circuitos, unifilar y metrados en Revit? ElectricasALF. Más en www.alfbim.com

Sheet POZO_TIERRA
B1: POZO A TIERRA · RESISTIVIDAD (WENNER) Y NÚMERO DE POZOS
B2: ALF_BIM · Calculadoras IIEE ALF · CNE-U Sección 060 · IEEE 80/81 · BS 7430 · v1.0.0
B3: Proyecto | C3: =INICIO!$D$7
B4: Ubicación | C4: =INICIO!$D$9
B5: Sistema | C5: SISTEMA DE PUESTA A TIERRA DEL TABLERO GENERAL (EJEMPLO)
B6: Proyectista | C6: =INICIO!$D$10&IF(INICIO!$D$11="",""," · CIP "&INICIO!$D$11)
B7: Fecha | C7: =INICIO!$D$12
B10: 1. MEDICIÓN DE LA RESISTIVIDAD DEL TERRENO · MÉTODO DE WENNER (IEEE Std 81)
B11: Telurómetro y fecha de la medición | D11: Telurómetro digital · 15/10/2026 (época seca)
B12: Profundidad de hincado de las picas de prueba | C12: b | D12: 0.2 | E12: m | F12: Con b ≤ a/20 la fórmula se reduce a ρ = 2π·a·R
B13: ρ = 4π·a·R / [1 + 2a/√(a² + 4b²) − a/√(a² + b²)] (a: separación entre picas; R: lectura del telurómetro). Mida en dos direcciones perpendiculares sobre el área del pozo.
B14: Lectura | C14: a (m) | D14: R dirección 1 (Ω) | E14: R dirección 2 (Ω) | F14: ρ dirección 1 (Ω·m) | G14: ρ dirección 2 (Ω·m) | H14: ρ media (Ω·m)
B15: Lectura 1 | C15: 1 | D15: 25.4 | E15: 27.1 | F15: =IF(OR(C15="",D15=""),"",4*PI()*C15*D15/(1+2*C15/SQRT(C15^2+4*$D$12^2)-C15/SQRT(C15^2+$D$12^2))) | G15: =IF(OR(C15="",E15=""),"",4*PI()*C15*E15/(1+2*C15/SQRT(C15^2+4*$D$12^2)-C15/SQRT(C15^2+$D$12^2))) | H15: =IF(COUNT(F15:G15)=0,"",AVERAGE(F15:G15))
B16: Lectura 2 | C16: 2 | D16: 13.6 | E16: 14.5 | F16: =IF(OR(C16="",D16=""),"",4*PI()*C16*D16/(1+2*C16/SQRT(C16^2+4*$D$12^2)-C16/SQRT(C16^2+$D$12^2))) | G16: =IF(OR(C16="",E16=""),"",4*PI()*C16*E16/(1+2*C16/SQRT(C16^2+4*$D$12^2)-C16/SQRT(C16^2+$D$12^2))) | H16: =IF(COUNT(F16:G16)=0,"",AVERAGE(F16:G16))
B17: Lectura 3 | C17: 3 | D17: 9.8 | E17: 10.2 | F17: =IF(OR(C17="",D17=""),"",4*PI()*C17*D17/(1+2*C17/SQRT(C17^2+4*$D$12^2)-C17/SQRT(C17^2+$D$12^2))) | G17: =IF(OR(C17="",E17=""),"",4*PI()*C17*E17/(1+2*C17/SQRT(C17^2+4*$D$12^2)-C17/SQRT(C17^2+$D$12^2))) | H17: =IF(COUNT(F17:G17)=0,"",AVERAGE(F17:G17))
B18: Lectura 4 | C18: 4 | D18: 7.6 | E18: 7.9 | F18: =IF(OR(C18="",D18=""),"",4*PI()*C18*D18/(1+2*C18/SQRT(C18^2+4*$D$12^2)-C18/SQRT(C18^2+$D$12^2))) | G18: =IF(OR(C18="",E18=""),"",4*PI()*C18*E18/(1+2*C18/SQRT(C18^2+4*$D$12^2)-C18/SQRT(C18^2+$D$12^2))) | H18: =IF(COUNT(F18:G18)=0,"",AVERAGE(F18:G18))
B19: Lectura 5 | C19: 6 | D19: 5.3 | E19: 5.5 | F19: =IF(OR(C19="",D19=""),"",4*PI()*C19*D19/(1+2*C19/SQRT(C19^2+4*$D$12^2)-C19/SQRT(C19^2+$D$12^2))) | G19: =IF(OR(C19="",E19=""),"",4*PI()*C19*E19/(1+2*C19/SQRT(C19^2+4*$D$12^2)-C19/SQRT(C19^2+$D$12^2))) | H19: =IF(COUNT(F19:G19)=0,"",AVERAGE(F19:G19))
B20: Lectura 6 | C20: 8 | D20: 4.1 | E20: 4.2 | F20: =IF(OR(C20="",D20=""),"",4*PI()*C20*D20/(1+2*C20/SQRT(C20^2+4*$D$12^2)-C20/SQRT(C20^2+$D$12^2))) | G20: =IF(OR(C20="",E20=""),"",4*PI()*C20*E20/(1+2*C20/SQRT(C20^2+4*$D$12^2)-C20/SQRT(C20^2+$D$12^2))) | H20: =IF(COUNT(F20:G20)=0,"",AVERAGE(F20:G20))
B21: Lectura 7 | F21: =IF(OR(C21="",D21=""),"",4*PI()*C21*D21/(1+2*C21/SQRT(C21^2+4*$D$12^2)-C21/SQRT(C21^2+$D$12^2))) | G21: =IF(OR(C21="",E21=""),"",4*PI()*C21*E21/(1+2*C21/SQRT(C21^2+4*$D$12^2)-C21/SQRT(C21^2+$D$12^2))) | H21: =IF(COUNT(F21:G21)=0,"",AVERAGE(F21:G21))
B22: Lectura 8 | F22: =IF(OR(C22="",D22=""),"",4*PI()*C22*D22/(1+2*C22/SQRT(C22^2+4*$D$12^2)-C22/SQRT(C22^2+$D$12^2))) | G22: =IF(OR(C22="",E22=""),"",4*PI()*C22*E22/(1+2*C22/SQRT(C22^2+4*$D$12^2)-C22/SQRT(C22^2+$D$12^2))) | H22: =IF(COUNT(F22:G22)=0,"",AVERAGE(F22:G22))
B36: Lecturas válidas | C36: n | D36: =COUNT($H$15:$H$22)
B37: Resistividad media de las lecturas | C37: ρm | D37: =IF($D$36=0,0,AVERAGE($H$15:$H$22)) | E37: Ω·m
B38: Resistividad máxima de las lecturas | C38: ρmáx | D38: =IF($D$36=0,0,MAX($F$15:$G$22)) | E38: Ω·m
B39: Resistividad mínima de las lecturas | C39: ρmín | D39: =IF($D$36=0,0,MIN($F$15:$G$22)) | E39: Ω·m
B40: Homogeneidad del terreno | D40: =IF($D$36=0,"Ingrese las lecturas",IF(($D$38-$D$39)/$D$37>0.5,"AVISO: el terreno es heterogéneo (estratificado). El modelo homogéneo es aproximado: use el criterio conservador.","Terreno aproximadamente homogéneo"))
B42: 2. RESISTIVIDAD DE DISEÑO
B43: Criterio para la resistividad de diseño | D43: Promedio de las lecturas
B44: Resistividad manual (solo con «Valor manual») | C44: ρman | E44: Ω·m | F44: Por ejemplo, de un estudio de suelos
B45: Resistividad seleccionada | C45: ρsel | D45: =IF($D$43="Valor manual",N($D$44),IF(LEFT($D$43,6)="Máximo",$D$38,$D$37)) | E45: Ω·m
B46: Factor estacional | C46: Ke | D46: 1 | F46: 1.0 si se midió en época seca; 1.2 a 2.0 si se midió con el terreno húmedo (criterio del proyectista)
B47: RESISTIVIDAD DE DISEÑO | C47: ρ | D47: =$D$45*$D$46 | E47: Ω·m
B49: 3. ELECTRODO Y POZO (CNE-U Regla 060-702)
B50: Varilla (electrodo) | D50: Cobre Ø 5/8" (15.9 mm)
B51: Diámetro de la varilla | C51: d | D51: =INDEX(VAR_D,MATCH($D$50,VAR_NOM,0)) | E51: m
B52: Material | D52: =INDEX(VAR_MAT,MATCH($D$50,VAR_NOM,0))
B53: Longitud de la varilla | C53: L | D53: 2.4 | E53: m | F53: Práctica comercial: 2.40 m
B54: Profundidad de la cabeza de la varilla bajo el piso terminado | C54: t | D54: 0.2 | E54: m
B55: Longitud ≥ 2 m · 060-702(3)(b) | C55: =IF($D$53>=2,"CUMPLE","NO CUMPLE")
B56: Diámetro mínimo: 16 mm (5/8") acero-cobre; 13 mm (1/2") cobre · 060-702(3)(a) | C56: =IF($D$51>=INDEX(VAR_DMIN,MATCH($D$50,VAR_NOM,0))-0.0001,"CUMPLE","NO CUMPLE")
B57: La varilla alcanza 2.5 m de profundidad (t + L ≥ 2.5 m) · 060-702(3)(d) | C57: =IF($D$54+$D$53>=2.5,"CUMPLE","NO CUMPLE")
...

Sheet ILUMINACION
B1: ILUMINACIÓN DE INTERIORES · MÉTODO DE LOS LÚMENES
B2: ALF_BIM · Calculadoras IIEE ALF · NTE EM.010-2019 (R.M. 083-2019-VIVIENDA) · v1.0.0
B3: Proyecto | C3: =INICIO!$D$7
B4: Ubicación | C4: =INICIO!$D$9
B5: Ambiente | C5: OFICINA ADMINISTRATIVA · 1.er PISO (EJEMPLO)
B6: Proyectista | C6: =INICIO!$D$10&IF(INICIO!$D$11="",""," · CIP "&INICIO!$D$11)
B7: Fecha | C7: =INICIO!$D$12
B10: 1. REQUISITOS DE LA EM.010 (Art. 6 y Anexo «Requisitos mínimos de iluminación»)
B11: Uso de la edificación (sección del Anexo) | D11: 6. Oficinas
B12: Tipo de interior, tarea o actividad | D12: Escritura, mecanografía, lectura, procesamiento de datos
B13: Fila en la tabla | D13: =IFERROR(MATCH($D$11&"|"&$D$12,EM_KEY,0),0)
B14: Iluminancia mantenida mínima de la norma | C14: Em | D14: =IF($D$13=0,"Elija el ambiente de la lista",INDEX(EM_E,$D$13)) | E14: lx | F14: Art. 6.6 y 6.7: valor mínimo medio mantenido
B15: Índice de deslumbramiento unificado máximo | C15: UGRL | D15: =IF($D$13=0,"—",INDEX(EM_UGR,$D$13)) | F15: Verifíquelo con la fotometría (DIALux, Relux)
B16: Uniformidad mínima (Emín/Em) | C16: Uo | D16: =IF($D$13=0,"—",INDEX(EM_UO,$D$13)) | F16: Verifíquela con la fotometría
B17: Índice de reproducción cromática mínimo | C17: Ra | D17: =IF($D$13=0,"—",INDEX(EM_RA,$D$13))
B18: Iluminancia de diseño del proyectista (opcional) | C18: Eman | E18: lx | F18: Solo si desea diseñar con un valor mayor
B19: ILUMINANCIA DE DISEÑO | C19: E | D19: =IF(N($D$18)>0,$D$18,IF(ISNUMBER($D$14),$D$14,0)) | E19: lx
B20: La iluminancia de diseño no es menor que la de la norma | C20: =IF(AND($D$19>0,OR(NOT(ISNUMBER($D$14)),$D$19>=$D$14)),"CUMPLE","Elija el ambiente de la lista")
B22: 2. GEOMETRÍA DEL LOCAL
B23: Largo del local | C23: a | D23: 6 | E23: m
B24: Ancho del local | C24: b | D24: 5 | E24: m
B25: Altura del local (piso a techo) | C25: H | D25: 2.8 | E25: m
B26: Altura del plano de trabajo | C26: hpt | D26: 0.8 | E26: m | F26: 0.80 m en escritorios y aulas; 0.00 m en pasillos
B27: Suspensión de la luminaria bajo el techo | C27: hs | D27: 0 | E27: m | F27: 0 si es empotrada o adosada
B28: Área del local | C28: A | D28: =$D$23*$D$24 | E28: m²
B29: Altura de montaje sobre el plano de trabajo | C29: h | D29: =$D$25-$D$26-$D$27 | E29: m
B30: Altura de montaje positiva | C30: =IF($D$29>0,"CUMPLE","NO CUMPLE")
B31: Índice del local K = a·b / [h·(a + b)] | C31: K | D31: =IF($D$29>0,$D$23*$D$24/($D$29*($D$23+$D$24)),0)
B33: 3. REFLECTANCIAS, LUMINARIA Y FACTORES
B34: Reflectancias techo / paredes / suelo | C34: ρ | D34: 0.7 / 0.5 / 0.2
B35: Luminaria (catálogo de TABLAS) | D35: Panel LED 60×60 cm, 40 W
B36: Flujo luminoso de la luminaria del fabricante (opcional) | C36: Φman | E36: lm
B37: Potencia de la luminaria del fabricante (opcional) | C37: Pman | E37: W
B38: Ra de la luminaria del fabricante (opcional) | C38: Ra,man
B39: Fila del catálogo | D39: =MATCH($D$35,LUM_NOM,0)
B40: Flujo luminoso por luminaria | C40: Φ | D40: =IF(N($D$36)>0,$D$36,INDEX(LUM_FLU,$D$39)) | E40: lm
B41: Potencia por luminaria | C41: P | D41: =IF(N($D$37)>0,$D$37,INDEX(LUM_W,$D$39)) | E41: W
B42: Ra de la luminaria | C42: Ra | D42: =IF(N($D$38)>0,$D$38,INDEX(LUM_RA,$D$39))
B43: Distribución luminosa | D43: =IF(INDEX(LUM_DIS,$D$39)=2,"Concentrada","Difusa")
B44: Factor de utilización de la tabla genérica (interpolado) | C44: CUt | D44: =P44 | F44: Tabla referencial de ALF_BIM (ver TABLAS) | K44: =MIN(5,MAX(0.3,$D$31)) | L44: =MATCH(K44,CU_K,1) | M44: =(INDEX(LUM_DIS,$D$39)-1)*10+MATCH($D$34,REFL_NOM,0) | N44: =INDEX(CU_TAB,M44,L44) | O44: =INDEX(CU_TAB,M44,MIN(L44+1,13)) | P44: =IF(L44>=13,N44,N44+(O44-N44)*(K44-INDEX(CU_K,L44))/(INDEX(CU_K,L44+1)-INDEX(CU_K,L44)))
...

Sheet ILUM_AMBIENTES
B1: CUADRO DE ILUMINACIÓN POR AMBIENTES · MÉTODO DE LOS LÚMENES · NTE EM.010-2019
B2: ALF_BIM · Calculadoras IIEE ALF · v1.0.0
B3: Proyecto | D3: =INICIO!$D$7
B4: Ubicación | D4: =INICIO!$D$9
B5: Proyectista | D5: =INICIO!$D$10&IF(INICIO!$D$11="",""," · CIP "&INICIO!$D$11)
B6: Fecha | D6: =INICIO!$D$12
B8: DATOS COMUNES
C9: Plano de trabajo por defecto (m) | F9: 0.8 | I9: Elija el uso y luego el tipo de interior (la lista se filtra por uso). Em de la EM.010-2019. Plano de trabajo: 0.80 m en escritorios y aulas, 0.00 m en pasillos, escaleras y baños (columna opcional por ambiente). FM: 0.70 normal, 0.80 limpio (oficinas, aulas, salud). Luminarias del catálogo de TABLAS (edítelo con los datos del fabricante). Más detalle: hoja ILUMINACION.
C10: Reflectancias techo/pared/suelo | F10: 0.7 / 0.5 / 0.2
C11: Factor de mantenimiento | F11: 0.7
B13: N.° | C13: Ambiente | D13: Uso (EM.010) | E13: Tipo de interior, tarea o actividad | F13: Em norma (lx) | G13: Largo a (m) | H13: Ancho b (m) | I13: Altura H (m) | J13: Plano de trabajo (m) (opcional) | K13: Luminaria | L13: K | M13: CU | N13: N calc. | O13: N propuesto (opcional) | P13: N adoptado | Q13: Em obtenida (lx) | R13: Potencia (W) | S13: W/m² | T13: Estado
B14: 1 | C14: Sala-comedor | D14: 1. Vivienda | E14: Sala, sala de estar | F14: =IF(C14="","",IF(W14=0,"Elija el tipo",INDEX(EM_E,W14))) | G14: 6 | H14: 4 | I14: 2.6 | K14: Plafón LED 24 W | L14: =IF(X14=1,Y14,"") | M14: =IF(X14=1,AF14,"") | N14: =IF(X14=1,F14*G14*H14/(INDEX(LUM_FLU,Z14)*M14*$F$11),"") | P14: =IF(X14=1,IF(N(O14)>0,ROUND(O14,0),MAX(1,ROUNDUP(N14,0))),"") | Q14: =IF(X14=1,P14*INDEX(LUM_FLU,Z14)*M14*$F$11/(G14*H14),"") | R14: =IF(X14=1,P14*INDEX(LUM_W,Z14),"") | S14: =IF(X14=1,R14/(G14*H14),"") | T14: =IF(C14="","",IF(X14=0,"REVISAR datos",IF(Q14>=F14,IF(Y14<0.3,"AVISO: K < 0.3","CUMPLE"),"NO CUMPLE"))) | W14: =IFERROR(MATCH(D14&"|"&E14,EM_KEY,0),0) | X14: =IF(AND(C14<>"",ISNUMBER(F14),N(G14)>0,N(H14)>0,N(I14)>AH14,K14<>""),1,0) | Y14: =IF(X14=1,G14*H14/((I14-AH14)*(G14+H14)),0) | Z14: =IF(X14=1,MATCH(K14,LUM_NOM,0),1) | AA14: =MIN(5,MAX(0.3,Y14)) | AB14: =MATCH(AA14,CU_K,1) | AC14: =(INDEX(LUM_DIS,Z14)-1)*10+MATCH($F$10,REFL_NOM,0) | AD14: =INDEX(CU_TAB,AC14,AB14) | AE14: =INDEX(CU_TAB,AC14,MIN(AB14+1,13)) | AF14: =IF(AB14>=13,AD14,AD14+(AE14-AD14)*(AA14-INDEX(CU_K,AB14))/(INDEX(CU_K,AB14+1)-INDEX(CU_K,AB14))) | AH14: =IF(ISNUMBER(J14),J14,$F$9)
B15: 2 | C15: Cocina | D15: 1. Vivienda | E15: Cocina | F15: =IF(C15="","",IF(W15=0,"Elija el tipo",INDEX(EM_E,W15))) | G15: 3.5 | H15: 2.8 | I15: 2.6 | K15: Plafón LED 24 W | L15: =IF(X15=1,Y15,"") | M15: =IF(X15=1,AF15,"") | N15: =IF(X15=1,F15*G15*H15/(INDEX(LUM_FLU,Z15)*M15*$F$11),"") | P15: =IF(X15=1,IF(N(O15)>0,ROUND(O15,0),MAX(1,ROUNDUP(N15,0))),"") | Q15: =IF(X15=1,P15*INDEX(LUM_FLU,Z15)*M15*$F$11/(G15*H15),"") | R15: =IF(X15=1,P15*INDEX(LUM_W,Z15),"") | S15: =IF(X15=1,R15/(G15*H15),"") | T15: =IF(C15="","",IF(X15=0,"REVISAR datos",IF(Q15>=F15,IF(Y15<0.3,"AVISO: K < 0.3","CUMPLE"),"NO CUMPLE"))) | W15: =IFERROR(MATCH(D15&"|"&E15,EM_KEY,0),0) | X15: =IF(AND(C15<>"",ISNUMBER(F15),N(G15)>0,N(H15)>0,N(I15)>AH15,K15<>""),1,0) | Y15: =IF(X15=1,G15*H15/((I15-AH15)*(G15+H15)),0) | Z15: =IF(X15=1,MATCH(K15,LUM_NOM,0),1) | AA15: =MIN(5,MAX(0.3,Y15)) | AB15: =MATCH(AA15,CU_K,1) | AC15: =(INDEX(LUM_DIS,Z15)-1)*10+MATCH($F$10,REFL_NOM,0) | AD15: =INDEX(CU_TAB,AC15,AB15) | AE15: =INDEX(CU_TAB,AC15,MIN(AB15+1,13)) | AF15: =IF(AB15>=13,AD15,AD15+(AE15-AD15)*(AA15-INDEX(CU_K,AB15))/(INDEX(CU_K,AB15+1)-INDEX(CU_K,AB15))) | AH15: =IF(ISNUMBER(J15),J15,$F$9)
B16: 3 | C16: Dormitorio principal | D16: 1. Vivienda | E16: Dormitorio | F16: =IF(C16="","",IF(W16=0,"Elija el tipo",INDEX(EM_E,W16))) | G16: 4 | H16: 3.5 | I16: 2.6 | K16: Plafón LED 18 W | L16: =IF(X16=1,Y16,"") | M16: =IF(X16=1,AF16,"") | N16: =IF(X16=1,F16*G16*H16/(INDEX(LUM_FLU,Z16)*M16*$F$11),"") | P16: =IF(X16=1,IF(N(O16)>0,ROUND(O16,0),MAX(1,ROUNDUP(N16,0))),"") | Q16: =IF(X16=1,P16*INDEX(LUM_FLU,Z16)*M16*$F$11/(G16*H16),"") | R16: =IF(X16=1,P16*INDEX(LUM_W,Z16),"") | S16: =IF(X16=1,R16/(G16*H16),"") | T16: =IF(C16="","",IF(X16=0,"REVISAR datos",IF(Q16>=F16,IF(Y16<0.3,"AVISO: K < 0.3","CUMPLE"),"NO CUMPLE"))) | W16: =IFERROR(MATCH(D16&"|"&E16,EM_KEY,0),0) | X16: =IF(AND(C16<>"",ISNUMBER(F16),N(G16)>0,N(H16)>0,N(I16)>AH16,K16<>""),1,0) | Y16: =IF(X16=1,G16*H16/((I16-AH16)*(G16+H16)),0) | Z16: =IF(X16=1,MATCH(K16,LUM_NOM,0),1) | AA16: =MIN(5,MAX(0.3,Y16)) | AB16: =MATCH(AA16,CU_K,1) | AC16: =(INDEX(LUM_DIS,Z16)-1)*10+MATCH($F$10,REFL_NOM,0) | AD16: =INDEX(CU_TAB,AC16,AB16) | AE16: =INDEX(CU_TAB,AC16,MIN(AB16+1,13)) | AF16: =IF(AB16>=13,AD16,AD16+(AE16-AD16)*(AA16-INDEX(CU_K,AB16))/(INDEX(CU_K,AB16+1)-INDEX(CU_K,AB16))) | AH16: =IF(ISNUMBER(J16),J16,$F$9)
B17: 4 | C17: Baño | D17: 1. Vivienda | E17: Baño | F17: =IF(C17="","",IF(W17=0,"Elija el tipo",INDEX(EM_E,W17))) | G17: 2.4 | H17: 1.8 | I17: 2.6 | J17: 0 | K17: Plafón LED 18 W | L17: =IF(X17=1,Y17,"") | M17: =IF(X17=1,AF17,"") | N17: =IF(X17=1,F17*G17*H17/(INDEX(LUM_FLU,Z17)*M17*$F$11),"") | P17: =IF(X17=1,IF(N(O17)>0,ROUND(O17,0),MAX(1,ROUNDUP(N17,0))),"") | Q17: =IF(X17=1,P17*INDEX(LUM_FLU,Z17)*M17*$F$11/(G17*H17),"") | R17: =IF(X17=1,P17*INDEX(LUM_W,Z17),"") | S17: =IF(X17=1,R17/(G17*H17),"") | T17: =IF(C17="","",IF(X17=0,"REVISAR datos",IF(Q17>=F17,IF(Y17<0.3,"AVISO: K < 0.3","CUMPLE"),"NO CUMPLE"))) | W17: =IFERROR(MATCH(D17&"|"&E17,EM_KEY,0),0) | X17: =IF(AND(C17<>"",ISNUMBER(F17),N(G17)>0,N(H17)>0,N(I17)>AH17,K17<>""),1,0) | Y17: =IF(X17=1,G17*H17/((I17-AH17)*(G17+H17)),0) | Z17: =IF(X17=1,MATCH(K17,LUM_NOM,0),1) | AA17: =MIN(5,MAX(0.3,Y17)) | AB17: =MATCH(AA17,CU_K,1) | AC17: =(INDEX(LUM_DIS,Z17)-1)*10+MATCH($F$10,REFL_NOM,0) | AD17: =INDEX(CU_TAB,AC17,AB17) | AE17: =INDEX(CU_TAB,AC17,MIN(AB17+1,13)) | AF17: =IF(AB17>=13,AD17,AD17+(AE17-AD17)*(AA17-INDEX(CU_K,AB17))/(INDEX(CU_K,AB17+1)-INDEX(CU_K,AB17))) | AH17: =IF(ISNUMBER(J17),J17,$F$9)
B18: 5 | C18: Estudio | D18: 1. Vivienda | E18: Estudios, almacenes, depósitos, walking closet, cuartos de trabajo doméstico (planchado, lavandería y similares) | F18: =IF(C18="","",IF(W18=0,"Elija el tipo",INDEX(EM_E,W18))) | G18: 3 | H18: 2.8 | I18: 2.6 | K18: Panel LED 60×60 cm, 40 W | L18: =IF(X18=1,Y18,"") | M18: =IF(X18=1,AF18,"") | N18: =IF(X18=1,F18*G18*H18/(INDEX(LUM_FLU,Z18)*M18*$F$11),"") | P18: =IF(X18=1,IF(N(O18)>0,ROUND(O18,0),MAX(1,ROUNDUP(N18,0))),"") | Q18: =IF(X18=1,P18*INDEX(LUM_FLU,Z18)*M18*$F$11/(G18*H18),"") | R18: =IF(X18=1,P18*INDEX(LUM_W,Z18),"") | S18: =IF(X18=1,R18/(G18*H18),"") | T18: =IF(C18="","",IF(X18=0,"REVISAR datos",IF(Q18>=F18,IF(Y18<0.3,"AVISO: K < 0.3","CUMPLE"),"NO CUMPLE"))) | W18: =IFERROR(MATCH(D18&"|"&E18,EM_KEY,0),0) | X18: =IF(AND(C18<>"",ISNUMBER(F18),N(G18)>0,N(H18)>0,N(I18)>AH18,K18<>""),1,0) | Y18: =IF(X18=1,G18*H18/((I18-AH18)*(G18+H18)),0) | Z18: =IF(X18=1,MATCH(K18,LUM_NOM,0),1) | AA18: =MIN(5,MAX(0.3,Y18)) | AB18: =MATCH(AA18,CU_K,1) | AC18: =(INDEX(LUM_DIS,Z18)-1)*10+MATCH($F$10,REFL_NOM,0) | AD18: =INDEX(CU_TAB,AC18,AB18) | AE18: =INDEX(CU_TAB,AC18,MIN(AB18+1,13)) | AF18: =IF(AB18>=13,AD18,AD18+(AE18-AD18)*(AA18-INDEX(CU_K,AB18))/(INDEX(CU_K,AB18+1)-INDEX(CU_K,AB18))) | AH18: =IF(ISNUMBER(J18),J18,$F$9)
B19: 6 | C19: Escalera común | D19: 1. Vivienda | E19: Escaleras, escaleras mecánicas y transportadores (de personas) | F19: =IF(C19="","",IF(W19=0,"Elija el tipo",INDEX(EM_E,W19))) | G19: 5 | H19: 2.4 | I19: 2.6 | J19: 0 | K19: Plafón LED 18 W | L19: =IF(X19=1,Y19,"") | M19: =IF(X19=1,AF19,"") | N19: =IF(X19=1,F19*G19*H19/(INDEX(LUM_FLU,Z19)*M19*$F$11),"") | P19: =IF(X19=1,IF(N(O19)>0,ROUND(O19,0),MAX(1,ROUNDUP(N19,0))),"") | Q19: =IF(X19=1,P19*INDEX(LUM_FLU,Z19)*M19*$F$11/(G19*H19),"") | R19: =IF(X19=1,P19*INDEX(LUM_W,Z19),"") | S19: =IF(X19=1,R19/(G19*H19),"") | T19: =IF(C19="","",IF(X19=0,"REVISAR datos",IF(Q19>=F19,IF(Y19<0.3,"AVISO: K < 0.3","CUMPLE"),"NO CUMPLE"))) | W19: =IFERROR(MATCH(D19&"|"&E19,EM_KEY,0),0) | X19: =IF(AND(C19<>"",ISNUMBER(F19),N(G19)>0,N(H19)>0,N(I19)>AH19,K19<>""),1,0) | Y19: =IF(X19=1,G19*H19/((I19-AH19)*(G19+H19)),0) | Z19: =IF(X19=1,MATCH(K19,LUM_NOM,0),1) | AA19: =MIN(5,MAX(0.3,Y19)) | AB19: =MATCH(AA19,CU_K,1) | AC19: =(INDEX(LUM_DIS,Z19)-1)*10+MATCH($F$10,REFL_NOM,0) | AD19: =INDEX(CU_TAB,AC19,AB19) | AE19: =INDEX(CU_TAB,AC19,MIN(AB19+1,13)) | AF19: =IF(AB19>=13,AD19,AD19+(AE19-AD19)*(AA19-INDEX(CU_K,AB19))/(INDEX(CU_K,AB19+1)-INDEX(CU_K,AB19))) | AH19: =IF(ISNUMBER(J19),J19,$F$9)
B20: 7 | C20: Pasillo común | D20: 1. Vivienda | E20: Áreas de circulación y pasillos | F20: =IF(C20="","",IF(W20=0,"Elija el tipo",INDEX(EM_E,W20))) | G20: 8 | H20: 1.5 | I20: 2.6 | J20: 0 | K20: Plafón LED 18 W | L20: =IF(X20=1,Y20,"") | M20: =IF(X20=1,AF20,"") | N20: =IF(X20=1,F20*G20*H20/(INDEX(LUM_FLU,Z20)*M20*$F$11),"") | P20: =IF(X20=1,IF(N(O20)>0,ROUND(O20,0),MAX(1,ROUNDUP(N20,0))),"") | Q20: =IF(X20=1,P20*INDEX(LUM_FLU,Z20)*M20*$F$11/(G20*H20),"") | R20: =IF(X20=1,P20*INDEX(LUM_W,Z20),"") | S20: =IF(X20=1,R20/(G20*H20),"") | T20: =IF(C20="","",IF(X20=0,"REVISAR datos",IF(Q20>=F20,IF(Y20<0.3,"AVISO: K < 0.3","CUMPLE"),"NO CUMPLE"))) | W20: =IFERROR(MATCH(D20&"|"&E20,EM_KEY,0),0) | X20: =IF(AND(C20<>"",ISNUMBER(F20),N(G20)>0,N(H20)>0,N(I20)>AH20,K20<>""),1,0) | Y20: =IF(X20=1,G20*H20/((I20-AH20)*(G20+H20)),0) | Z20: =IF(X20=1,MATCH(K20,LUM_NOM,0),1) | AA20: =MIN(5,MAX(0.3,Y20)) | AB20: =MATCH(AA20,CU_K,1) | AC20: =(INDEX(LUM_DIS,Z20)-1)*10+MATCH($F$10,REFL_NOM,0) | AD20: =INDEX(CU_TAB,AC20,AB20) | AE20: =INDEX(CU_TAB,AC20,MIN(AB20+1,13)) | AF20: =IF(AB20>=13,AD20,AD20+(AE20-AD20)*(AA20-INDEX(CU_K,AB20))/(INDEX(CU_K,AB20+1)-INDEX(CU_K,AB20))) | AH20: =IF(ISNUMBER(J20),J20,$F$9)
B21: 8 | C21: Oficina administrativa | D21: 6. Oficinas | E21: Escritura, mecanografía, lectura, procesamiento de datos | F21: =IF(C21="","",IF(W21=0,"Elija el tipo",INDEX(EM_E,W21))) | G21: 6 | H21: 5 | I21: 2.8 | K21: Panel LED 60×60 cm, 40 W | L21: =IF(X21=1,Y21,"") | M21: =IF(X21=1,AF21,"") | N21: =IF(X21=1,F21*G21*H21/(INDEX(LUM_FLU,Z21)*M21*$F$11),"") | P21: =IF(X21=1,IF(N(O21)>0,ROUND(O21,0),MAX(1,ROUNDUP(N21,0))),"") | Q21: =IF(X21=1,P21*INDEX(LUM_FLU,Z21)*M21*$F$11/(G21*H21),"") | R21: =IF(X21=1,P21*INDEX(LUM_W,Z21),"") | S21: =IF(X21=1,R21/(G21*H21),"") | T21: =IF(C21="","",IF(X21=0,"REVISAR datos",IF(Q21>=F21,IF(Y21<0.3,"AVISO: K < 0.3","CUMPLE"),"NO CUMPLE"))) | W21: =IFERROR(MATCH(D21&"|"&E21,EM_KEY,0),0) | X21: =IF(AND(C21<>"",ISNUMBER(F21),N(G21)>0,N(H21)>0,N(I21)>AH21,K21<>""),1,0) | Y21: =IF(X21=1,G21*H21/((I21-AH21)*(G21+H21)),0) | Z21: =IF(X21=1,MATCH(K21,LUM_NOM,0),1) | AA21: =MIN(5,MAX(0.3,Y21)) | AB21: =MATCH(AA21,CU_K,1) | AC21: =(INDEX(LUM_DIS,Z21)-1)*10+MATCH($F$10,REFL_NOM,0) | AD21: =INDEX(CU_TAB,AC21,AB21) | AE21: =INDEX(CU_TAB,AC21,MIN(AB21+1,13)) | AF21: =IF(AB21>=13,AD21,AD21+(AE21-AD21)*(AA21-INDEX(CU_K,AB21))/(INDEX(CU_K,AB21+1)-INDEX(CU_K,AB21))) | AH21: =IF(ISNUMBER(J21),J21,$F$9)
B22: 9 | F22: =IF(C22="","",IF(W22=0,"Elija el tipo",INDEX(EM_E,W22))) | L22: =IF(X22=1,Y22,"") | M22: =IF(X22=1,AF22,"") | N22: =IF(X22=1,F22*G22*H22/(INDEX(LUM_FLU,Z22)*M22*$F$11),"") | P22: =IF(X22=1,IF(N(O22)>0,ROUND(O22,0),MAX(1,ROUNDUP(N22,0))),"") | Q22: =IF(X22=1,P22*INDEX(LUM_FLU,Z22)*M22*$F$11/(G22*H22),"") | R22: =IF(X22=1,P22*INDEX(LUM_W,Z22),"") | S22: =IF(X22=1,R22/(G22*H22),"") | T22: =IF(C22="","",IF(X22=0,"REVISAR datos",IF(Q22>=F22,IF(Y22<0.3,"AVISO: K < 0.3","CUMPLE"),"NO CUMPLE"))) | W22: =IFERROR(MATCH(D22&"|"&E22,EM_KEY,0),0) | X22: =IF(AND(C22<>"",ISNUMBER(F22),N(G22)>0,N(H22)>0,N(I22)>AH22,K22<>""),1,0) | Y22: =IF(X22=1,G22*H22/((I22-AH22)*(G22+H22)),0) | Z22: =IF(X22=1,MATCH(K22,LUM_NOM,0),1) | AA22: =MIN(5,MAX(0.3,Y22)) | AB22: =MATCH(AA22,CU_K,1) | AC22: =(INDEX(LUM_DIS,Z22)-1)*10+MATCH($F$10,REFL_NOM,0) | AD22: =INDEX(CU_TAB,AC22,AB22) | AE22: =INDEX(CU_TAB,AC22,MIN(AB22+1,13)) | AF22: =IF(AB22>=13,AD22,AD22+(AE22-AD22)*(AA22-INDEX(CU_K,AB22))/(INDEX(CU_K,AB22+1)-INDEX(CU_K,AB22))) | AH22: =IF(ISNUMBER(J22),J22,$F$9)
B23: 10 | F23: =IF(C23="","",IF(W23=0,"Elija el tipo",INDEX(EM_E,W23))) | L23: =IF(X23=1,Y23,"") | M23: =IF(X23=1,AF23,"") | N23: =IF(X23=1,F23*G23*H23/(INDEX(LUM_FLU,Z23)*M23*$F$11),"") | P23: =IF(X23=1,IF(N(O23)>0,ROUND(O23,0),MAX(1,ROUNDUP(N23,0))),"") | Q23: =IF(X23=1,P23*INDEX(LUM_FLU,Z23)*M23*$F$11/(G23*H23),"") | R23: =IF(X23=1,P23*INDEX(LUM_W,Z23),"") | S23: =IF(X23=1,R23/(G23*H23),"") | T23: =IF(C23="","",IF(X23=0,"REVISAR datos",IF(Q23>=F23,IF(Y23<0.3,"AVISO: K < 0.3","CUMPLE"),"NO CUMPLE"))) | W23: =IFERROR(MATCH(D23&"|"&E23,EM_KEY,0),0) | X23: =IF(AND(C23<>"",ISNUMBER(F23),N(G23)>0,N(H23)>0,N(I23)>AH23,K23<>""),1,0) | Y23: =IF(X23=1,G23*H23/((I23-AH23)*(G23+H23)),0) | Z23: =IF(X23=1,MATCH(K23,LUM_NOM,0),1) | AA23: =MIN(5,MAX(0.3,Y23)) | AB23: =MATCH(AA23,CU_K,1) | AC23: =(INDEX(LUM_DIS,Z23)-1)*10+MATCH($F$10,REFL_NOM,0) | AD23: =INDEX(CU_TAB,AC23,AB23) | AE23: =INDEX(CU_TAB,AC23,MIN(AB23+1,13)) | AF23: =IF(AB23>=13,AD23,AD23+(AE23-AD23)*(AA23-INDEX(CU_K,AB23))/(INDEX(CU_K,AB23+1)-INDEX(CU_K,AB23))) | AH23: =IF(ISNUMBER(J23),J23,$F$9)
B24: 11 | F24: =IF(C24="","",IF(W24=0,"Elija el tipo",INDEX(EM_E,W24))) | L24: =IF(X24=1,Y24,"") | M24: =IF(X24=1,AF24,"") | N24: =IF(X24=1,F24*G24*H24/(INDEX(LUM_FLU,Z24)*M24*$F$11),"") | P24: =IF(X24=1,IF(N(O24)>0,ROUND(O24,0),MAX(1,ROUNDUP(N24,0))),"") | Q24: =IF(X24=1,P24*INDEX(LUM_FLU,Z24)*M24*$F$11/(G24*H24),"") | R24: =IF(X24=1,P24*INDEX(LUM_W,Z24),"") | S24: =IF(X24=1,R24/(G24*H24),"") | T24: =IF(C24="","",IF(X24=0,"REVISAR datos",IF(Q24>=F24,IF(Y24<0.3,"AVISO: K < 0.3","CUMPLE"),"NO CUMPLE"))) | W24: =IFERROR(MATCH(D24&"|"&E24,EM_KEY,0),0) | X24: =IF(AND(C24<>"",ISNUMBER(F24),N(G24)>0,N(H24)>0,N(I24)>AH24,K24<>""),1,0) | Y24: =IF(X24=1,G24*H24/((I24-AH24)*(G24+H24)),0) | Z24: =IF(X24=1,MATCH(K24,LUM_NOM,0),1) | AA24: =MIN(5,MAX(0.3,Y24)) | AB24: =MATCH(AA24,CU_K,1) | AC24: =(INDEX(LUM_DIS,Z24)-1)*10+MATCH($F$10,REFL_NOM,0) | AD24: =INDEX(CU_TAB,AC24,AB24) | AE24: =INDEX(CU_TAB,AC24,MIN(AB24+1,13)) | AF24: =IF(AB24>=13,AD24,AD24+(AE24-AD24)*(AA24-INDEX(CU_K,AB24))/(INDEX(CU_K,AB24+1)-INDEX(CU_K,AB24))) | AH24: =IF(ISNUMBER(J24),J24,$F$9)
B25: 12 | F25: =IF(C25="","",IF(W25=0,"Elija el tipo",INDEX(EM_E,W25))) | L25: =IF(X25=1,Y25,"") | M25: =IF(X25=1,AF25,"") | N25: =IF(X25=1,F25*G25*H25/(INDEX(LUM_FLU,Z25)*M25*$F$11),"") | P25: =IF(X25=1,IF(N(O25)>0,ROUND(O25,0),MAX(1,ROUNDUP(N25,0))),"") | Q25: =IF(X25=1,P25*INDEX(LUM_FLU,Z25)*M25*$F$11/(G25*H25),"") | R25: =IF(X25=1,P25*INDEX(LUM_W,Z25),"") | S25: =IF(X25=1,R25/(G25*H25),"") | T25: =IF(C25="","",IF(X25=0,"REVISAR datos",IF(Q25>=F25,IF(Y25<0.3,"AVISO: K < 0.3","CUMPLE"),"NO CUMPLE"))) | W25: =IFERROR(MATCH(D25&"|"&E25,EM_KEY,0),0) | X25: =IF(AND(C25<>"",ISNUMBER(F25),N(G25)>0,N(H25)>0,N(I25)>AH25,K25<>""),1,0) | Y25: =IF(X25=1,G25*H25/((I25-AH25)*(G25+H25)),0) | Z25: =IF(X25=1,MATCH(K25,LUM_NOM,0),1) | AA25: =MIN(5,MAX(0.3,Y25)) | AB25: =MATCH(AA25,CU_K,1) | AC25: =(INDEX(LUM_DIS,Z25)-1)*10+MATCH($F$10,REFL_NOM,0) | AD25: =INDEX(CU_TAB,AC25,AB25) | AE25: =INDEX(CU_TAB,AC25,MIN(AB25+1,13)) | AF25: =IF(AB25>=13,AD25,AD25+(AE25-AD25)*(AA25-INDEX(CU_K,AB25))/(INDEX(CU_K,AB25+1)-INDEX(CU_K,AB25))) | AH25: =IF(ISNUMBER(J25),J25,$F$9)
B26: 13 | F26: =IF(C26="","",IF(W26=0,"Elija el tipo",INDEX(EM_E,W26))) | L26: =IF(X26=1,Y26,"") | M26: =IF(X26=1,AF26,"") | N26: =IF(X26=1,F26*G26*H26/(INDEX(LUM_FLU,Z26)*M26*$F$11),"") | P26: =IF(X26=1,IF(N(O26)>0,ROUND(O26,0),MAX(1,ROUNDUP(N26,0))),"") | Q26: =IF(X26=1,P26*INDEX(LUM_FLU,Z26)*M26*$F$11/(G26*H26),"") | R26: =IF(X26=1,P26*INDEX(LUM_W,Z26),"") | S26: =IF(X26=1,R26/(G26*H26),"") | T26: =IF(C26="","",IF(X26=0,"REVISAR datos",IF(Q26>=F26,IF(Y26<0.3,"AVISO: K < 0.3","CUMPLE"),"NO CUMPLE"))) | W26: =IFERROR(MATCH(D26&"|"&E26,EM_KEY,0),0) | X26: =IF(AND(C26<>"",ISNUMBER(F26),N(G26)>0,N(H26)>0,N(I26)>AH26,K26<>""),1,0) | Y26: =IF(X26=1,G26*H26/((I26-AH26)*(G26+H26)),0) | Z26: =IF(X26=1,MATCH(K26,LUM_NOM,0),1) | AA26: =MIN(5,MAX(0.3,Y26)) | AB26: =MATCH(AA26,CU_K,1) | AC26: =(INDEX(LUM_DIS,Z26)-1)*10+MATCH($F$10,REFL_NOM,0) | AD26: =INDEX(CU_TAB,AC26,AB26) | AE26: =INDEX(CU_TAB,AC26,MIN(AB26+1,13)) | AF26: =IF(AB26>=13,AD26,AD26+(AE26-AD26)*(AA26-INDEX(CU_K,AB26))/(INDEX(CU_K,AB26+1)-INDEX(CU_K,AB26))) | AH26: =IF(ISNUMBER(J26),J26,$F$9)
B27: 14 | F27: =IF(C27="","",IF(W27=0,"Elija el tipo",INDEX(EM_E,W27))) | L27: =IF(X27=1,Y27,"") | M27: =IF(X27=1,AF27,"") | N27: =IF(X27=1,F27*G27*H27/(INDEX(LUM_FLU,Z27)*M27*$F$11),"") | P27: =IF(X27=1,IF(N(O27)>0,ROUND(O27,0),MAX(1,ROUNDUP(N27,0))),"") | Q27: =IF(X27=1,P27*INDEX(LUM_FLU,Z27)*M27*$F$11/(G27*H27),"") | R27: =IF(X27=1,P27*INDEX(LUM_W,Z27),"") | S27: =IF(X27=1,R27/(G27*H27),"") | T27: =IF(C27="","",IF(X27=0,"REVISAR datos",IF(Q27>=F27,IF(Y27<0.3,"AVISO: K < 0.3","CUMPLE"),"NO CUMPLE"))) | W27: =IFERROR(MATCH(D27&"|"&E27,EM_KEY,0),0) | X27: =IF(AND(C27<>"",ISNUMBER(F27),N(G27)>0,N(H27)>0,N(I27)>AH27,K27<>""),1,0) | Y27: =IF(X27=1,G27*H27/((I27-AH27)*(G27+H27)),0) | Z27: =IF(X27=1,MATCH(K27,LUM_NOM,0),1) | AA27: =MIN(5,MAX(0.3,Y27)) | AB27: =MATCH(AA27,CU_K,1) | AC27: =(INDEX(LUM_DIS,Z27)-1)*10+MATCH($F$10,REFL_NOM,0) | AD27: =INDEX(CU_TAB,AC27,AB27) | AE27: =INDEX(CU_TAB,AC27,MIN(AB27+1,13)) | AF27: =IF(AB27>=13,AD27,AD27+(AE27-AD27)*(AA27-INDEX(CU_K,AB27))/(INDEX(CU_K,AB27+1)-INDEX(CU_K,AB27))) | AH27: =IF(ISNUMBER(J27),J27,$F$9)
B28: 15 | F28: =IF(C28="","",IF(W28=0,"Elija el tipo",INDEX(EM_E,W28))) | L28: =IF(X28=1,Y28,"") | M28: =IF(X28=1,AF28,"") | N28: =IF(X28=1,F28*G28*H28/(INDEX(LUM_FLU,Z28)*M28*$F$11),"") | P28: =IF(X28=1,IF(N(O28)>0,ROUND(O28,0),MAX(1,ROUNDUP(N28,0))),"") | Q28: =IF(X28=1,P28*INDEX(LUM_FLU,Z28)*M28*$F$11/(G28*H28),"") | R28: =IF(X28=1,P28*INDEX(LUM_W,Z28),"") | S28: =IF(X28=1,R28/(G28*H28),"") | T28: =IF(C28="","",IF(X28=0,"REVISAR datos",IF(Q28>=F28,IF(Y28<0.3,"AVISO: K < 0.3","CUMPLE"),"NO CUMPLE"))) | W28: =IFERROR(MATCH(D28&"|"&E28,EM_KEY,0),0) | X28: =IF(AND(C28<>"",ISNUMBER(F28),N(G28)>0,N(H28)>0,N(I28)>AH28,K28<>""),1,0) | Y28: =IF(X28=1,G28*H28/((I28-AH28)*(G28+H28)),0) | Z28: =IF(X28=1,MATCH(K28,LUM_NOM,0),1) | AA28: =MIN(5,MAX(0.3,Y28)) | AB28: =MATCH(AA28,CU_K,1) | AC28: =(INDEX(LUM_DIS,Z28)-1)*10+MATCH($F$10,REFL_NOM,0) | AD28: =INDEX(CU_TAB,AC28,AB28) | AE28: =INDEX(CU_TAB,AC28,MIN(AB28+1,13)) | AF28: =IF(AB28>=13,AD28,AD28+(AE28-AD28)*(AA28-INDEX(CU_K,AB28))/(INDEX(CU_K,AB28+1)-INDEX(CU_K,AB28))) | AH28: =IF(ISNUMBER(J28),J28,$F$9)
B29: 16 | F29: =IF(C29="","",IF(W29=0,"Elija el tipo",INDEX(EM_E,W29))) | L29: =IF(X29=1,Y29,"") | M29: =IF(X29=1,AF29,"") | N29: =IF(X29=1,F29*G29*H29/(INDEX(LUM_FLU,Z29)*M29*$F$11),"") | P29: =IF(X29=1,IF(N(O29)>0,ROUND(O29,0),MAX(1,ROUNDUP(N29,0))),"") | Q29: =IF(X29=1,P29*INDEX(LUM_FLU,Z29)*M29*$F$11/(G29*H29),"") | R29: =IF(X29=1,P29*INDEX(LUM_W,Z29),"") | S29: =IF(X29=1,R29/(G29*H29),"") | T29: =IF(C29="","",IF(X29=0,"REVISAR datos",IF(Q29>=F29,IF(Y29<0.3,"AVISO: K < 0.3","CUMPLE"),"NO CUMPLE"))) | W29: =IFERROR(MATCH(D29&"|"&E29,EM_KEY,0),0) | X29: =IF(AND(C29<>"",ISNUMBER(F29),N(G29)>0,N(H29)>0,N(I29)>AH29,K29<>""),1,0) | Y29: =IF(X29=1,G29*H29/((I29-AH29)*(G29+H29)),0) | Z29: =IF(X29=1,MATCH(K29,LUM_NOM,0),1) | AA29: =MIN(5,MAX(0.3,Y29)) | AB29: =MATCH(AA29,CU_K,1) | AC29: =(INDEX(LUM_DIS,Z29)-1)*10+MATCH($F$10,REFL_NOM,0) | AD29: =INDEX(CU_TAB,AC29,AB29) | AE29: =INDEX(CU_TAB,AC29,MIN(AB29+1,13)) | AF29: =IF(AB29>=13,AD29,AD29+(AE29-AD29)*(AA29-INDEX(CU_K,AB29))/(INDEX(CU_K,AB29+1)-INDEX(CU_K,AB29))) | AH29: =IF(ISNUMBER(J29),J29,$F$9)
B30: 17 | F30: =IF(C30="","",IF(W30=0,"Elija el tipo",INDEX(EM_E,W30))) | L30: =IF(X30=1,Y30,"") | M30: =IF(X30=1,AF30,"") | N30: =IF(X30=1,F30*G30*H30/(INDEX(LUM_FLU,Z30)*M30*$F$11),"") | P30: =IF(X30=1,IF(N(O30)>0,ROUND(O30,0),MAX(1,ROUNDUP(N30,0))),"") | Q30: =IF(X30=1,P30*INDEX(LUM_FLU,Z30)*M30*$F$11/(G30*H30),"") | R30: =IF(X30=1,P30*INDEX(LUM_W,Z30),"") | S30: =IF(X30=1,R30/(G30*H30),"") | T30: =IF(C30="","",IF(X30=0,"REVISAR datos",IF(Q30>=F30,IF(Y30<0.3,"AVISO: K < 0.3","CUMPLE"),"NO CUMPLE"))) | W30: =IFERROR(MATCH(D30&"|"&E30,EM_KEY,0),0) | X30: =IF(AND(C30<>"",ISNUMBER(F30),N(G30)>0,N(H30)>0,N(I30)>AH30,K30<>""),1,0) | Y30: =IF(X30=1,G30*H30/((I30-AH30)*(G30+H30)),0) | Z30: =IF(X30=1,MATCH(K30,LUM_NOM,0),1) | AA30: =MIN(5,MAX(0.3,Y30)) | AB30: =MATCH(AA30,CU_K,1) | AC30: =(INDEX(LUM_DIS,Z30)-1)*10+MATCH($F$10,REFL_NOM,0) | AD30: =INDEX(CU_TAB,AC30,AB30) | AE30: =INDEX(CU_TAB,AC30,MIN(AB30+1,13)) | AF30: =IF(AB30>=13,AD30,AD30+(AE30-AD30)*(AA30-INDEX(CU_K,AB30))/(INDEX(CU_K,AB30+1)-INDEX(CU_K,AB30))) | AH30: =IF(ISNUMBER(J30),J30,$F$9)
B31: 18 | F31: =IF(C31="","",IF(W31=0,"Elija el tipo",INDEX(EM_E,W31))) | L31: =IF(X31=1,Y31,"") | M31: =IF(X31=1,AF31,"") | N31: =IF(X31=1,F31*G31*H31/(INDEX(LUM_FLU,Z31)*M31*$F$11),"") | P31: =IF(X31=1,IF(N(O31)>0,ROUND(O31,0),MAX(1,ROUNDUP(N31,0))),"") | Q31: =IF(X31=1,P31*INDEX(LUM_FLU,Z31)*M31*$F$11/(G31*H31),"") | R31: =IF(X31=1,P31*INDEX(LUM_W,Z31),"") | S31: =IF(X31=1,R31/(G31*H31),"") | T31: =IF(C31="","",IF(X31=0,"REVISAR datos",IF(Q31>=F31,IF(Y31<0.3,"AVISO: K < 0.3","CUMPLE"),"NO CUMPLE"))) | W31: =IFERROR(MATCH(D31&"|"&E31,EM_KEY,0),0) | X31: =IF(AND(C31<>"",ISNUMBER(F31),N(G31)>0,N(H31)>0,N(I31)>AH31,K31<>""),1,0) | Y31: =IF(X31=1,G31*H31/((I31-AH31)*(G31+H31)),0) | Z31: =IF(X31=1,MATCH(K31,LUM_NOM,0),1) | AA31: =MIN(5,MAX(0.3,Y31)) | AB31: =MATCH(AA31,CU_K,1) | AC31: =(INDEX(LUM_DIS,Z31)-1)*10+MATCH($F$10,REFL_NOM,0) | AD31: =INDEX(CU_TAB,AC31,AB31) | AE31: =INDEX(CU_TAB,AC31,MIN(AB31+1,13)) | AF31: =IF(AB31>=13,AD31,AD31+(AE31-AD31)*(AA31-INDEX(CU_K,AB31))/(INDEX(CU_K,AB31+1)-INDEX(CU_K,AB31))) | AH31: =IF(ISNUMBER(J31),J31,$F$9)
B32: 19 | F32: =IF(C32="","",IF(W32=0,"Elija el tipo",INDEX(EM_E,W32))) | L32: =IF(X32=1,Y32,"") | M32: =IF(X32=1,AF32,"") | N32: =IF(X32=1,F32*G32*H32/(INDEX(LUM_FLU,Z32)*M32*$F$11),"") | P32: =IF(X32=1,IF(N(O32)>0,ROUND(O32,0),MAX(1,ROUNDUP(N32,0))),"") | Q32: =IF(X32=1,P32*INDEX(LUM_FLU,Z32)*M32*$F$11/(G32*H32),"") | R32: =IF(X32=1,P32*INDEX(LUM_W,Z32),"") | S32: =IF(X32=1,R32/(G32*H32),"") | T32: =IF(C32="","",IF(X32=0,"REVISAR datos",IF(Q32>=F32,IF(Y32<0.3,"AVISO: K < 0.3","CUMPLE"),"NO CUMPLE"))) | W32: =IFERROR(MATCH(D32&"|"&E32,EM_KEY,0),0) | X32: =IF(AND(C32<>"",ISNUMBER(F32),N(G32)>0,N(H32)>0,N(I32)>AH32,K32<>""),1,0) | Y32: =IF(X32=1,G32*H32/((I32-AH32)*(G32+H32)),0) | Z32: =IF(X32=1,MATCH(K32,LUM_NOM,0),1) | AA32: =MIN(5,MAX(0.3,Y32)) | AB32: =MATCH(AA32,CU_K,1) | AC32: =(INDEX(LUM_DIS,Z32)-1)*10+MATCH($F$10,REFL_NOM,0) | AD32: =INDEX(CU_TAB,AC32,AB32) | AE32: =INDEX(CU_TAB,AC32,MIN(AB32+1,13)) | AF32: =IF(AB32>=13,AD32,AD32+(AE32-AD32)*(AA32-INDEX(CU_K,AB32))/(INDEX(CU_K,AB32+1)-INDEX(CU_K,AB32))) | AH32: =IF(ISNUMBER(J32),J32,$F$9)
B33: 20 | F33: =IF(C33="","",IF(W33=0,"Elija el tipo",INDEX(EM_E,W33))) | L33: =IF(X33=1,Y33,"") | M33: =IF(X33=1,AF33,"") | N33: =IF(X33=1,F33*G33*H33/(INDEX(LUM_FLU,Z33)*M33*$F$11),"") | P33: =IF(X33=1,IF(N(O33)>0,ROUND(O33,0),MAX(1,ROUNDUP(N33,0))),"") | Q33: =IF(X33=1,P33*INDEX(LUM_FLU,Z33)*M33*$F$11/(G33*H33),"") | R33: =IF(X33=1,P33*INDEX(LUM_W,Z33),"") | S33: =IF(X33=1,R33/(G33*H33),"") | T33: =IF(C33="","",IF(X33=0,"REVISAR datos",IF(Q33>=F33,IF(Y33<0.3,"AVISO: K < 0.3","CUMPLE"),"NO CUMPLE"))) | W33: =IFERROR(MATCH(D33&"|"&E33,EM_KEY,0),0) | X33: =IF(AND(C33<>"",ISNUMBER(F33),N(G33)>0,N(H33)>0,N(I33)>AH33,K33<>""),1,0) | Y33: =IF(X33=1,G33*H33/((I33-AH33)*(G33+H33)),0) | Z33: =IF(X33=1,MATCH(K33,LUM_NOM,0),1) | AA33: =MIN(5,MAX(0.3,Y33)) | AB33: =MATCH(AA33,CU_K,1) | AC33: =(INDEX(LUM_DIS,Z33)-1)*10+MATCH($F$10,REFL_NOM,0) | AD33: =INDEX(CU_TAB,AC33,AB33) | AE33: =INDEX(CU_TAB,AC33,MIN(AB33+1,13)) | AF33: =IF(AB33>=13,AD33,AD33+(AE33-AD33)*(AA33-INDEX(CU_K,AB33))/(INDEX(CU_K,AB33+1)-INDEX(CU_K,AB33))) | AH33: =IF(ISNUMBER(J33),J33,$F$9)
... B38: 25 | F38: =IF(C38="","",IF(W38=0,"Elija el tipo",INDEX(EM_E,W38))) | L38: =IF(X38=1,Y38,"") | M38: =IF(X38=1,AF38,"") | N38: =IF(X38=1,F38*G38*H38/(INDEX(LUM_FLU,Z38)*M38*$F$11),"") | P38: =IF(X38=1,IF(N(O38)>0,ROUND(O38,0),MAX(1,ROUNDUP(N38,0))),"") | Q38: =IF(X38=1,P38*INDEX(LUM_FLU,Z38)*M38*$F$11/(G38*H38),"") | R38: =IF(X38=1,P38*INDEX(LUM_W,Z38),"") | S38: =IF(X38=1,R38/(G38*H38),"") | T38: =IF(C38="","",IF(X38=0,"REVISAR datos",IF(Q38>=F38,IF(Y38<0.3,"AVISO: K < 0.3","CUMPLE"),"NO CUMPLE"))) | W38: =IFERROR(MATCH(D38&"|"&E38,EM_KEY,0),0) | X38: =IF(AND(C38<>"",ISNUMBER(F38),N(G38)>0,N(H38)>0,N(I38)>AH38,K38<>""),1,0) | Y38: =IF(X38=1,G38*H38/((I38-AH38)*(G38+H38)),0) | Z38: =IF(X38=1,MATCH(K38,LUM_NOM,0),1) | AA38: =MIN(5,MAX(0.3,Y38)) | AB38: =MATCH(AA38,CU_K,1) | AC38: =(INDEX(LUM_DIS,Z38)-1)*10+MATCH($F$10,REFL_NOM,0) | AD38: =INDEX(CU_TAB,AC38,AB38) | AE38: =INDEX(CU_TAB,AC38,MIN(AB38+1,13)) | AF38: =IF(AB38>=13,AD38,AD38+(AE38-AD38)*(AA38-INDEX(CU_K,AB38))/(INDEX(CU_K,AB38+1)-INDEX(CU_K,AB38))) | AH38: =IF(ISNUMBER(J38),J38,$F$9)
B39: TOTAL | P39: =SUM(P14:P38) | R39: =SUM(R14:R38) | S39: =IF(SUMPRODUCT((X14:X38=1)*G14:G38*H14:H38)=0,"",R39/SUMPRODUCT((X14:X38=1)*G14:G38*H14:H38)) | T39: =IF(COUNTIF(T14:T38,"NO CUMPLE")+COUNTIF(T14:T38,"REVISAR*")+COUNTIF(T14:T38,"AVISO*")>0,"REVISAR","CUMPLE")
B41: CU de la tabla genérica de ALF_BIM (luminaria difusa o concentrada, local cuadrado, K de 0.3 a 5; ver TABLAS). Em obtenida = N·Φ·CU·FM/A. Verifique el UGRL, la Uo y el Ra de cada ambiente con la fotometría del fabricante (EM.010 Art. 6.8). Potencia de alumbrado para el cuadro de cargas: columna «Potencia».

Sheet CAIDA_TENSION
B1: CAÍDA DE TENSIÓN Y SECCIÓN DEL CONDUCTOR
B2: ALF_BIM · Calculadoras IIEE ALF · CNE-U Regla 050-102 · Tabla 2 · Tablas 5A y 5C · v1.0.0
B3: Proyecto | C3: =INICIO!$D$7
B4: Ubicación | C4: =INICIO!$D$9
B5: Circuito | C5: ALIMENTADOR DEL TABLERO GENERAL TG AL TABLERO DE DISTRIBUCIÓN TD-1 (EJEMPLO)
B6: Proyectista | C6: =INICIO!$D$10&IF(INICIO!$D$11="",""," · CIP "&INICIO!$D$11)
B7: Fecha | C7: =INICIO!$D$12
B10: 1. DATOS DEL CIRCUITO
B11: Tipo de tramo | D11: Alimentador
B12: Sistema | D12: Monofásico 220 V
B13: Potencia de la carga (máxima demanda del tramo) | C13: P | D13: 9500 | E13: W | F13: De la máxima demanda (MaximaDemandaALF) o del cuadro de cargas
B14: Factor de potencia | C14: cos φ | D14: 0.9
B15: Corriente conocida (opcional, reemplaza a P) | C15: Iman | E15: A | F15: Por ejemplo, la corriente de placa de un motor
B16: Longitud del tramo (hasta la carga o la salida más lejana) | C16: L | D16: 32 | E16: m
B17: Método de instalación | D17: B1 · Unipolares en tubo empotrado o sobre pared (lo usual en edificaciones)
B18: Temperatura ambiente (o del terreno en el método D) | C18: T | D18: 30 | E18: °C
B19: Circuitos agrupados en el mismo tubo (incluido este) | D19: 1 | F19: Tabla 5C, ítem 1: hasta 20 circuitos
B20: Sección mínima del proyectista | C20: Smín | D20: 4 | E20: mm² | F20: 030-002: 2.5 mm² en circuitos derivados de fuerza y alumbrado
B21: ITM mínimo (opcional) | E21: A | F21: Por ejemplo, 16 A alumbrado y 20 A tomacorrientes
B22: Resistividad del conductor (cobre) | C22: ρ | D22: 0.0175 | E22: Ω·mm²/m | F22: 0.0175 a 20 °C (usual en el Perú); 0.0225 a 70 °C (IEC 60364-5-52, más conservador)
B23: Reactancia del conductor (opcional) | C23: X | D23: 0 | E23: Ω/km | F23: ≈ 0.08 Ω/km en tubo; recomendable desde 35 mm²
B24: Límite de caída del tramo del proyectista (opcional) | E24: % | F24: Si se deja vacío: el del tipo de tramo (050-102)
B25: Caída acumulada aguas arriba (alimentadores previos) | C25: ΔVprev | D25: 0 | E25: % | F25: 0 si el tramo sale del medidor
B26: Tipo de conductor | D26: NH-80
B28: 2. CORRIENTE Y PROTECCIÓN
B29: Fila del sistema | D29: =MATCH($D$12,SIS_NOM,0)
B30: Tensión del sistema | C30: V | D30: =INDEX(SIS_V,$D$29) | E30: V
B31: Constante de corriente (1 monofásico; √3 trifásico) | C31: k | D31: =INDEX(SIS_K,$D$29)
B32: Constante de caída (2 monofásico; √3 trifásico) | C32: k' | D32: =INDEX(SIS_K2,$D$29)
B33: Conductores cargados | D33: =INDEX(SIS_CARG,$D$29)
B34: Corriente de la carga I = P/(k·V·cos φ) | C34: I | D34: =IF(N($D$15)>0,$D$15,$D$13/($D$31*$D$30*$D$14)) | E34: A
B35: Corriente de diseño Id = 1.25·I | C35: Id | D35: =1.25*$D$34 | E35: A | F35: 050-104: carga continua al 80 % del dispositivo
B36: INTERRUPTOR TERMOMAGNÉTICO In ≥ Id | C36: In | D36: =INDEX(ITM,MIN(COUNT(ITM),COUNTIF(ITM,"<"&MAX($D$35,N($D$21))-0.000001)+1)) | E36: A
B37: Existe un ITM normalizado ≥ Id (hasta 630 A) | C37: =IF($D$36>=$D$35-0.000001,"CUMPLE","NO CUMPLE")
B38: Capacidad requerida del conductor máx(In, Id) | C38: Ireq | D38: =MAX($D$36,$D$35) | E38: A
B40: 3. CAPACIDAD DE CORRIENTE (CNE-U Tabla 2 · Tabla 5A · Tabla 5C)
B41: Método (fila) | D41: =MATCH($D$17,MET_DESC,0)
B42: Columna de la Tabla 2 | D42: =($D$41-1)*2+IF($D$33=3,2,1)
B43: Método y conductores cargados | D43: =INDEX(MET_COD,$D$41)&" · "&$D$33&" conductores cargados"
B44: Factor por temperatura (Tabla 5A) | C44: Ft | D44: =IF(INDEX(MET_COD,$D$41)="D",INDEX(FT_TER,MATCH($D$18,FT_T,0)),INDEX(FT_AIR,MATCH($D$18,FT_T,0)))
...

Sheet CIRCUITOS
B1: CUADRO DE ALIMENTADORES Y CIRCUITOS · CAÍDA DE TENSIÓN Y SECCIÓN · CNE-U 050-102 Y TABLA 2
B2: ALF_BIM · Calculadoras IIEE ALF · v1.0.0
B3: Proyecto | D3: =INICIO!$D$7
B4: Ubicación | D4: =INICIO!$D$9
B5: Proyectista | D5: =INICIO!$D$10&IF(INICIO!$D$11="",""," · CIP "&INICIO!$D$11)
B6: Fecha | D6: =INICIO!$D$12
B8: DATOS COMUNES
C9: Temperatura ambiente (°C) | F9: 30 | I9: Una fila por tramo. «ΔV previo» es la caída acumulada del alimentador que alimenta al tramo: escriba la referencia a su celda «ΔV acum.» (por ejemplo =R15) para encadenarlos. Id = 1.25·I; ITM ≥ Id; conductor con Iz·Ft·Fa ≥ máx(ITM, Id), caída del tramo ≤ 2.5 % y acumulada ≤ 4 %. Método: A1, A2, B1 (tubo empotrado), B2, C, D (enterrado; la temperatura común se usa como la del terreno). ρ: 0.0175 a 20 °C (usual) o 0.0225 a 70 °C (IEC). X ≈ 0.08 Ω/km en tubo.
C10: Resistividad del cobre (Ω·mm²/m) | F10: 0.0175
C11: Límite de caída acumulada (%) | F11: 4
C12: ITM mínimo en circuitos derivados (A) | F12: 16
C13: Reactancia del conductor (Ω/km, opcional) | F13: 0
B14: N.° | C14: Tramo (de → a) | D14: Tipo | E14: Sistema | F14: P (W) | G14: cos φ | H14: L (m) | I14: Método | J14: Circ. en tubo | K14: S mín. (mm²) | L14: ΔV previo (%) | M14: I (A) | N14: ITM (A) | O14: S (mm²) | P14: Iz·F (A) | Q14: ΔV tramo (%) | R14: ΔV acum. (%) | S14: Gobierna | T14: Estado
B15: 1 | C15: Medidor → TG | D15: Alimentador | E15: Monofásico 220 V | F15: 9500 | G15: 0.9 | H15: 12 | I15: B1 | J15: 1 | K15: 6 | L15: 0 | M15: =IF(V15=1,AA15,"") | N15: =IF(V15=1,AB15,"") | O15: =IF(V15=1,IF(AG15=1,INDEX(SECC,AF15),"Insuficiente"),"") | P15: =IF(AND(V15=1,AG15=1),INDEX(TABLA2,AF15,Y15)*Z15,"") | Q15: =IF(AND(V15=1,AG15=1),100*INDEX(SIS_K2,W15)*H15*AA15*($F$10*G15/O15+$F$13/1000*AK15)/INDEX(SIS_V,W15),"") | R15: =IF(AND(V15=1,AG15=1),N(L15)+Q15,"") | S15: =IF(V15=0,"",IF(AG15=0,"Insuficiente",IF(AND(AD15>AC15,AD15>=AE15),"Caída",IF(AC15>=AE15,"Capacidad","S mínima")))) | T15: =IF(C15="","",IF(V15=0,"REVISAR datos",IF(AH15=0,"REVISAR ΔV previo",IF(AG15=0,"NO CUMPLE",IF(AB15<1.25*AA15-0.000001,"NO CUMPLE (ITM)",IF(AND(Q15<=AJ15+0.000001,R15<=$F$11+0.000001),"CUMPLE","NO CUMPLE")))))) | V15: =IF(AND(C15<>"",D15<>"",E15<>"",N(F15)>0,N(G15)>0,N(H15)>0,I15<>""),1,0) | W15: =IF(V15=1,MATCH(E15,SIS_NOM,0),1) | X15: =IF(V15=1,MATCH(I15,MET_COD,0),3) | Y15: =(X15-1)*2+IF(INDEX(SIS_CARG,W15)=3,2,1) | Z15: =IF(I15="D",INDEX(FT_TER,MATCH($F$9,FT_T,0)),INDEX(FT_AIR,MATCH($F$9,FT_T,0)))*INDEX(FA_F,MIN(COUNT(FA_N),COUNTIF(FA_N,"<"&MAX(1,N(J15)))+1)) | AA15: =IF(V15=1,F15/(INDEX(SIS_K,W15)*INDEX(SIS_V,W15)*G15),0) | AB15: =INDEX(ITM,MIN(COUNT(ITM),COUNTIF(ITM,"<"&MAX(1.25*AA15,IF(D15="Circuito derivado",N($F$12),0))-0.000001)+1)) | AC15: =COUNTIF(INDEX(TABLA2,0,Y15),"<"&MAX(AB15,1.25*AA15)/Z15-0.000001)+1 | AD15: =IF(V15=1,IF(AL15<=0,99,COUNTIF(SECC,"<"&INDEX(SIS_K2,W15)*$F$10*H15*AA15*G15/AL15-0.000001)+1),1) | AE15: =IFERROR(MATCH(N(K15),SECC,0),2) | AF15: =MAX(AC15,AD15,AE15) | AG15: =IF(AF15<=COUNT(INDEX(TABLA2,0,Y15)),1,0) | AH15: =IF(OR(ISBLANK(L15),ISNUMBER(L15)),1,0) | AI15: =MIN(AJ15,$F$11-N(L15)) | AJ15: =IF(V15=1,INDEX(TRAMO_LIM,MATCH(D15,TRAMO_NOM,0)),2.5) | AK15: =SQRT(MAX(0,1-N(G15)^2)) | AL15: =AI15/100*INDEX(SIS_V,W15)-INDEX(SIS_K2,W15)*N(H15)*AA15*$F$13/1000*AK15
B16: 2 | C16: TG → TD-1 (2.° piso) | D16: Alimentador | E16: Monofásico 220 V | F16: 6200 | G16: 0.9 | H16: 18 | I16: B1 | J16: 1 | K16: 4 | L16: =R15 | M16: =IF(V16=1,AA16,"") | N16: =IF(V16=1,AB16,"") | O16: =IF(V16=1,IF(AG16=1,INDEX(SECC,AF16),"Insuficiente"),"") | P16: =IF(AND(V16=1,AG16=1),INDEX(TABLA2,AF16,Y16)*Z16,"") | Q16: =IF(AND(V16=1,AG16=1),100*INDEX(SIS_K2,W16)*H16*AA16*($F$10*G16/O16+$F$13/1000*AK16)/INDEX(SIS_V,W16),"") | R16: =IF(AND(V16=1,AG16=1),N(L16)+Q16,"") | S16: =IF(V16=0,"",IF(AG16=0,"Insuficiente",IF(AND(AD16>AC16,AD16>=AE16),"Caída",IF(AC16>=AE16,"Capacidad","S mínima")))) | T16: =IF(C16="","",IF(V16=0,"REVISAR datos",IF(AH16=0,"REVISAR ΔV previo",IF(AG16=0,"NO CUMPLE",IF(AB16<1.25*AA16-0.000001,"NO CUMPLE (ITM)",IF(AND(Q16<=AJ16+0.000001,R16<=$F$11+0.000001),"CUMPLE","NO CUMPLE")))))) | V16: =IF(AND(C16<>"",D16<>"",E16<>"",N(F16)>0,N(G16)>0,N(H16)>0,I16<>""),1,0) | W16: =IF(V16=1,MATCH(E16,SIS_NOM,0),1) | X16: =IF(V16=1,MATCH(I16,MET_COD,0),3) | Y16: =(X16-1)*2+IF(INDEX(SIS_CARG,W16)=3,2,1) | Z16: =IF(I16="D",INDEX(FT_TER,MATCH($F$9,FT_T,0)),INDEX(FT_AIR,MATCH($F$9,FT_T,0)))*INDEX(FA_F,MIN(COUNT(FA_N),COUNTIF(FA_N,"<"&MAX(1,N(J16)))+1)) | AA16: =IF(V16=1,F16/(INDEX(SIS_K,W16)*INDEX(SIS_V,W16)*G16),0) | AB16: =INDEX(ITM,MIN(COUNT(ITM),COUNTIF(ITM,"<"&MAX(1.25*AA16,IF(D16="Circuito derivado",N($F$12),0))-0.000001)+1)) | AC16: =COUNTIF(INDEX(TABLA2,0,Y16),"<"&MAX(AB16,1.25*AA16)/Z16-0.000001)+1 | AD16: =IF(V16=1,IF(AL16<=0,99,COUNTIF(SECC,"<"&INDEX(SIS_K2,W16)*$F$10*H16*AA16*G16/AL16-0.000001)+1),1) | AE16: =IFERROR(MATCH(N(K16),SECC,0),2) | AF16: =MAX(AC16,AD16,AE16) | AG16: =IF(AF16<=COUNT(INDEX(TABLA2,0,Y16)),1,0) | AH16: =IF(OR(ISBLANK(L16),ISNUMBER(L16)),1,0) | AI16: =MIN(AJ16,$F$11-N(L16)) | AJ16: =IF(V16=1,INDEX(TRAMO_LIM,MATCH(D16,TRAMO_NOM,0)),2.5) | AK16: =SQRT(MAX(0,1-N(G16)^2)) | AL16: =AI16/100*INDEX(SIS_V,W16)-INDEX(SIS_K2,W16)*N(H16)*AA16*$F$13/1000*AK16
B17: 3 | C17: TD-1 · C-1 Alumbrado | D17: Circuito derivado | E17: Monofásico 220 V | F17: 800 | G17: 1 | H17: 22 | I17: B1 | J17: 2 | K17: 2.5 | L17: =R16 | M17: =IF(V17=1,AA17,"") | N17: =IF(V17=1,AB17,"") | O17: =IF(V17=1,IF(AG17=1,INDEX(SECC,AF17),"Insuficiente"),"") | P17: =IF(AND(V17=1,AG17=1),INDEX(TABLA2,AF17,Y17)*Z17,"") | Q17: =IF(AND(V17=1,AG17=1),100*INDEX(SIS_K2,W17)*H17*AA17*($F$10*G17/O17+$F$13/1000*AK17)/INDEX(SIS_V,W17),"") | R17: =IF(AND(V17=1,AG17=1),N(L17)+Q17,"") | S17: =IF(V17=0,"",IF(AG17=0,"Insuficiente",IF(AND(AD17>AC17,AD17>=AE17),"Caída",IF(AC17>=AE17,"Capacidad","S mínima")))) | T17: =IF(C17="","",IF(V17=0,"REVISAR datos",IF(AH17=0,"REVISAR ΔV previo",IF(AG17=0,"NO CUMPLE",IF(AB17<1.25*AA17-0.000001,"NO CUMPLE (ITM)",IF(AND(Q17<=AJ17+0.000001,R17<=$F$11+0.000001),"CUMPLE","NO CUMPLE")))))) | V17: =IF(AND(C17<>"",D17<>"",E17<>"",N(F17)>0,N(G17)>0,N(H17)>0,I17<>""),1,0) | W17: =IF(V17=1,MATCH(E17,SIS_NOM,0),1) | X17: =IF(V17=1,MATCH(I17,MET_COD,0),3) | Y17: =(X17-1)*2+IF(INDEX(SIS_CARG,W17)=3,2,1) | Z17: =IF(I17="D",INDEX(FT_TER,MATCH($F$9,FT_T,0)),INDEX(FT_AIR,MATCH($F$9,FT_T,0)))*INDEX(FA_F,MIN(COUNT(FA_N),COUNTIF(FA_N,"<"&MAX(1,N(J17)))+1)) | AA17: =IF(V17=1,F17/(INDEX(SIS_K,W17)*INDEX(SIS_V,W17)*G17),0) | AB17: =INDEX(ITM,MIN(COUNT(ITM),COUNTIF(ITM,"<"&MAX(1.25*AA17,IF(D17="Circuito derivado",N($F$12),0))-0.000001)+1)) | AC17: =COUNTIF(INDEX(TABLA2,0,Y17),"<"&MAX(AB17,1.25*AA17)/Z17-0.000001)+1 | AD17: =IF(V17=1,IF(AL17<=0,99,COUNTIF(SECC,"<"&INDEX(SIS_K2,W17)*$F$10*H17*AA17*G17/AL17-0.000001)+1),1) | AE17: =IFERROR(MATCH(N(K17),SECC,0),2) | AF17: =MAX(AC17,AD17,AE17) | AG17: =IF(AF17<=COUNT(INDEX(TABLA2,0,Y17)),1,0) | AH17: =IF(OR(ISBLANK(L17),ISNUMBER(L17)),1,0) | AI17: =MIN(AJ17,$F$11-N(L17)) | AJ17: =IF(V17=1,INDEX(TRAMO_LIM,MATCH(D17,TRAMO_NOM,0)),2.5) | AK17: =SQRT(MAX(0,1-N(G17)^2)) | AL17: =AI17/100*INDEX(SIS_V,W17)-INDEX(SIS_K2,W17)*N(H17)*AA17*$F$13/1000*AK17
B18: 4 | C18: TD-1 · C-2 Tomacorrientes | D18: Circuito derivado | E18: Monofásico 220 V | F18: 1800 | G18: 0.9 | H18: 25 | I18: B1 | J18: 2 | K18: 4 | L18: =R16 | M18: =IF(V18=1,AA18,"") | N18: =IF(V18=1,AB18,"") | O18: =IF(V18=1,IF(AG18=1,INDEX(SECC,AF18),"Insuficiente"),"") | P18: =IF(AND(V18=1,AG18=1),INDEX(TABLA2,AF18,Y18)*Z18,"") | Q18: =IF(AND(V18=1,AG18=1),100*INDEX(SIS_K2,W18)*H18*AA18*($F$10*G18/O18+$F$13/1000*AK18)/INDEX(SIS_V,W18),"") | R18: =IF(AND(V18=1,AG18=1),N(L18)+Q18,"") | S18: =IF(V18=0,"",IF(AG18=0,"Insuficiente",IF(AND(AD18>AC18,AD18>=AE18),"Caída",IF(AC18>=AE18,"Capacidad","S mínima")))) | T18: =IF(C18="","",IF(V18=0,"REVISAR datos",IF(AH18=0,"REVISAR ΔV previo",IF(AG18=0,"NO CUMPLE",IF(AB18<1.25*AA18-0.000001,"NO CUMPLE (ITM)",IF(AND(Q18<=AJ18+0.000001,R18<=$F$11+0.000001),"CUMPLE","NO CUMPLE")))))) | V18: =IF(AND(C18<>"",D18<>"",E18<>"",N(F18)>0,N(G18)>0,N(H18)>0,I18<>""),1,0) | W18: =IF(V18=1,MATCH(E18,SIS_NOM,0),1) | X18: =IF(V18=1,MATCH(I18,MET_COD,0),3) | Y18: =(X18-1)*2+IF(INDEX(SIS_CARG,W18)=3,2,1) | Z18: =IF(I18="D",INDEX(FT_TER,MATCH($F$9,FT_T,0)),INDEX(FT_AIR,MATCH($F$9,FT_T,0)))*INDEX(FA_F,MIN(COUNT(FA_N),COUNTIF(FA_N,"<"&MAX(1,N(J18)))+1)) | AA18: =IF(V18=1,F18/(INDEX(SIS_K,W18)*INDEX(SIS_V,W18)*G18),0) | AB18: =INDEX(ITM,MIN(COUNT(ITM),COUNTIF(ITM,"<"&MAX(1.25*AA18,IF(D18="Circuito derivado",N($F$12),0))-0.000001)+1)) | AC18: =COUNTIF(INDEX(TABLA2,0,Y18),"<"&MAX(AB18,1.25*AA18)/Z18-0.000001)+1 | AD18: =IF(V18=1,IF(AL18<=0,99,COUNTIF(SECC,"<"&INDEX(SIS_K2,W18)*$F$10*H18*AA18*G18/AL18-0.000001)+1),1) | AE18: =IFERROR(MATCH(N(K18),SECC,0),2) | AF18: =MAX(AC18,AD18,AE18) | AG18: =IF(AF18<=COUNT(INDEX(TABLA2,0,Y18)),1,0) | AH18: =IF(OR(ISBLANK(L18),ISNUMBER(L18)),1,0) | AI18: =MIN(AJ18,$F$11-N(L18)) | AJ18: =IF(V18=1,INDEX(TRAMO_LIM,MATCH(D18,TRAMO_NOM,0)),2.5) | AK18: =SQRT(MAX(0,1-N(G18)^2)) | AL18: =AI18/100*INDEX(SIS_V,W18)-INDEX(SIS_K2,W18)*N(H18)*AA18*$F$13/1000*AK18
B19: 5 | C19: TD-1 · C-3 Cocina eléctrica | D19: Circuito derivado | E19: Monofásico 220 V | F19: 8000 | G19: 1 | H19: 14 | I19: B1 | J19: 1 | K19: 4 | L19: =R16 | M19: =IF(V19=1,AA19,"") | N19: =IF(V19=1,AB19,"") | O19: =IF(V19=1,IF(AG19=1,INDEX(SECC,AF19),"Insuficiente"),"") | P19: =IF(AND(V19=1,AG19=1),INDEX(TABLA2,AF19,Y19)*Z19,"") | Q19: =IF(AND(V19=1,AG19=1),100*INDEX(SIS_K2,W19)*H19*AA19*($F$10*G19/O19+$F$13/1000*AK19)/INDEX(SIS_V,W19),"") | R19: =IF(AND(V19=1,AG19=1),N(L19)+Q19,"") | S19: =IF(V19=0,"",IF(AG19=0,"Insuficiente",IF(AND(AD19>AC19,AD19>=AE19),"Caída",IF(AC19>=AE19,"Capacidad","S mínima")))) | T19: =IF(C19="","",IF(V19=0,"REVISAR datos",IF(AH19=0,"REVISAR ΔV previo",IF(AG19=0,"NO CUMPLE",IF(AB19<1.25*AA19-0.000001,"NO CUMPLE (ITM)",IF(AND(Q19<=AJ19+0.000001,R19<=$F$11+0.000001),"CUMPLE","NO CUMPLE")))))) | V19: =IF(AND(C19<>"",D19<>"",E19<>"",N(F19)>0,N(G19)>0,N(H19)>0,I19<>""),1,0) | W19: =IF(V19=1,MATCH(E19,SIS_NOM,0),1) | X19: =IF(V19=1,MATCH(I19,MET_COD,0),3) | Y19: =(X19-1)*2+IF(INDEX(SIS_CARG,W19)=3,2,1) | Z19: =IF(I19="D",INDEX(FT_TER,MATCH($F$9,FT_T,0)),INDEX(FT_AIR,MATCH($F$9,FT_T,0)))*INDEX(FA_F,MIN(COUNT(FA_N),COUNTIF(FA_N,"<"&MAX(1,N(J19)))+1)) | AA19: =IF(V19=1,F19/(INDEX(SIS_K,W19)*INDEX(SIS_V,W19)*G19),0) | AB19: =INDEX(ITM,MIN(COUNT(ITM),COUNTIF(ITM,"<"&MAX(1.25*AA19,IF(D19="Circuito derivado",N($F$12),0))-0.000001)+1)) | AC19: =COUNTIF(INDEX(TABLA2,0,Y19),"<"&MAX(AB19,1.25*AA19)/Z19-0.000001)+1 | AD19: =IF(V19=1,IF(AL19<=0,99,COUNTIF(SECC,"<"&INDEX(SIS_K2,W19)*$F$10*H19*AA19*G19/AL19-0.000001)+1),1) | AE19: =IFERROR(MATCH(N(K19),SECC,0),2) | AF19: =MAX(AC19,AD19,AE19) | AG19: =IF(AF19<=COUNT(INDEX(TABLA2,0,Y19)),1,0) | AH19: =IF(OR(ISBLANK(L19),ISNUMBER(L19)),1,0) | AI19: =MIN(AJ19,$F$11-N(L19)) | AJ19: =IF(V19=1,INDEX(TRAMO_LIM,MATCH(D19,TRAMO_NOM,0)),2.5) | AK19: =SQRT(MAX(0,1-N(G19)^2)) | AL19: =AI19/100*INDEX(SIS_V,W19)-INDEX(SIS_K2,W19)*N(H19)*AA19*$F$13/1000*AK19
B20: 6 | C20: TD-1 · C-4 Terma | D20: Circuito derivado | E20: Monofásico 220 V | F20: 1500 | G20: 1 | H20: 12 | I20: B1 | J20: 1 | K20: 4 | L20: =R16 | M20: =IF(V20=1,AA20,"") | N20: =IF(V20=1,AB20,"") | O20: =IF(V20=1,IF(AG20=1,INDEX(SECC,AF20),"Insuficiente"),"") | P20: =IF(AND(V20=1,AG20=1),INDEX(TABLA2,AF20,Y20)*Z20,"") | Q20: =IF(AND(V20=1,AG20=1),100*INDEX(SIS_K2,W20)*H20*AA20*($F$10*G20/O20+$F$13/1000*AK20)/INDEX(SIS_V,W20),"") | R20: =IF(AND(V20=1,AG20=1),N(L20)+Q20,"") | S20: =IF(V20=0,"",IF(AG20=0,"Insuficiente",IF(AND(AD20>AC20,AD20>=AE20),"Caída",IF(AC20>=AE20,"Capacidad","S mínima")))) | T20: =IF(C20="","",IF(V20=0,"REVISAR datos",IF(AH20=0,"REVISAR ΔV previo",IF(AG20=0,"NO CUMPLE",IF(AB20<1.25*AA20-0.000001,"NO CUMPLE (ITM)",IF(AND(Q20<=AJ20+0.000001,R20<=$F$11+0.000001),"CUMPLE","NO CUMPLE")))))) | V20: =IF(AND(C20<>"",D20<>"",E20<>"",N(F20)>0,N(G20)>0,N(H20)>0,I20<>""),1,0) | W20: =IF(V20=1,MATCH(E20,SIS_NOM,0),1) | X20: =IF(V20=1,MATCH(I20,MET_COD,0),3) | Y20: =(X20-1)*2+IF(INDEX(SIS_CARG,W20)=3,2,1) | Z20: =IF(I20="D",INDEX(FT_TER,MATCH($F$9,FT_T,0)),INDEX(FT_AIR,MATCH($F$9,FT_T,0)))*INDEX(FA_F,MIN(COUNT(FA_N),COUNTIF(FA_N,"<"&MAX(1,N(J20)))+1)) | AA20: =IF(V20=1,F20/(INDEX(SIS_K,W20)*INDEX(SIS_V,W20)*G20),0) | AB20: =INDEX(ITM,MIN(COUNT(ITM),COUNTIF(ITM,"<"&MAX(1.25*AA20,IF(D20="Circuito derivado",N($F$12),0))-0.000001)+1)) | AC20: =COUNTIF(INDEX(TABLA2,0,Y20),"<"&MAX(AB20,1.25*AA20)/Z20-0.000001)+1 | AD20: =IF(V20=1,IF(AL20<=0,99,COUNTIF(SECC,"<"&INDEX(SIS_K2,W20)*$F$10*H20*AA20*G20/AL20-0.000001)+1),1) | AE20: =IFERROR(MATCH(N(K20),SECC,0),2) | AF20: =MAX(AC20,AD20,AE20) | AG20: =IF(AF20<=COUNT(INDEX(TABLA2,0,Y20)),1,0) | AH20: =IF(OR(ISBLANK(L20),ISNUMBER(L20)),1,0) | AI20: =MIN(AJ20,$F$11-N(L20)) | AJ20: =IF(V20=1,INDEX(TRAMO_LIM,MATCH(D20,TRAMO_NOM,0)),2.5) | AK20: =SQRT(MAX(0,1-N(G20)^2)) | AL20: =AI20/100*INDEX(SIS_V,W20)-INDEX(SIS_K2,W20)*N(H20)*AA20*$F$13/1000*AK20
B21: 7 | C21: TG → Electrobomba 2 HP (trifásica) | D21: Circuito derivado | E21: Trifásico 380/220 V (4 hilos) | F21: 1870 | G21: 0.85 | H21: 30 | I21: B1 | J21: 1 | K21: 2.5 | L21: =R15 | M21: =IF(V21=1,AA21,"") | N21: =IF(V21=1,AB21,"") | O21: =IF(V21=1,IF(AG21=1,INDEX(SECC,AF21),"Insuficiente"),"") | P21: =IF(AND(V21=1,AG21=1),INDEX(TABLA2,AF21,Y21)*Z21,"") | Q21: =IF(AND(V21=1,AG21=1),100*INDEX(SIS_K2,W21)*H21*AA21*($F$10*G21/O21+$F$13/1000*AK21)/INDEX(SIS_V,W21),"") | R21: =IF(AND(V21=1,AG21=1),N(L21)+Q21,"") | S21: =IF(V21=0,"",IF(AG21=0,"Insuficiente",IF(AND(AD21>AC21,AD21>=AE21),"Caída",IF(AC21>=AE21,"Capacidad","S mínima")))) | T21: =IF(C21="","",IF(V21=0,"REVISAR datos",IF(AH21=0,"REVISAR ΔV previo",IF(AG21=0,"NO CUMPLE",IF(AB21<1.25*AA21-0.000001,"NO CUMPLE (ITM)",IF(AND(Q21<=AJ21+0.000001,R21<=$F$11+0.000001),"CUMPLE","NO CUMPLE")))))) | V21: =IF(AND(C21<>"",D21<>"",E21<>"",N(F21)>0,N(G21)>0,N(H21)>0,I21<>""),1,0) | W21: =IF(V21=1,MATCH(E21,SIS_NOM,0),1) | X21: =IF(V21=1,MATCH(I21,MET_COD,0),3) | Y21: =(X21-1)*2+IF(INDEX(SIS_CARG,W21)=3,2,1) | Z21: =IF(I21="D",INDEX(FT_TER,MATCH($F$9,FT_T,0)),INDEX(FT_AIR,MATCH($F$9,FT_T,0)))*INDEX(FA_F,MIN(COUNT(FA_N),COUNTIF(FA_N,"<"&MAX(1,N(J21)))+1)) | AA21: =IF(V21=1,F21/(INDEX(SIS_K,W21)*INDEX(SIS_V,W21)*G21),0) | AB21: =INDEX(ITM,MIN(COUNT(ITM),COUNTIF(ITM,"<"&MAX(1.25*AA21,IF(D21="Circuito derivado",N($F$12),0))-0.000001)+1)) | AC21: =COUNTIF(INDEX(TABLA2,0,Y21),"<"&MAX(AB21,1.25*AA21)/Z21-0.000001)+1 | AD21: =IF(V21=1,IF(AL21<=0,99,COUNTIF(SECC,"<"&INDEX(SIS_K2,W21)*$F$10*H21*AA21*G21/AL21-0.000001)+1),1) | AE21: =IFERROR(MATCH(N(K21),SECC,0),2) | AF21: =MAX(AC21,AD21,AE21) | AG21: =IF(AF21<=COUNT(INDEX(TABLA2,0,Y21)),1,0) | AH21: =IF(OR(ISBLANK(L21),ISNUMBER(L21)),1,0) | AI21: =MIN(AJ21,$F$11-N(L21)) | AJ21: =IF(V21=1,INDEX(TRAMO_LIM,MATCH(D21,TRAMO_NOM,0)),2.5) | AK21: =SQRT(MAX(0,1-N(G21)^2)) | AL21: =AI21/100*INDEX(SIS_V,W21)-INDEX(SIS_K2,W21)*N(H21)*AA21*$F$13/1000*AK21
