Workbook
Name BAR_NOM: TABLAS!$B$5:$B$13
Name BAR_DB: TABLAS!$C$5:$C$13
Name BAR_AS: TABLAS!$D$5:$D$13
Name COMB_NOM: TABLAS!$B$17:$B$25
Name COMB_AS: TABLAS!$C$17:$C$25
Name ALIG_H: TABLAS!$B$29:$B$32
Name ALIG_PP: TABLAS!$C$29:$C$32
Name USO_NOM: TABLAS!$G$5:$G$24
Name USO_SC: TABLAS!$H$5:$H$24
Name LNEG: TABLAS!$B$42:$T$52
Name LPCM: TABLAS!$B$56:$T$66
Name LPCV: TABLAS!$B$70:$T$80
Name CASOS: TABLAS!$B$83:$B$91

Sheet INICIO
B2: PLANTILLA EXCEL ESTRUCTURAS ALF
B3: NTE E.060 · Vigas · Columnas · Placas · Losas · Escaleras · Cimentaciones · Muros · v2.1.0
B4: ALF_BIM · www.alfbim.com · Herramienta gratuita
B6: DATOS DEL PROYECTO (aparecen en el encabezado de cada reporte)
B7: Proyecto | D7: VIVIENDA MULTIFAMILIAR DE 4 NIVELES (EJEMPLO)
B8: Propietario | D8: —
B9: Ubicación | D9: Chota, Cajamarca
B10: Calculista | D10: Ing.
B11: CIP
B12: Fecha | D12: 46310
B14: HOJAS DE CÁLCULO
B15: =HYPERLINK("#'PREDIM'!A1","→ PREDIM") | D15: Predimensionamiento: aligerados, losas macizas, vigas, columnas por área tributaria y longitud de placas.
B16: =HYPERLINK("#'VIGA'!A1","→ VIGA") | D16: Viga sísmica: 6 secciones, doble armadura, reglas del cap. 21, cortante por capacidad, confinamiento y anclajes.
B17: =HYPERLINK("#'COLUMNA'!A1","→ COLUMNA") | D17: Columna: diagramas de interacción X e Y, 9 combinaciones, biaxial (Bresler), esbeltez con amplificación de momentos, columna fuerte–viga débil, cortante por capacidad, Ash y confinamiento.
B18: =HYPERLINK("#'PLACA'!A1","→ PLACA") | D18: Muro estructural: flexocompresión, cortante amplificado Mn/Mua, cuantías ρh y ρv, elementos de borde (21.9).
B19: =HYPERLINK("#'LOSA_MACIZA'!A1","→ LOSA_MACIZA") | D19: Losa maciza en dos direcciones: método de coeficientes E.060 13.7 (casos 1 a 9), acero, cortante y espesor.
B20: =HYPERLINK("#'ALIGERADO'!A1","→ ALIGERADO") | D20: Losa aligerada en una dirección (1 a 5 tramos): coeficientes 8.3.3, acero mínimo por 1.2·Mcr, bastones, cortante y deflexiones.
B21: =HYPERLINK("#'ESCALERA'!A1","→ ESCALERA") | D21: Escalera de un tramo con descanso: geometría A.010, cargas, momento máximo, acero y cortante.
B22: =HYPERLINK("#'ZAPATA'!A1","→ ZAPATA") | D22: Zapata aislada con carga axial y momentos biaxiales: presiones, punzonamiento con transferencia de momento, cortante, flexión, anclaje y aplastamiento.
B23: =HYPERLINK("#'ZAP_CONECTADA'!A1","→ ZAP_CONECTADA") | D23: Zapata exterior de lindero con viga de conexión: excentricidad, reacción, viga y zapata.
B24: =HYPERLINK("#'ZAP_COMBINADA'!A1","→ ZAP_COMBINADA") | D24: Zapata combinada rectangular de dos columnas: dimensiones, momentos, acero longitudinal y transversal, cortante y punzonamiento.
B25: =HYPERLINK("#'CIMIENTO'!A1","→ CIMIENTO") | D25: Cimiento corrido de concreto simple para muros de albañilería (E.060 cap. 22).
B26: =HYPERLINK("#'MURO'!A1","→ MURO") | D26: Muro de contención en voladizo: Rankine con sobrecarga y sismo (Mononobe–Okabe), volteo, deslizamiento, presiones, pantalla, puntera y talón.
B27: =HYPERLINK("#'ANCLAJES'!A1","→ ANCLAJES") | D27: Cuadro de longitudes de desarrollo, ganchos y empalmes por varilla (E.060 cap. 12).
B28: =HYPERLINK("#'TABLAS'!A1","→ TABLAS") | D28: Varillas, combinaciones para viguetas, cargas E.020, pesos de aligerados y coeficientes de losas (Tablas 13.1–13.3).
B30: CÓMO SE USA
B31: Celda amarilla con texto azul | D31: Dato que usted ingresa (cargas, dimensiones, materiales, varillas).
B32: Celda gris con texto negro | D32: Resultado calculado. Está protegida para no borrarla por error.
B33: CUMPLE / NO CUMPLE | D33: Verificación de la norma. Si no cumple, cambie el dato indicado en la nota de la derecha. REVISAR (naranja) es un aviso.
B34: Listas desplegables | D34: Varillas, sistema estructural, uso, caso de losa y otras opciones se eligen de una lista.
B35: Protección | D35: Las hojas están protegidas SIN contraseña: Revisar → Desproteger hoja, si necesita cambiar algo.
B37: REPORTE EN PDF
B38: 1. Abra la hoja que quiere imprimir.
B39: 2. Archivo → Exportar → Crear documento PDF/XPS (o Archivo → Imprimir → Microsoft Print to PDF).
B40: 3. Cada hoja ya está configurada en A4 vertical, ajustada al ancho, con encabezado, pie y número de página.
B41: 4. Para un solo PDF con varias hojas: selecciónelas con Ctrl + clic en las pestañas y luego exporte.
B42: 5. Para varios elementos (Z-1, Z-2, C-1…): clic derecho en la pestaña → Mover o copiar → Crear una copia.
B44: NORMAS Y CRITERIOS
B45: NTE E.060 Concreto Armado (DS 010-2009-VIVIENDA), verificada con el texto oficial: φ flexión 0.90, cortante 0.85, compresión con estribos 0.70 (hasta 0.90), aplastamiento 0.70.
B46: Combinaciones: U = 1.4CM + 1.7CV; U = 1.25(CM+CV) ± CS; U = 0.9CM ± CS; empuje lateral 1.7. Capítulo 21 según el sistema: pórticos/dual tipo II o muros/dual tipo I.
...

Sheet PREDIM
B1: PREDIMENSIONAMIENTO DE ELEMENTOS ESTRUCTURALES
B2: ALF_BIM · Plantilla Excel Estructuras · NTE E.060 Concreto Armado · v2.1.0
B3: Proyecto | C3: =INICIO!$D$7
B4: Ubicación | C4: =INICIO!$D$9
B5: Elemento | C5: Edificación de 4 niveles
B6: Calculista | C6: =INICIO!$D$10&IF(INICIO!$D$11="",""," · CIP "&INICIO!$D$11)
B7: Fecha | C7: =INICIO!$D$12
B10: 1. LOSAS
B11: Resistencia del concreto | C11: f'c | D11: 210 | E11: kgf/cm²
B12: Fluencia del acero | C12: fy | D12: 4200 | E12: kgf/cm²
B13: Luz libre mayor del aligerado (una dirección) | C13: ln | D13: 4.2 | E13: m
B14: Aligerado: criterio práctico ln/25 | C14: h | D14: =$D$13/25*100 | E14: cm | F14: Práctica peruana para s/c ≤ 300 kgf/m²
B15: Aligerado: referencia Tabla 9.1 (ambos extremos continuos ℓ/21) | C15: h | D15: =$D$13/21*100 | E15: cm | F15: E.060 9.6.2.1: sin verificar deflexiones
B16: PERALTE DE ALIGERADO SUGERIDO | C16: h | D16: =IF($D$14<=17,17,IF($D$14<=20,20,IF($D$14<=25,25,30))) | E16: cm | F16: Valores comerciales 17 / 20 / 25 / 30 cm
B17: h sugerido ≥ referencia Tabla 9.1 | C17: =IF($D$16>=$D$15,"CUMPLE","REVISAR") | F17: Si sale REVISAR: verifique deflexiones en la hoja ALIGERADO o use el h mayor
B18: Losa maciza en dos direcciones: luz libre corta A | C18: A | D18: 4 | E18: m
B19: Losa maciza en dos direcciones: luz libre larga B | C19: B | D19: 5 | E19: m
B20: Criterio práctico perímetro/180 | C20: h | D20: =2*($D$18+$D$19)/180*100 | E20: cm
B21: E.060 9.6.3.3 con vigas rígidas (αfm > 2) | C21: h | D21: =MAX(9,$D$19*100*(0.8+$D$12/14000)/(36+9*$D$19/$D$18)) | E21: cm | F21: h = ln(0.8 + fy/14000)/(36 + 9β) ≥ 9 cm
B22: ESPESOR DE LOSA MACIZA SUGERIDO | C22: h | D22: =CEILING(MAX($D$20,$D$21),1) | E22: cm
B24: 2. VIGAS
B25: Luz libre de la viga | C25: ln | D25: 6 | E25: m
B26: Sistema estructural | D26: Pórticos o dual tipo II
B27: Peralte ln/10 (sismo, pórticos) | C27: h | D27: =$D$25/10*100 | E27: cm
B28: Peralte ln/12 (gravedad o muros) | C28: h | D28: =$D$25/12*100 | E28: cm
B29: PERALTE DE VIGA SUGERIDO | C29: h | D29: =CEILING(IF($D$26="Pórticos o dual tipo II",$D$27,($D$27+$D$28)/2),5) | E29: cm | F29: Redondeado a 5 cm
B30: ANCHO DE VIGA SUGERIDO | C30: b | D30: =MAX(25,CEILING($D$29/2,5)) | E30: cm | F30: E.060 21.5.1: bw ≥ 25 cm y ≥ 0.25h
B31: Referencia Tabla 9.1 (ambos extremos continuos ℓ/21) | C31: h | D31: =$D$25/21*100 | E31: cm
B33: 3. COLUMNAS (área tributaria)
B34: Área tributaria | C34: At | D34: 20 | E34: m²
B35: Número de pisos sobre la columna | C35: N | D35: 4
B36: Categoría de la edificación (E.030) | D36: C | F36: A esencial 1.5 · B importante 1.25 · C común 1.0 t/m²
B37: Ubicación de la columna | D37: Interior | F37: Interior: n = 0.45 · Exterior o esquina: n = 0.35
B38: Peso unitario por piso | C38: Pg | D38: =IF($D$36="A",1.5,IF($D$36="B",1.25,1.0)) | E38: t/m²
B39: Carga de servicio P = Pg·At·N | C39: P | D39: =$D$38*$D$34*$D$35 | E39: t
B40: Factor n | C40: n | D40: =IF($D$37="Interior",0.45,0.35)
B41: Área de columna Ac = P/(n·f'c) | C41: Ac | D41: =$D$39*1000/($D$40*$D$11) | E41: cm² | F41: Criterio de Blanco Blasco
B42: LADO DE COLUMNA CUADRADA | C42: b | D42: =MAX(25,CEILING(SQRT($D$41),5)) | E42: cm | F42: Mínimo 25 cm (E.060 21.6.1.2)
B43: Ancho fijo para columna rectangular | C43: b | D43: 30 | E43: cm
B44: LARGO DE COLUMNA RECTANGULAR | C44: h | D44: =MAX($D$43,CEILING($D$41/$D$43,5)) | E44: cm
...

Sheet VIGA
B1: DISEÑO DE VIGA SÍSMICA · NTE E.060 CAP. 10, 11 Y 21
B2: ALF_BIM · Plantilla Excel Estructuras · NTE E.060 Concreto Armado · v2.1.0
B3: Proyecto | C3: =INICIO!$D$7
B4: Ubicación | C4: =INICIO!$D$9
B5: Elemento | C5: Viga V-101 (30×60), eje 2, tramo A–B
B6: Calculista | C6: =INICIO!$D$10&IF(INICIO!$D$11="",""," · CIP "&INICIO!$D$11)
B7: Fecha | C7: =INICIO!$D$12
B10: 1. DATOS DE ENTRADA
B11: Resistencia del concreto | C11: f'c | D11: 210 | E11: kgf/cm² | F11: Elementos sísmicos: f'c ≥ 210 (21.3.2)
B12: Fluencia del acero | C12: fy | D12: 4200 | E12: kgf/cm²
B13: Sistema estructural (define el capítulo 21) | D13: Pórticos o dual tipo II
B14: Ancho de la viga | C14: b | D14: 30 | E14: cm
B15: Peralte de la viga | C15: h | D15: 60 | E15: cm
B16: Del borde al centroide del acero en tracción | C16: d' | D16: 6 | E16: cm | F16: Una capa: 4 + Ø estribo + db/2 ≈ 6 cm
B17: Luz libre (cara a cara de columnas) | C17: ln | D17: 5.6 | E17: m
B18: Varilla superior | C18: Øs | D18: 3/4"
B19: Varilla inferior | C19: Øi | D19: 5/8"
B20: Varilla del estribo | C20: Øe | D20: 3/8" | F20: E.060 21: Ø 3/8" para barras hasta 1"
B21: Ramas del estribo | C21: n | D21: 2
B22: Cargas de gravedad sobre la viga (servicio) y cortantes del análisis
B23: Carga muerta repartida | C23: wD | D23: 2.1 | E23: t/m
B24: Carga viva repartida | C24: wL | D24: 0.8 | E24: t/m
B25: Cortante último máximo del análisis (envolvente) | C25: Vua | D25: 14 | E25: t
B26: Cortante de sismo puro en la cara | C26: VS | D26: 5 | E26: t | F26: Para la alternativa 2.5·sismo (21.4.3)
B27: Momentos últimos en las caras (envolvente del análisis, valores positivos)
B28: Sección | C28: Izq (−) | D28: Izq (+) | E28: Centro (−) | F28: Centro (+) | G28: Der (−) | H28: Der (+)
B29: Mu (t·m) | C29: 22 | D29: 9 | E29: 0 | F29: 12 | G29: 24 | H29: 10
B30: n varillas (vacío = automático)
B31: La armadura se elige sola (mínimo 2 varillas corridas). Escriba un número en la fila amarilla para fijarla usted.
B33: 2. PROPIEDADES Y LÍMITES (E.060 10.3, 10.5 y 21)
B34: Peralte efectivo d = h − d' | C34: d | D34: =$D$15-$D$16 | E34: cm
B35: Diámetro superior | C35: db | D35: =INDEX(BAR_DB,MATCH($D$18,BAR_NOM,0)) | E35: cm
B36: Área de la varilla superior | C36: Ab | D36: =INDEX(BAR_AS,MATCH($D$18,BAR_NOM,0)) | E36: cm²
B37: Diámetro inferior | C37: db | D37: =INDEX(BAR_DB,MATCH($D$19,BAR_NOM,0)) | E37: cm
B38: Área de la varilla inferior | C38: Ab | D38: =INDEX(BAR_AS,MATCH($D$19,BAR_NOM,0)) | E38: cm²
B39: Diámetro del estribo | C39: dbe | D39: =INDEX(BAR_DB,MATCH($D$20,BAR_NOM,0)) | E39: cm
B40: Área del estribo | C40: Abe | D40: =INDEX(BAR_AS,MATCH($D$20,BAR_NOM,0)) | E40: cm²
B41: Factor β1 | C41: β1 | D41: =IF($D$11<=280,0.85,MAX(0.65,0.85-0.05*($D$11-280)/70))
B42: Cuantía balanceada | C42: ρb | D42: =0.85*$D$41*$D$11/$D$12*6000/(6000+$D$12)
B43: As mínimo 0.7·√f'c/fy·b·d | C43: Asmín | D43: =0.7*SQRT($D$11)/$D$12*$D$14*$D$34 | E43: cm² | F43: E.060 10.5.2
...

Sheet COLUMNA
B1: DISEÑO DE COLUMNA · FLEXOCOMPRESIÓN BIAXIAL · NTE E.060
B2: ALF_BIM · Plantilla Excel Estructuras · NTE E.060 Concreto Armado · v2.1.0
B3: Proyecto | C3: =INICIO!$D$7
B4: Ubicación | C4: =INICIO!$D$9
B5: Elemento | C5: Columna C-1, 1er piso, eje B-2
B6: Calculista | C6: =INICIO!$D$10&IF(INICIO!$D$11="",""," · CIP "&INICIO!$D$11) | AD6: Capas de acero (no imprimir)
B7: Fecha | C7: =INICIO!$D$12 | AD7: i | AE7: d X (cm) | AF7: As X | AG7: d Y (cm) | AH7: As Y | AK7: Diagrama X (no imprimir) | AU7: Diagrama Y (no imprimir)
AD8: 1 | AE8: =IF(1<=$D$19,$D$61+($D$15-2*$D$61)*(1-1)/($D$19-1),0) | AF8: =IF(1<=$D$19,IF(OR(1=1,1=$D$19),$D$18,2)*$D$53,0) | AG8: =IF(1<=$D$18,$D$61+($D$14-2*$D$61)*(1-1)/($D$18-1),0) | AH8: =IF(1<=$D$18,IF(OR(1=1,1=$D$18),$D$19,2)*$D$53,0) | AK8: c (cm) | AL8: a (cm) | AM8: Pn (t) | AN8: Mn (t·m) | AO8: φ | AP8: φPn (t) | AQ8: φMn (t·m) | AR8: −e (m) | AS8: φPn sin tope | AU8: c (cm) | AV8: a (cm) | AW8: Pn (t) | AX8: Mn (t·m) | AY8: φ | AZ8: φPn (t) | BA8: φMn (t·m) | BB8: −e (m) | BC8: φPn sin tope
AD9: 2 | AE9: =IF(2<=$D$19,$D$61+($D$15-2*$D$61)*(2-1)/($D$19-1),0) | AF9: =IF(2<=$D$19,IF(OR(2=1,2=$D$19),$D$18,2)*$D$53,0) | AG9: =IF(2<=$D$18,$D$61+($D$14-2*$D$61)*(2-1)/($D$18-1),0) | AH9: =IF(2<=$D$18,IF(OR(2=1,2=$D$18),$D$19,2)*$D$53,0) | AK9: 0 | AL9: 0 | AM9: =-$D$12*$D$57/1000 | AN9: 0 | AO9: 0.9 | AP9: =AO9*AM9 | AQ9: 0 | AR9: -1000000000 | AS9: =AP9 | AU9: 0 | AV9: 0 | AW9: =-$D$12*$D$57/1000 | AX9: 0 | AY9: 0.9 | AZ9: =AY9*AW9 | BA9: 0 | BB9: -1000000000 | BC9: =AZ9
B10: 1. DATOS DE ENTRADA | AD10: 3 | AE10: =IF(3<=$D$19,$D$61+($D$15-2*$D$61)*(3-1)/($D$19-1),0) | AF10: =IF(3<=$D$19,IF(OR(3=1,3=$D$19),$D$18,2)*$D$53,0) | AG10: =IF(3<=$D$18,$D$61+($D$14-2*$D$61)*(3-1)/($D$18-1),0) | AH10: =IF(3<=$D$18,IF(OR(3=1,3=$D$18),$D$19,2)*$D$53,0) | AK10: =0.02*$D$15 | AL10: =MIN($D$66*AK10,$D$15) | AM10: =(0.85*$D$11*AL10*$D$14+SUMPRODUCT($AF$8:$AF$17,(ABS(6000*(1-$AE$8:$AE$17/AK10)+$D$12)-ABS(6000*(1-$AE$8:$AE$17/AK10)-$D$12))/2-0.85*$D$11*($AE$8:$AE$17<AL10)))/1000 | AN10: =(0.85*$D$11*AL10*$D$14*($D$15/2-AL10/2)+SUMPRODUCT($AF$8:$AF$17,(ABS(6000*(1-$AE$8:$AE$17/AK10)+$D$12)-ABS(6000*(1-$AE$8:$AE$17/AK10)-$D$12))/2-0.85*$D$11*($AE$8:$AE$17<AL10),$D$15/2-$AE$8:$AE$17))/100000 | AO10: =IF(AM10<=0,0.9,MAX(0.7,0.9/(1+0.2*AM10/$D$71))) | AP10: =MIN(AO10*AM10,$D$68) | AQ10: =MAX(0,AO10*AN10) | AR10: =IF(AS10>0,-AQ10/AS10,-1E+9) | AS10: =AO10*AM10 | AU10: =0.02*$D$14 | AV10: =MIN($D$66*AU10,$D$14) | AW10: =(0.85*$D$11*AV10*$D$15+SUMPRODUCT($AH$8:$AH$17,(ABS(6000*(1-$AG$8:$AG$17/AU10)+$D$12)-ABS(6000*(1-$AG$8:$AG$17/AU10)-$D$12))/2-0.85*$D$11*($AG$8:$AG$17<AV10)))/1000 | AX10: =(0.85*$D$11*AV10*$D$15*($D$14/2-AV10/2)+SUMPRODUCT($AH$8:$AH$17,(ABS(6000*(1-$AG$8:$AG$17/AU10)+$D$12)-ABS(6000*(1-$AG$8:$AG$17/AU10)-$D$12))/2-0.85*$D$11*($AG$8:$AG$17<AV10),$D$14/2-$AG$8:$AG$17))/100000 | AY10: =IF(AW10<=0,0.9,MAX(0.7,0.9/(1+0.2*AW10/$D$72))) | AZ10: =MIN(AY10*AW10,$D$68) | BA10: =MAX(0,AY10*AX10) | BB10: =IF(BC10>0,-BA10/BC10,-1E+9) | BC10: =AY10*AW10
B11: Resistencia del concreto | C11: f'c | D11: 210 | E11: kgf/cm² | AD11: 4 | AE11: =IF(4<=$D$19,$D$61+($D$15-2*$D$61)*(4-1)/($D$19-1),0) | AF11: =IF(4<=$D$19,IF(OR(4=1,4=$D$19),$D$18,2)*$D$53,0) | AG11: =IF(4<=$D$18,$D$61+($D$14-2*$D$61)*(4-1)/($D$18-1),0) | AH11: =IF(4<=$D$18,IF(OR(4=1,4=$D$18),$D$19,2)*$D$53,0) | AK11: =0.04*$D$15 | AL11: =MIN($D$66*AK11,$D$15) | AM11: =(0.85*$D$11*AL11*$D$14+SUMPRODUCT($AF$8:$AF$17,(ABS(6000*(1-$AE$8:$AE$17/AK11)+$D$12)-ABS(6000*(1-$AE$8:$AE$17/AK11)-$D$12))/2-0.85*$D$11*($AE$8:$AE$17<AL11)))/1000 | AN11: =(0.85*$D$11*AL11*$D$14*($D$15/2-AL11/2)+SUMPRODUCT($AF$8:$AF$17,(ABS(6000*(1-$AE$8:$AE$17/AK11)+$D$12)-ABS(6000*(1-$AE$8:$AE$17/AK11)-$D$12))/2-0.85*$D$11*($AE$8:$AE$17<AL11),$D$15/2-$AE$8:$AE$17))/100000 | AO11: =IF(AM11<=0,0.9,MAX(0.7,0.9/(1+0.2*AM11/$D$71))) | AP11: =MIN(AO11*AM11,$D$68) | AQ11: =MAX(0,AO11*AN11) | AR11: =IF(AS11>0,-AQ11/AS11,-1E+9) | AS11: =AO11*AM11 | AU11: =0.04*$D$14 | AV11: =MIN($D$66*AU11,$D$14) | AW11: =(0.85*$D$11*AV11*$D$15+SUMPRODUCT($AH$8:$AH$17,(ABS(6000*(1-$AG$8:$AG$17/AU11)+$D$12)-ABS(6000*(1-$AG$8:$AG$17/AU11)-$D$12))/2-0.85*$D$11*($AG$8:$AG$17<AV11)))/1000 | AX11: =(0.85*$D$11*AV11*$D$15*($D$14/2-AV11/2)+SUMPRODUCT($AH$8:$AH$17,(ABS(6000*(1-$AG$8:$AG$17/AU11)+$D$12)-ABS(6000*(1-$AG$8:$AG$17/AU11)-$D$12))/2-0.85*$D$11*($AG$8:$AG$17<AV11),$D$14/2-$AG$8:$AG$17))/100000 | AY11: =IF(AW11<=0,0.9,MAX(0.7,0.9/(1+0.2*AW11/$D$72))) | AZ11: =MIN(AY11*AW11,$D$68) | BA11: =MAX(0,AY11*AX11) | BB11: =IF(BC11>0,-BA11/BC11,-1E+9) | BC11: =AY11*AW11
B12: Fluencia del acero | C12: fy | D12: 4200 | E12: kgf/cm² | AD12: 5 | AE12: =IF(5<=$D$19,$D$61+($D$15-2*$D$61)*(5-1)/($D$19-1),0) | AF12: =IF(5<=$D$19,IF(OR(5=1,5=$D$19),$D$18,2)*$D$53,0) | AG12: =IF(5<=$D$18,$D$61+($D$14-2*$D$61)*(5-1)/($D$18-1),0) | AH12: =IF(5<=$D$18,IF(OR(5=1,5=$D$18),$D$19,2)*$D$53,0) | AK12: =0.06*$D$15 | AL12: =MIN($D$66*AK12,$D$15) | AM12: =(0.85*$D$11*AL12*$D$14+SUMPRODUCT($AF$8:$AF$17,(ABS(6000*(1-$AE$8:$AE$17/AK12)+$D$12)-ABS(6000*(1-$AE$8:$AE$17/AK12)-$D$12))/2-0.85*$D$11*($AE$8:$AE$17<AL12)))/1000 | AN12: =(0.85*$D$11*AL12*$D$14*($D$15/2-AL12/2)+SUMPRODUCT($AF$8:$AF$17,(ABS(6000*(1-$AE$8:$AE$17/AK12)+$D$12)-ABS(6000*(1-$AE$8:$AE$17/AK12)-$D$12))/2-0.85*$D$11*($AE$8:$AE$17<AL12),$D$15/2-$AE$8:$AE$17))/100000 | AO12: =IF(AM12<=0,0.9,MAX(0.7,0.9/(1+0.2*AM12/$D$71))) | AP12: =MIN(AO12*AM12,$D$68) | AQ12: =MAX(0,AO12*AN12) | AR12: =IF(AS12>0,-AQ12/AS12,-1E+9) | AS12: =AO12*AM12 | AU12: =0.06*$D$14 | AV12: =MIN($D$66*AU12,$D$14) | AW12: =(0.85*$D$11*AV12*$D$15+SUMPRODUCT($AH$8:$AH$17,(ABS(6000*(1-$AG$8:$AG$17/AU12)+$D$12)-ABS(6000*(1-$AG$8:$AG$17/AU12)-$D$12))/2-0.85*$D$11*($AG$8:$AG$17<AV12)))/1000 | AX12: =(0.85*$D$11*AV12*$D$15*($D$14/2-AV12/2)+SUMPRODUCT($AH$8:$AH$17,(ABS(6000*(1-$AG$8:$AG$17/AU12)+$D$12)-ABS(6000*(1-$AG$8:$AG$17/AU12)-$D$12))/2-0.85*$D$11*($AG$8:$AG$17<AV12),$D$14/2-$AG$8:$AG$17))/100000 | AY12: =IF(AW12<=0,0.9,MAX(0.7,0.9/(1+0.2*AW12/$D$72))) | AZ12: =MIN(AY12*AW12,$D$68) | BA12: =MAX(0,AY12*AX12) | BB12: =IF(BC12>0,-BA12/BC12,-1E+9) | BC12: =AY12*AW12
B13: Sistema estructural (define el capítulo 21) | D13: Muros estructurales o dual tipo I | AD13: 6 | AE13: =IF(6<=$D$19,$D$61+($D$15-2*$D$61)*(6-1)/($D$19-1),0) | AF13: =IF(6<=$D$19,IF(OR(6=1,6=$D$19),$D$18,2)*$D$53,0) | AG13: =IF(6<=$D$18,$D$61+($D$14-2*$D$61)*(6-1)/($D$18-1),0) | AH13: =IF(6<=$D$18,IF(OR(6=1,6=$D$18),$D$19,2)*$D$53,0) | AK13: =0.08*$D$15 | AL13: =MIN($D$66*AK13,$D$15) | AM13: =(0.85*$D$11*AL13*$D$14+SUMPRODUCT($AF$8:$AF$17,(ABS(6000*(1-$AE$8:$AE$17/AK13)+$D$12)-ABS(6000*(1-$AE$8:$AE$17/AK13)-$D$12))/2-0.85*$D$11*($AE$8:$AE$17<AL13)))/1000 | AN13: =(0.85*$D$11*AL13*$D$14*($D$15/2-AL13/2)+SUMPRODUCT($AF$8:$AF$17,(ABS(6000*(1-$AE$8:$AE$17/AK13)+$D$12)-ABS(6000*(1-$AE$8:$AE$17/AK13)-$D$12))/2-0.85*$D$11*($AE$8:$AE$17<AL13),$D$15/2-$AE$8:$AE$17))/100000 | AO13: =IF(AM13<=0,0.9,MAX(0.7,0.9/(1+0.2*AM13/$D$71))) | AP13: =MIN(AO13*AM13,$D$68) | AQ13: =MAX(0,AO13*AN13) | AR13: =IF(AS13>0,-AQ13/AS13,-1E+9) | AS13: =AO13*AM13 | AU13: =0.08*$D$14 | AV13: =MIN($D$66*AU13,$D$14) | AW13: =(0.85*$D$11*AV13*$D$15+SUMPRODUCT($AH$8:$AH$17,(ABS(6000*(1-$AG$8:$AG$17/AU13)+$D$12)-ABS(6000*(1-$AG$8:$AG$17/AU13)-$D$12))/2-0.85*$D$11*($AG$8:$AG$17<AV13)))/1000 | AX13: =(0.85*$D$11*AV13*$D$15*($D$14/2-AV13/2)+SUMPRODUCT($AH$8:$AH$17,(ABS(6000*(1-$AG$8:$AG$17/AU13)+$D$12)-ABS(6000*(1-$AG$8:$AG$17/AU13)-$D$12))/2-0.85*$D$11*($AG$8:$AG$17<AV13),$D$14/2-$AG$8:$AG$17))/100000 | AY13: =IF(AW13<=0,0.9,MAX(0.7,0.9/(1+0.2*AW13/$D$72))) | AZ13: =MIN(AY13*AW13,$D$68) | BA13: =MAX(0,AY13*AX13) | BB13: =IF(BC13>0,-BA13/BC13,-1E+9) | BC13: =AY13*AW13
B14: Dimensión B (paralela al eje X) | C14: B | D14: 35 | E14: cm | AD14: 7 | AE14: =IF(7<=$D$19,$D$61+($D$15-2*$D$61)*(7-1)/($D$19-1),0) | AF14: =IF(7<=$D$19,IF(OR(7=1,7=$D$19),$D$18,2)*$D$53,0) | AG14: =IF(7<=$D$18,$D$61+($D$14-2*$D$61)*(7-1)/($D$18-1),0) | AH14: =IF(7<=$D$18,IF(OR(7=1,7=$D$18),$D$19,2)*$D$53,0) | AK14: =0.1*$D$15 | AL14: =MIN($D$66*AK14,$D$15) | AM14: =(0.85*$D$11*AL14*$D$14+SUMPRODUCT($AF$8:$AF$17,(ABS(6000*(1-$AE$8:$AE$17/AK14)+$D$12)-ABS(6000*(1-$AE$8:$AE$17/AK14)-$D$12))/2-0.85*$D$11*($AE$8:$AE$17<AL14)))/1000 | AN14: =(0.85*$D$11*AL14*$D$14*($D$15/2-AL14/2)+SUMPRODUCT($AF$8:$AF$17,(ABS(6000*(1-$AE$8:$AE$17/AK14)+$D$12)-ABS(6000*(1-$AE$8:$AE$17/AK14)-$D$12))/2-0.85*$D$11*($AE$8:$AE$17<AL14),$D$15/2-$AE$8:$AE$17))/100000 | AO14: =IF(AM14<=0,0.9,MAX(0.7,0.9/(1+0.2*AM14/$D$71))) | AP14: =MIN(AO14*AM14,$D$68) | AQ14: =MAX(0,AO14*AN14) | AR14: =IF(AS14>0,-AQ14/AS14,-1E+9) | AS14: =AO14*AM14 | AU14: =0.1*$D$14 | AV14: =MIN($D$66*AU14,$D$14) | AW14: =(0.85*$D$11*AV14*$D$15+SUMPRODUCT($AH$8:$AH$17,(ABS(6000*(1-$AG$8:$AG$17/AU14)+$D$12)-ABS(6000*(1-$AG$8:$AG$17/AU14)-$D$12))/2-0.85*$D$11*($AG$8:$AG$17<AV14)))/1000 | AX14: =(0.85*$D$11*AV14*$D$15*($D$14/2-AV14/2)+SUMPRODUCT($AH$8:$AH$17,(ABS(6000*(1-$AG$8:$AG$17/AU14)+$D$12)-ABS(6000*(1-$AG$8:$AG$17/AU14)-$D$12))/2-0.85*$D$11*($AG$8:$AG$17<AV14),$D$14/2-$AG$8:$AG$17))/100000 | AY14: =IF(AW14<=0,0.9,MAX(0.7,0.9/(1+0.2*AW14/$D$72))) | AZ14: =MIN(AY14*AW14,$D$68) | BA14: =MAX(0,AY14*AX14) | BB14: =IF(BC14>0,-BA14/BC14,-1E+9) | BC14: =AY14*AW14
B15: Dimensión H (paralela al eje Y) | C15: H | D15: 50 | E15: cm | AD15: 8 | AE15: =IF(8<=$D$19,$D$61+($D$15-2*$D$61)*(8-1)/($D$19-1),0) | AF15: =IF(8<=$D$19,IF(OR(8=1,8=$D$19),$D$18,2)*$D$53,0) | AG15: =IF(8<=$D$18,$D$61+($D$14-2*$D$61)*(8-1)/($D$18-1),0) | AH15: =IF(8<=$D$18,IF(OR(8=1,8=$D$18),$D$19,2)*$D$53,0) | AK15: =0.13*$D$15 | AL15: =MIN($D$66*AK15,$D$15) | AM15: =(0.85*$D$11*AL15*$D$14+SUMPRODUCT($AF$8:$AF$17,(ABS(6000*(1-$AE$8:$AE$17/AK15)+$D$12)-ABS(6000*(1-$AE$8:$AE$17/AK15)-$D$12))/2-0.85*$D$11*($AE$8:$AE$17<AL15)))/1000 | AN15: =(0.85*$D$11*AL15*$D$14*($D$15/2-AL15/2)+SUMPRODUCT($AF$8:$AF$17,(ABS(6000*(1-$AE$8:$AE$17/AK15)+$D$12)-ABS(6000*(1-$AE$8:$AE$17/AK15)-$D$12))/2-0.85*$D$11*($AE$8:$AE$17<AL15),$D$15/2-$AE$8:$AE$17))/100000 | AO15: =IF(AM15<=0,0.9,MAX(0.7,0.9/(1+0.2*AM15/$D$71))) | AP15: =MIN(AO15*AM15,$D$68) | AQ15: =MAX(0,AO15*AN15) | AR15: =IF(AS15>0,-AQ15/AS15,-1E+9) | AS15: =AO15*AM15 | AU15: =0.13*$D$14 | AV15: =MIN($D$66*AU15,$D$14) | AW15: =(0.85*$D$11*AV15*$D$15+SUMPRODUCT($AH$8:$AH$17,(ABS(6000*(1-$AG$8:$AG$17/AU15)+$D$12)-ABS(6000*(1-$AG$8:$AG$17/AU15)-$D$12))/2-0.85*$D$11*($AG$8:$AG$17<AV15)))/1000 | AX15: =(0.85*$D$11*AV15*$D$15*($D$14/2-AV15/2)+SUMPRODUCT($AH$8:$AH$17,(ABS(6000*(1-$AG$8:$AG$17/AU15)+$D$12)-ABS(6000*(1-$AG$8:$AG$17/AU15)-$D$12))/2-0.85*$D$11*($AG$8:$AG$17<AV15),$D$14/2-$AG$8:$AG$17))/100000 | AY15: =IF(AW15<=0,0.9,MAX(0.7,0.9/(1+0.2*AW15/$D$72))) | AZ15: =MIN(AY15*AW15,$D$68) | BA15: =MAX(0,AY15*AX15) | BB15: =IF(BC15>0,-BA15/BC15,-1E+9) | BC15: =AY15*AW15
B16: Recubrimiento libre | C16: r | D16: 4 | E16: cm | F16: E.060 7.7.1: columnas 4 cm | AD16: 9 | AE16: =IF(9<=$D$19,$D$61+($D$15-2*$D$61)*(9-1)/($D$19-1),0) | AF16: =IF(9<=$D$19,IF(OR(9=1,9=$D$19),$D$18,2)*$D$53,0) | AG16: =IF(9<=$D$18,$D$61+($D$14-2*$D$61)*(9-1)/($D$18-1),0) | AH16: =IF(9<=$D$18,IF(OR(9=1,9=$D$18),$D$19,2)*$D$53,0) | AK16: =0.16*$D$15 | AL16: =MIN($D$66*AK16,$D$15) | AM16: =(0.85*$D$11*AL16*$D$14+SUMPRODUCT($AF$8:$AF$17,(ABS(6000*(1-$AE$8:$AE$17/AK16)+$D$12)-ABS(6000*(1-$AE$8:$AE$17/AK16)-$D$12))/2-0.85*$D$11*($AE$8:$AE$17<AL16)))/1000 | AN16: =(0.85*$D$11*AL16*$D$14*($D$15/2-AL16/2)+SUMPRODUCT($AF$8:$AF$17,(ABS(6000*(1-$AE$8:$AE$17/AK16)+$D$12)-ABS(6000*(1-$AE$8:$AE$17/AK16)-$D$12))/2-0.85*$D$11*($AE$8:$AE$17<AL16),$D$15/2-$AE$8:$AE$17))/100000 | AO16: =IF(AM16<=0,0.9,MAX(0.7,0.9/(1+0.2*AM16/$D$71))) | AP16: =MIN(AO16*AM16,$D$68) | AQ16: =MAX(0,AO16*AN16) | AR16: =IF(AS16>0,-AQ16/AS16,-1E+9) | AS16: =AO16*AM16 | AU16: =0.16*$D$14 | AV16: =MIN($D$66*AU16,$D$14) | AW16: =(0.85*$D$11*AV16*$D$15+SUMPRODUCT($AH$8:$AH$17,(ABS(6000*(1-$AG$8:$AG$17/AU16)+$D$12)-ABS(6000*(1-$AG$8:$AG$17/AU16)-$D$12))/2-0.85*$D$11*($AG$8:$AG$17<AV16)))/1000 | AX16: =(0.85*$D$11*AV16*$D$15*($D$14/2-AV16/2)+SUMPRODUCT($AH$8:$AH$17,(ABS(6000*(1-$AG$8:$AG$17/AU16)+$D$12)-ABS(6000*(1-$AG$8:$AG$17/AU16)-$D$12))/2-0.85*$D$11*($AG$8:$AG$17<AV16),$D$14/2-$AG$8:$AG$17))/100000 | AY16: =IF(AW16<=0,0.9,MAX(0.7,0.9/(1+0.2*AW16/$D$72))) | AZ16: =MIN(AY16*AW16,$D$68) | BA16: =MAX(0,AY16*AX16) | BB16: =IF(BC16>0,-BA16/BC16,-1E+9) | BC16: =AY16*AW16
B17: Varilla longitudinal | C17: Ø | D17: 5/8" | AD17: 10 | AE17: =IF(10<=$D$19,$D$61+($D$15-2*$D$61)*(10-1)/($D$19-1),0) | AF17: =IF(10<=$D$19,IF(OR(10=1,10=$D$19),$D$18,2)*$D$53,0) | AG17: =IF(10<=$D$18,$D$61+($D$14-2*$D$61)*(10-1)/($D$18-1),0) | AH17: =IF(10<=$D$18,IF(OR(10=1,10=$D$18),$D$19,2)*$D$53,0) | AK17: =0.2*$D$15 | AL17: =MIN($D$66*AK17,$D$15) | AM17: =(0.85*$D$11*AL17*$D$14+SUMPRODUCT($AF$8:$AF$17,(ABS(6000*(1-$AE$8:$AE$17/AK17)+$D$12)-ABS(6000*(1-$AE$8:$AE$17/AK17)-$D$12))/2-0.85*$D$11*($AE$8:$AE$17<AL17)))/1000 | AN17: =(0.85*$D$11*AL17*$D$14*($D$15/2-AL17/2)+SUMPRODUCT($AF$8:$AF$17,(ABS(6000*(1-$AE$8:$AE$17/AK17)+$D$12)-ABS(6000*(1-$AE$8:$AE$17/AK17)-$D$12))/2-0.85*$D$11*($AE$8:$AE$17<AL17),$D$15/2-$AE$8:$AE$17))/100000 | AO17: =IF(AM17<=0,0.9,MAX(0.7,0.9/(1+0.2*AM17/$D$71))) | AP17: =MIN(AO17*AM17,$D$68) | AQ17: =MAX(0,AO17*AN17) | AR17: =IF(AS17>0,-AQ17/AS17,-1E+9) | AS17: =AO17*AM17 | AU17: =0.2*$D$14 | AV17: =MIN($D$66*AU17,$D$14) | AW17: =(0.85*$D$11*AV17*$D$15+SUMPRODUCT($AH$8:$AH$17,(ABS(6000*(1-$AG$8:$AG$17/AU17)+$D$12)-ABS(6000*(1-$AG$8:$AG$17/AU17)-$D$12))/2-0.85*$D$11*($AG$8:$AG$17<AV17)))/1000 | AX17: =(0.85*$D$11*AV17*$D$15*($D$14/2-AV17/2)+SUMPRODUCT($AH$8:$AH$17,(ABS(6000*(1-$AG$8:$AG$17/AU17)+$D$12)-ABS(6000*(1-$AG$8:$AG$17/AU17)-$D$12))/2-0.85*$D$11*($AG$8:$AG$17<AV17),$D$14/2-$AG$8:$AG$17))/100000 | AY17: =IF(AW17<=0,0.9,MAX(0.7,0.9/(1+0.2*AW17/$D$72))) | AZ17: =MIN(AY17*AW17,$D$68) | BA17: =MAX(0,AY17*AX17) | BB17: =IF(BC17>0,-BA17/BC17,-1E+9) | BC17: =AY17*AW17
B18: Varillas por cara paralela a X (incluye esquinas) | C18: nx | D18: 3 | F18: Cara de longitud B | AK18: =0.25*$D$15 | AL18: =MIN($D$66*AK18,$D$15) | AM18: =(0.85*$D$11*AL18*$D$14+SUMPRODUCT($AF$8:$AF$17,(ABS(6000*(1-$AE$8:$AE$17/AK18)+$D$12)-ABS(6000*(1-$AE$8:$AE$17/AK18)-$D$12))/2-0.85*$D$11*($AE$8:$AE$17<AL18)))/1000 | AN18: =(0.85*$D$11*AL18*$D$14*($D$15/2-AL18/2)+SUMPRODUCT($AF$8:$AF$17,(ABS(6000*(1-$AE$8:$AE$17/AK18)+$D$12)-ABS(6000*(1-$AE$8:$AE$17/AK18)-$D$12))/2-0.85*$D$11*($AE$8:$AE$17<AL18),$D$15/2-$AE$8:$AE$17))/100000 | AO18: =IF(AM18<=0,0.9,MAX(0.7,0.9/(1+0.2*AM18/$D$71))) | AP18: =MIN(AO18*AM18,$D$68) | AQ18: =MAX(0,AO18*AN18) | AR18: =IF(AS18>0,-AQ18/AS18,-1E+9) | AS18: =AO18*AM18 | AU18: =0.25*$D$14 | AV18: =MIN($D$66*AU18,$D$14) | AW18: =(0.85*$D$11*AV18*$D$15+SUMPRODUCT($AH$8:$AH$17,(ABS(6000*(1-$AG$8:$AG$17/AU18)+$D$12)-ABS(6000*(1-$AG$8:$AG$17/AU18)-$D$12))/2-0.85*$D$11*($AG$8:$AG$17<AV18)))/1000 | AX18: =(0.85*$D$11*AV18*$D$15*($D$14/2-AV18/2)+SUMPRODUCT($AH$8:$AH$17,(ABS(6000*(1-$AG$8:$AG$17/AU18)+$D$12)-ABS(6000*(1-$AG$8:$AG$17/AU18)-$D$12))/2-0.85*$D$11*($AG$8:$AG$17<AV18),$D$14/2-$AG$8:$AG$17))/100000 | AY18: =IF(AW18<=0,0.9,MAX(0.7,0.9/(1+0.2*AW18/$D$72))) | AZ18: =MIN(AY18*AW18,$D$68) | BA18: =MAX(0,AY18*AX18) | BB18: =IF(BC18>0,-BA18/BC18,-1E+9) | BC18: =AY18*AW18
B19: Varillas por cara paralela a Y (incluye esquinas) | C19: ny | D19: 4 | F19: Cara de longitud H | AK19: =0.3*$D$15 | AL19: =MIN($D$66*AK19,$D$15) | AM19: =(0.85*$D$11*AL19*$D$14+SUMPRODUCT($AF$8:$AF$17,(ABS(6000*(1-$AE$8:$AE$17/AK19)+$D$12)-ABS(6000*(1-$AE$8:$AE$17/AK19)-$D$12))/2-0.85*$D$11*($AE$8:$AE$17<AL19)))/1000 | AN19: =(0.85*$D$11*AL19*$D$14*($D$15/2-AL19/2)+SUMPRODUCT($AF$8:$AF$17,(ABS(6000*(1-$AE$8:$AE$17/AK19)+$D$12)-ABS(6000*(1-$AE$8:$AE$17/AK19)-$D$12))/2-0.85*$D$11*($AE$8:$AE$17<AL19),$D$15/2-$AE$8:$AE$17))/100000 | AO19: =IF(AM19<=0,0.9,MAX(0.7,0.9/(1+0.2*AM19/$D$71))) | AP19: =MIN(AO19*AM19,$D$68) | AQ19: =MAX(0,AO19*AN19) | AR19: =IF(AS19>0,-AQ19/AS19,-1E+9) | AS19: =AO19*AM19 | AU19: =0.3*$D$14 | AV19: =MIN($D$66*AU19,$D$14) | AW19: =(0.85*$D$11*AV19*$D$15+SUMPRODUCT($AH$8:$AH$17,(ABS(6000*(1-$AG$8:$AG$17/AU19)+$D$12)-ABS(6000*(1-$AG$8:$AG$17/AU19)-$D$12))/2-0.85*$D$11*($AG$8:$AG$17<AV19)))/1000 | AX19: =(0.85*$D$11*AV19*$D$15*($D$14/2-AV19/2)+SUMPRODUCT($AH$8:$AH$17,(ABS(6000*(1-$AG$8:$AG$17/AU19)+$D$12)-ABS(6000*(1-$AG$8:$AG$17/AU19)-$D$12))/2-0.85*$D$11*($AG$8:$AG$17<AV19),$D$14/2-$AG$8:$AG$17))/100000 | AY19: =IF(AW19<=0,0.9,MAX(0.7,0.9/(1+0.2*AW19/$D$72))) | AZ19: =MIN(AY19*AW19,$D$68) | BA19: =MAX(0,AY19*AX19) | BB19: =IF(BC19>0,-BA19/BC19,-1E+9) | BC19: =AY19*AW19
B20: Varilla del estribo | C20: Øe | D20: 3/8" | AK20: =0.35*$D$15 | AL20: =MIN($D$66*AK20,$D$15) | AM20: =(0.85*$D$11*AL20*$D$14+SUMPRODUCT($AF$8:$AF$17,(ABS(6000*(1-$AE$8:$AE$17/AK20)+$D$12)-ABS(6000*(1-$AE$8:$AE$17/AK20)-$D$12))/2-0.85*$D$11*($AE$8:$AE$17<AL20)))/1000 | AN20: =(0.85*$D$11*AL20*$D$14*($D$15/2-AL20/2)+SUMPRODUCT($AF$8:$AF$17,(ABS(6000*(1-$AE$8:$AE$17/AK20)+$D$12)-ABS(6000*(1-$AE$8:$AE$17/AK20)-$D$12))/2-0.85*$D$11*($AE$8:$AE$17<AL20),$D$15/2-$AE$8:$AE$17))/100000 | AO20: =IF(AM20<=0,0.9,MAX(0.7,0.9/(1+0.2*AM20/$D$71))) | AP20: =MIN(AO20*AM20,$D$68) | AQ20: =MAX(0,AO20*AN20) | AR20: =IF(AS20>0,-AQ20/AS20,-1E+9) | AS20: =AO20*AM20 | AU20: =0.35*$D$14 | AV20: =MIN($D$66*AU20,$D$14) | AW20: =(0.85*$D$11*AV20*$D$15+SUMPRODUCT($AH$8:$AH$17,(ABS(6000*(1-$AG$8:$AG$17/AU20)+$D$12)-ABS(6000*(1-$AG$8:$AG$17/AU20)-$D$12))/2-0.85*$D$11*($AG$8:$AG$17<AV20)))/1000 | AX20: =(0.85*$D$11*AV20*$D$15*($D$14/2-AV20/2)+SUMPRODUCT($AH$8:$AH$17,(ABS(6000*(1-$AG$8:$AG$17/AU20)+$D$12)-ABS(6000*(1-$AG$8:$AG$17/AU20)-$D$12))/2-0.85*$D$11*($AG$8:$AG$17<AV20),$D$14/2-$AG$8:$AG$17))/100000 | AY20: =IF(AW20<=0,0.9,MAX(0.7,0.9/(1+0.2*AW20/$D$72))) | AZ20: =MIN(AY20*AW20,$D$68) | BA20: =MAX(0,AY20*AX20) | BB20: =IF(BC20>0,-BA20/BC20,-1E+9) | BC20: =AY20*AW20
B21: Ramas paralelas a H (resisten cortante en Y) | C21: nY | D21: 2 | AK21: =0.375*$D$15 | AL21: =MIN($D$66*AK21,$D$15) | AM21: =(0.85*$D$11*AL21*$D$14+SUMPRODUCT($AF$8:$AF$17,(ABS(6000*(1-$AE$8:$AE$17/AK21)+$D$12)-ABS(6000*(1-$AE$8:$AE$17/AK21)-$D$12))/2-0.85*$D$11*($AE$8:$AE$17<AL21)))/1000 | AN21: =(0.85*$D$11*AL21*$D$14*($D$15/2-AL21/2)+SUMPRODUCT($AF$8:$AF$17,(ABS(6000*(1-$AE$8:$AE$17/AK21)+$D$12)-ABS(6000*(1-$AE$8:$AE$17/AK21)-$D$12))/2-0.85*$D$11*($AE$8:$AE$17<AL21),$D$15/2-$AE$8:$AE$17))/100000 | AO21: =IF(AM21<=0,0.9,MAX(0.7,0.9/(1+0.2*AM21/$D$71))) | AP21: =MIN(AO21*AM21,$D$68) | AQ21: =MAX(0,AO21*AN21) | AR21: =IF(AS21>0,-AQ21/AS21,-1E+9) | AS21: =AO21*AM21 | AU21: =0.375*$D$14 | AV21: =MIN($D$66*AU21,$D$14) | AW21: =(0.85*$D$11*AV21*$D$15+SUMPRODUCT($AH$8:$AH$17,(ABS(6000*(1-$AG$8:$AG$17/AU21)+$D$12)-ABS(6000*(1-$AG$8:$AG$17/AU21)-$D$12))/2-0.85*$D$11*($AG$8:$AG$17<AV21)))/1000 | AX21: =(0.85*$D$11*AV21*$D$15*($D$14/2-AV21/2)+SUMPRODUCT($AH$8:$AH$17,(ABS(6000*(1-$AG$8:$AG$17/AU21)+$D$12)-ABS(6000*(1-$AG$8:$AG$17/AU21)-$D$12))/2-0.85*$D$11*($AG$8:$AG$17<AV21),$D$14/2-$AG$8:$AG$17))/100000 | AY21: =IF(AW21<=0,0.9,MAX(0.7,0.9/(1+0.2*AW21/$D$72))) | AZ21: =MIN(AY21*AW21,$D$68) | BA21: =MAX(0,AY21*AX21) | BB21: =IF(BC21>0,-BA21/BC21,-1E+9) | BC21: =AY21*AW21
B22: Ramas paralelas a B (resisten cortante en X) | C22: nX | D22: 3 | F22: Incluye grapas | AK22: =0.4*$D$15 | AL22: =MIN($D$66*AK22,$D$15) | AM22: =(0.85*$D$11*AL22*$D$14+SUMPRODUCT($AF$8:$AF$17,(ABS(6000*(1-$AE$8:$AE$17/AK22)+$D$12)-ABS(6000*(1-$AE$8:$AE$17/AK22)-$D$12))/2-0.85*$D$11*($AE$8:$AE$17<AL22)))/1000 | AN22: =(0.85*$D$11*AL22*$D$14*($D$15/2-AL22/2)+SUMPRODUCT($AF$8:$AF$17,(ABS(6000*(1-$AE$8:$AE$17/AK22)+$D$12)-ABS(6000*(1-$AE$8:$AE$17/AK22)-$D$12))/2-0.85*$D$11*($AE$8:$AE$17<AL22),$D$15/2-$AE$8:$AE$17))/100000 | AO22: =IF(AM22<=0,0.9,MAX(0.7,0.9/(1+0.2*AM22/$D$71))) | AP22: =MIN(AO22*AM22,$D$68) | AQ22: =MAX(0,AO22*AN22) | AR22: =IF(AS22>0,-AQ22/AS22,-1E+9) | AS22: =AO22*AM22 | AU22: =0.4*$D$14 | AV22: =MIN($D$66*AU22,$D$14) | AW22: =(0.85*$D$11*AV22*$D$15+SUMPRODUCT($AH$8:$AH$17,(ABS(6000*(1-$AG$8:$AG$17/AU22)+$D$12)-ABS(6000*(1-$AG$8:$AG$17/AU22)-$D$12))/2-0.85*$D$11*($AG$8:$AG$17<AV22)))/1000 | AX22: =(0.85*$D$11*AV22*$D$15*($D$14/2-AV22/2)+SUMPRODUCT($AH$8:$AH$17,(ABS(6000*(1-$AG$8:$AG$17/AU22)+$D$12)-ABS(6000*(1-$AG$8:$AG$17/AU22)-$D$12))/2-0.85*$D$11*($AG$8:$AG$17<AV22),$D$14/2-$AG$8:$AG$17))/100000 | AY22: =IF(AW22<=0,0.9,MAX(0.7,0.9/(1+0.2*AW22/$D$72))) | AZ22: =MIN(AY22*AW22,$D$68) | BA22: =MAX(0,AY22*AX22) | BB22: =IF(BC22>0,-BA22/BC22,-1E+9) | BC22: =AY22*AW22
B23: Longitudes y esbeltez | AK23: =0.425*$D$15 | AL23: =MIN($D$66*AK23,$D$15) | AM23: =(0.85*$D$11*AL23*$D$14+SUMPRODUCT($AF$8:$AF$17,(ABS(6000*(1-$AE$8:$AE$17/AK23)+$D$12)-ABS(6000*(1-$AE$8:$AE$17/AK23)-$D$12))/2-0.85*$D$11*($AE$8:$AE$17<AL23)))/1000 | AN23: =(0.85*$D$11*AL23*$D$14*($D$15/2-AL23/2)+SUMPRODUCT($AF$8:$AF$17,(ABS(6000*(1-$AE$8:$AE$17/AK23)+$D$12)-ABS(6000*(1-$AE$8:$AE$17/AK23)-$D$12))/2-0.85*$D$11*($AE$8:$AE$17<AL23),$D$15/2-$AE$8:$AE$17))/100000 | AO23: =IF(AM23<=0,0.9,MAX(0.7,0.9/(1+0.2*AM23/$D$71))) | AP23: =MIN(AO23*AM23,$D$68) | AQ23: =MAX(0,AO23*AN23) | AR23: =IF(AS23>0,-AQ23/AS23,-1E+9) | AS23: =AO23*AM23 | AU23: =0.425*$D$14 | AV23: =MIN($D$66*AU23,$D$14) | AW23: =(0.85*$D$11*AV23*$D$15+SUMPRODUCT($AH$8:$AH$17,(ABS(6000*(1-$AG$8:$AG$17/AU23)+$D$12)-ABS(6000*(1-$AG$8:$AG$17/AU23)-$D$12))/2-0.85*$D$11*($AG$8:$AG$17<AV23)))/1000 | AX23: =(0.85*$D$11*AV23*$D$15*($D$14/2-AV23/2)+SUMPRODUCT($AH$8:$AH$17,(ABS(6000*(1-$AG$8:$AG$17/AU23)+$D$12)-ABS(6000*(1-$AG$8:$AG$17/AU23)-$D$12))/2-0.85*$D$11*($AG$8:$AG$17<AV23),$D$14/2-$AG$8:$AG$17))/100000 | AY23: =IF(AW23<=0,0.9,MAX(0.7,0.9/(1+0.2*AW23/$D$72))) | AZ23: =MIN(AY23*AW23,$D$68) | BA23: =MAX(0,AY23*AX23) | BB23: =IF(BC23>0,-BA23/BC23,-1E+9) | BC23: =AY23*AW23
B24: Luz libre de la columna | C24: hn | D24: 2.6 | E24: m | AK24: =0.45*$D$15 | AL24: =MIN($D$66*AK24,$D$15) | AM24: =(0.85*$D$11*AL24*$D$14+SUMPRODUCT($AF$8:$AF$17,(ABS(6000*(1-$AE$8:$AE$17/AK24)+$D$12)-ABS(6000*(1-$AE$8:$AE$17/AK24)-$D$12))/2-0.85*$D$11*($AE$8:$AE$17<AL24)))/1000 | AN24: =(0.85*$D$11*AL24*$D$14*($D$15/2-AL24/2)+SUMPRODUCT($AF$8:$AF$17,(ABS(6000*(1-$AE$8:$AE$17/AK24)+$D$12)-ABS(6000*(1-$AE$8:$AE$17/AK24)-$D$12))/2-0.85*$D$11*($AE$8:$AE$17<AL24),$D$15/2-$AE$8:$AE$17))/100000 | AO24: =IF(AM24<=0,0.9,MAX(0.7,0.9/(1+0.2*AM24/$D$71))) | AP24: =MIN(AO24*AM24,$D$68) | AQ24: =MAX(0,AO24*AN24) | AR24: =IF(AS24>0,-AQ24/AS24,-1E+9) | AS24: =AO24*AM24 | AU24: =0.45*$D$14 | AV24: =MIN($D$66*AU24,$D$14) | AW24: =(0.85*$D$11*AV24*$D$15+SUMPRODUCT($AH$8:$AH$17,(ABS(6000*(1-$AG$8:$AG$17/AU24)+$D$12)-ABS(6000*(1-$AG$8:$AG$17/AU24)-$D$12))/2-0.85*$D$11*($AG$8:$AG$17<AV24)))/1000 | AX24: =(0.85*$D$11*AV24*$D$15*($D$14/2-AV24/2)+SUMPRODUCT($AH$8:$AH$17,(ABS(6000*(1-$AG$8:$AG$17/AU24)+$D$12)-ABS(6000*(1-$AG$8:$AG$17/AU24)-$D$12))/2-0.85*$D$11*($AG$8:$AG$17<AV24),$D$14/2-$AG$8:$AG$17))/100000 | AY24: =IF(AW24<=0,0.9,MAX(0.7,0.9/(1+0.2*AW24/$D$72))) | AZ24: =MIN(AY24*AW24,$D$68) | BA24: =MAX(0,AY24*AX24) | BB24: =IF(BC24>0,-BA24/BC24,-1E+9) | BC24: =AY24*AW24
B25: Factor de longitud efectiva | C25: k | D25: 1 | F25: E.060 10.12.1: k = 1.0 si es arriostrada | AK25: =0.475*$D$15 | AL25: =MIN($D$66*AK25,$D$15) | AM25: =(0.85*$D$11*AL25*$D$14+SUMPRODUCT($AF$8:$AF$17,(ABS(6000*(1-$AE$8:$AE$17/AK25)+$D$12)-ABS(6000*(1-$AE$8:$AE$17/AK25)-$D$12))/2-0.85*$D$11*($AE$8:$AE$17<AL25)))/1000 | AN25: =(0.85*$D$11*AL25*$D$14*($D$15/2-AL25/2)+SUMPRODUCT($AF$8:$AF$17,(ABS(6000*(1-$AE$8:$AE$17/AK25)+$D$12)-ABS(6000*(1-$AE$8:$AE$17/AK25)-$D$12))/2-0.85*$D$11*($AE$8:$AE$17<AL25),$D$15/2-$AE$8:$AE$17))/100000 | AO25: =IF(AM25<=0,0.9,MAX(0.7,0.9/(1+0.2*AM25/$D$71))) | AP25: =MIN(AO25*AM25,$D$68) | AQ25: =MAX(0,AO25*AN25) | AR25: =IF(AS25>0,-AQ25/AS25,-1E+9) | AS25: =AO25*AM25 | AU25: =0.475*$D$14 | AV25: =MIN($D$66*AU25,$D$14) | AW25: =(0.85*$D$11*AV25*$D$15+SUMPRODUCT($AH$8:$AH$17,(ABS(6000*(1-$AG$8:$AG$17/AU25)+$D$12)-ABS(6000*(1-$AG$8:$AG$17/AU25)-$D$12))/2-0.85*$D$11*($AG$8:$AG$17<AV25)))/1000 | AX25: =(0.85*$D$11*AV25*$D$15*($D$14/2-AV25/2)+SUMPRODUCT($AH$8:$AH$17,(ABS(6000*(1-$AG$8:$AG$17/AU25)+$D$12)-ABS(6000*(1-$AG$8:$AG$17/AU25)-$D$12))/2-0.85*$D$11*($AG$8:$AG$17<AV25),$D$14/2-$AG$8:$AG$17))/100000 | AY25: =IF(AW25<=0,0.9,MAX(0.7,0.9/(1+0.2*AW25/$D$72))) | AZ25: =MIN(AY25*AW25,$D$68) | BA25: =MAX(0,AY25*AX25) | BB25: =IF(BC25>0,-BA25/BC25,-1E+9) | BC25: =AY25*AW25
B26: ¿Entrepiso arriostrado? (Q ≤ 0.06) | D26: Sí | F26: 10.11.4.2 | AK26: =0.5*$D$15 | AL26: =MIN($D$66*AK26,$D$15) | AM26: =(0.85*$D$11*AL26*$D$14+SUMPRODUCT($AF$8:$AF$17,(ABS(6000*(1-$AE$8:$AE$17/AK26)+$D$12)-ABS(6000*(1-$AE$8:$AE$17/AK26)-$D$12))/2-0.85*$D$11*($AE$8:$AE$17<AL26)))/1000 | AN26: =(0.85*$D$11*AL26*$D$14*($D$15/2-AL26/2)+SUMPRODUCT($AF$8:$AF$17,(ABS(6000*(1-$AE$8:$AE$17/AK26)+$D$12)-ABS(6000*(1-$AE$8:$AE$17/AK26)-$D$12))/2-0.85*$D$11*($AE$8:$AE$17<AL26),$D$15/2-$AE$8:$AE$17))/100000 | AO26: =IF(AM26<=0,0.9,MAX(0.7,0.9/(1+0.2*AM26/$D$71))) | AP26: =MIN(AO26*AM26,$D$68) | AQ26: =MAX(0,AO26*AN26) | AR26: =IF(AS26>0,-AQ26/AS26,-1E+9) | AS26: =AO26*AM26 | AU26: =0.5*$D$14 | AV26: =MIN($D$66*AU26,$D$14) | AW26: =(0.85*$D$11*AV26*$D$15+SUMPRODUCT($AH$8:$AH$17,(ABS(6000*(1-$AG$8:$AG$17/AU26)+$D$12)-ABS(6000*(1-$AG$8:$AG$17/AU26)-$D$12))/2-0.85*$D$11*($AG$8:$AG$17<AV26)))/1000 | AX26: =(0.85*$D$11*AV26*$D$15*($D$14/2-AV26/2)+SUMPRODUCT($AH$8:$AH$17,(ABS(6000*(1-$AG$8:$AG$17/AU26)+$D$12)-ABS(6000*(1-$AG$8:$AG$17/AU26)-$D$12))/2-0.85*$D$11*($AG$8:$AG$17<AV26),$D$14/2-$AG$8:$AG$17))/100000 | AY26: =IF(AW26<=0,0.9,MAX(0.7,0.9/(1+0.2*AW26/$D$72))) | AZ26: =MIN(AY26*AW26,$D$68) | BA26: =MAX(0,AY26*AX26) | BB26: =IF(BC26>0,-BA26/BC26,-1E+9) | BC26: =AY26*AW26
B27: Relación M1/M2 (+ curvatura simple, − doble) | C27: M1/M2 | D27: -0.5 | AK27: =0.525*$D$15 | AL27: =MIN($D$66*AK27,$D$15) | AM27: =(0.85*$D$11*AL27*$D$14+SUMPRODUCT($AF$8:$AF$17,(ABS(6000*(1-$AE$8:$AE$17/AK27)+$D$12)-ABS(6000*(1-$AE$8:$AE$17/AK27)-$D$12))/2-0.85*$D$11*($AE$8:$AE$17<AL27)))/1000 | AN27: =(0.85*$D$11*AL27*$D$14*($D$15/2-AL27/2)+SUMPRODUCT($AF$8:$AF$17,(ABS(6000*(1-$AE$8:$AE$17/AK27)+$D$12)-ABS(6000*(1-$AE$8:$AE$17/AK27)-$D$12))/2-0.85*$D$11*($AE$8:$AE$17<AL27),$D$15/2-$AE$8:$AE$17))/100000 | AO27: =IF(AM27<=0,0.9,MAX(0.7,0.9/(1+0.2*AM27/$D$71))) | AP27: =MIN(AO27*AM27,$D$68) | AQ27: =MAX(0,AO27*AN27) | AR27: =IF(AS27>0,-AQ27/AS27,-1E+9) | AS27: =AO27*AM27 | AU27: =0.525*$D$14 | AV27: =MIN($D$66*AU27,$D$14) | AW27: =(0.85*$D$11*AV27*$D$15+SUMPRODUCT($AH$8:$AH$17,(ABS(6000*(1-$AG$8:$AG$17/AU27)+$D$12)-ABS(6000*(1-$AG$8:$AG$17/AU27)-$D$12))/2-0.85*$D$11*($AG$8:$AG$17<AV27)))/1000 | AX27: =(0.85*$D$11*AV27*$D$15*($D$14/2-AV27/2)+SUMPRODUCT($AH$8:$AH$17,(ABS(6000*(1-$AG$8:$AG$17/AU27)+$D$12)-ABS(6000*(1-$AG$8:$AG$17/AU27)-$D$12))/2-0.85*$D$11*($AG$8:$AG$17<AV27),$D$14/2-$AG$8:$AG$17))/100000 | AY27: =IF(AW27<=0,0.9,MAX(0.7,0.9/(1+0.2*AW27/$D$72))) | AZ27: =MIN(AY27*AW27,$D$68) | BA27: =MAX(0,AY27*AX27) | BB27: =IF(BC27>0,-BA27/BC27,-1E+9) | BC27: =AY27*AW27
B28: Factor de carga sostenida βd | C28: βd | D28: 0.6 | F28: CM amplificada / carga axial amplificada total | AK28: =0.55*$D$15 | AL28: =MIN($D$66*AK28,$D$15) | AM28: =(0.85*$D$11*AL28*$D$14+SUMPRODUCT($AF$8:$AF$17,(ABS(6000*(1-$AE$8:$AE$17/AK28)+$D$12)-ABS(6000*(1-$AE$8:$AE$17/AK28)-$D$12))/2-0.85*$D$11*($AE$8:$AE$17<AL28)))/1000 | AN28: =(0.85*$D$11*AL28*$D$14*($D$15/2-AL28/2)+SUMPRODUCT($AF$8:$AF$17,(ABS(6000*(1-$AE$8:$AE$17/AK28)+$D$12)-ABS(6000*(1-$AE$8:$AE$17/AK28)-$D$12))/2-0.85*$D$11*($AE$8:$AE$17<AL28),$D$15/2-$AE$8:$AE$17))/100000 | AO28: =IF(AM28<=0,0.9,MAX(0.7,0.9/(1+0.2*AM28/$D$71))) | AP28: =MIN(AO28*AM28,$D$68) | AQ28: =MAX(0,AO28*AN28) | AR28: =IF(AS28>0,-AQ28/AS28,-1E+9) | AS28: =AO28*AM28 | AU28: =0.55*$D$14 | AV28: =MIN($D$66*AU28,$D$14) | AW28: =(0.85*$D$11*AV28*$D$15+SUMPRODUCT($AH$8:$AH$17,(ABS(6000*(1-$AG$8:$AG$17/AU28)+$D$12)-ABS(6000*(1-$AG$8:$AG$17/AU28)-$D$12))/2-0.85*$D$11*($AG$8:$AG$17<AV28)))/1000 | AX28: =(0.85*$D$11*AV28*$D$15*($D$14/2-AV28/2)+SUMPRODUCT($AH$8:$AH$17,(ABS(6000*(1-$AG$8:$AG$17/AU28)+$D$12)-ABS(6000*(1-$AG$8:$AG$17/AU28)-$D$12))/2-0.85*$D$11*($AG$8:$AG$17<AV28),$D$14/2-$AG$8:$AG$17))/100000 | AY28: =IF(AW28<=0,0.9,MAX(0.7,0.9/(1+0.2*AW28/$D$72))) | AZ28: =MIN(AY28*AW28,$D$68) | BA28: =MAX(0,AY28*AX28) | BB28: =IF(BC28>0,-BA28/BC28,-1E+9) | BC28: =AY28*AW28
B29: Índice de estabilidad Q (no arriostrado) | C29: Q | D29: 0.04 | F29: De ETABS: ΣPu·Δo/(Vus·he); Δo × 0.75R | AK29: =0.575*$D$15 | AL29: =MIN($D$66*AK29,$D$15) | AM29: =(0.85*$D$11*AL29*$D$14+SUMPRODUCT($AF$8:$AF$17,(ABS(6000*(1-$AE$8:$AE$17/AK29)+$D$12)-ABS(6000*(1-$AE$8:$AE$17/AK29)-$D$12))/2-0.85*$D$11*($AE$8:$AE$17<AL29)))/1000 | AN29: =(0.85*$D$11*AL29*$D$14*($D$15/2-AL29/2)+SUMPRODUCT($AF$8:$AF$17,(ABS(6000*(1-$AE$8:$AE$17/AK29)+$D$12)-ABS(6000*(1-$AE$8:$AE$17/AK29)-$D$12))/2-0.85*$D$11*($AE$8:$AE$17<AL29),$D$15/2-$AE$8:$AE$17))/100000 | AO29: =IF(AM29<=0,0.9,MAX(0.7,0.9/(1+0.2*AM29/$D$71))) | AP29: =MIN(AO29*AM29,$D$68) | AQ29: =MAX(0,AO29*AN29) | AR29: =IF(AS29>0,-AQ29/AS29,-1E+9) | AS29: =AO29*AM29 | AU29: =0.575*$D$14 | AV29: =MIN($D$66*AU29,$D$14) | AW29: =(0.85*$D$11*AV29*$D$15+SUMPRODUCT($AH$8:$AH$17,(ABS(6000*(1-$AG$8:$AG$17/AU29)+$D$12)-ABS(6000*(1-$AG$8:$AG$17/AU29)-$D$12))/2-0.85*$D$11*($AG$8:$AG$17<AV29)))/1000 | AX29: =(0.85*$D$11*AV29*$D$15*($D$14/2-AV29/2)+SUMPRODUCT($AH$8:$AH$17,(ABS(6000*(1-$AG$8:$AG$17/AU29)+$D$12)-ABS(6000*(1-$AG$8:$AG$17/AU29)-$D$12))/2-0.85*$D$11*($AG$8:$AG$17<AV29),$D$14/2-$AG$8:$AG$17))/100000 | AY29: =IF(AW29<=0,0.9,MAX(0.7,0.9/(1+0.2*AW29/$D$72))) | AZ29: =MIN(AY29*AW29,$D$68) | BA29: =MAX(0,AY29*AX29) | BB29: =IF(BC29>0,-BA29/BC29,-1E+9) | BC29: =AY29*AW29
B30: Columna fuerte – viga débil (solo pórticos y dual tipo II, 21.6.2.2) | AK30: =0.6*$D$15 | AL30: =MIN($D$66*AK30,$D$15) | AM30: =(0.85*$D$11*AL30*$D$14+SUMPRODUCT($AF$8:$AF$17,(ABS(6000*(1-$AE$8:$AE$17/AK30)+$D$12)-ABS(6000*(1-$AE$8:$AE$17/AK30)-$D$12))/2-0.85*$D$11*($AE$8:$AE$17<AL30)))/1000 | AN30: =(0.85*$D$11*AL30*$D$14*($D$15/2-AL30/2)+SUMPRODUCT($AF$8:$AF$17,(ABS(6000*(1-$AE$8:$AE$17/AK30)+$D$12)-ABS(6000*(1-$AE$8:$AE$17/AK30)-$D$12))/2-0.85*$D$11*($AE$8:$AE$17<AL30),$D$15/2-$AE$8:$AE$17))/100000 | AO30: =IF(AM30<=0,0.9,MAX(0.7,0.9/(1+0.2*AM30/$D$71))) | AP30: =MIN(AO30*AM30,$D$68) | AQ30: =MAX(0,AO30*AN30) | AR30: =IF(AS30>0,-AQ30/AS30,-1E+9) | AS30: =AO30*AM30 | AU30: =0.6*$D$14 | AV30: =MIN($D$66*AU30,$D$14) | AW30: =(0.85*$D$11*AV30*$D$15+SUMPRODUCT($AH$8:$AH$17,(ABS(6000*(1-$AG$8:$AG$17/AU30)+$D$12)-ABS(6000*(1-$AG$8:$AG$17/AU30)-$D$12))/2-0.85*$D$11*($AG$8:$AG$17<AV30)))/1000 | AX30: =(0.85*$D$11*AV30*$D$15*($D$14/2-AV30/2)+SUMPRODUCT($AH$8:$AH$17,(ABS(6000*(1-$AG$8:$AG$17/AU30)+$D$12)-ABS(6000*(1-$AG$8:$AG$17/AU30)-$D$12))/2-0.85*$D$11*($AG$8:$AG$17<AV30),$D$14/2-$AG$8:$AG$17))/100000 | AY30: =IF(AW30<=0,0.9,MAX(0.7,0.9/(1+0.2*AW30/$D$72))) | AZ30: =MIN(AY30*AW30,$D$68) | BA30: =MAX(0,AY30*AX30) | BB30: =IF(BC30>0,-BA30/BC30,-1E+9) | BC30: =AY30*AW30
B31: Suma de Mn de las vigas que llegan al nudo, flexión en X | C31: ΣMnv | D31: 35 | E31: t·m | F31: Mn− de un lado + Mn+ del otro (hoja VIGA: φMn/0.9) | AK31: =0.625*$D$15 | AL31: =MIN($D$66*AK31,$D$15) | AM31: =(0.85*$D$11*AL31*$D$14+SUMPRODUCT($AF$8:$AF$17,(ABS(6000*(1-$AE$8:$AE$17/AK31)+$D$12)-ABS(6000*(1-$AE$8:$AE$17/AK31)-$D$12))/2-0.85*$D$11*($AE$8:$AE$17<AL31)))/1000 | AN31: =(0.85*$D$11*AL31*$D$14*($D$15/2-AL31/2)+SUMPRODUCT($AF$8:$AF$17,(ABS(6000*(1-$AE$8:$AE$17/AK31)+$D$12)-ABS(6000*(1-$AE$8:$AE$17/AK31)-$D$12))/2-0.85*$D$11*($AE$8:$AE$17<AL31),$D$15/2-$AE$8:$AE$17))/100000 | AO31: =IF(AM31<=0,0.9,MAX(0.7,0.9/(1+0.2*AM31/$D$71))) | AP31: =MIN(AO31*AM31,$D$68) | AQ31: =MAX(0,AO31*AN31) | AR31: =IF(AS31>0,-AQ31/AS31,-1E+9) | AS31: =AO31*AM31 | AU31: =0.625*$D$14 | AV31: =MIN($D$66*AU31,$D$14) | AW31: =(0.85*$D$11*AV31*$D$15+SUMPRODUCT($AH$8:$AH$17,(ABS(6000*(1-$AG$8:$AG$17/AU31)+$D$12)-ABS(6000*(1-$AG$8:$AG$17/AU31)-$D$12))/2-0.85*$D$11*($AG$8:$AG$17<AV31)))/1000 | AX31: =(0.85*$D$11*AV31*$D$15*($D$14/2-AV31/2)+SUMPRODUCT($AH$8:$AH$17,(ABS(6000*(1-$AG$8:$AG$17/AU31)+$D$12)-ABS(6000*(1-$AG$8:$AG$17/AU31)-$D$12))/2-0.85*$D$11*($AG$8:$AG$17<AV31),$D$14/2-$AG$8:$AG$17))/100000 | AY31: =IF(AW31<=0,0.9,MAX(0.7,0.9/(1+0.2*AW31/$D$72))) | AZ31: =MIN(AY31*AW31,$D$68) | BA31: =MAX(0,AY31*AX31) | BB31: =IF(BC31>0,-BA31/BC31,-1E+9) | BC31: =AY31*AW31
B32: Suma de Mn de las vigas que llegan al nudo, flexión en Y | C32: ΣMnv | D32: 20 | E32: t·m | AK32: =0.65*$D$15 | AL32: =MIN($D$66*AK32,$D$15) | AM32: =(0.85*$D$11*AL32*$D$14+SUMPRODUCT($AF$8:$AF$17,(ABS(6000*(1-$AE$8:$AE$17/AK32)+$D$12)-ABS(6000*(1-$AE$8:$AE$17/AK32)-$D$12))/2-0.85*$D$11*($AE$8:$AE$17<AL32)))/1000 | AN32: =(0.85*$D$11*AL32*$D$14*($D$15/2-AL32/2)+SUMPRODUCT($AF$8:$AF$17,(ABS(6000*(1-$AE$8:$AE$17/AK32)+$D$12)-ABS(6000*(1-$AE$8:$AE$17/AK32)-$D$12))/2-0.85*$D$11*($AE$8:$AE$17<AL32),$D$15/2-$AE$8:$AE$17))/100000 | AO32: =IF(AM32<=0,0.9,MAX(0.7,0.9/(1+0.2*AM32/$D$71))) | AP32: =MIN(AO32*AM32,$D$68) | AQ32: =MAX(0,AO32*AN32) | AR32: =IF(AS32>0,-AQ32/AS32,-1E+9) | AS32: =AO32*AM32 | AU32: =0.65*$D$14 | AV32: =MIN($D$66*AU32,$D$14) | AW32: =(0.85*$D$11*AV32*$D$15+SUMPRODUCT($AH$8:$AH$17,(ABS(6000*(1-$AG$8:$AG$17/AU32)+$D$12)-ABS(6000*(1-$AG$8:$AG$17/AU32)-$D$12))/2-0.85*$D$11*($AG$8:$AG$17<AV32)))/1000 | AX32: =(0.85*$D$11*AV32*$D$15*($D$14/2-AV32/2)+SUMPRODUCT($AH$8:$AH$17,(ABS(6000*(1-$AG$8:$AG$17/AU32)+$D$12)-ABS(6000*(1-$AG$8:$AG$17/AU32)-$D$12))/2-0.85*$D$11*($AG$8:$AG$17<AV32),$D$14/2-$AG$8:$AG$17))/100000 | AY32: =IF(AW32<=0,0.9,MAX(0.7,0.9/(1+0.2*AW32/$D$72))) | AZ32: =MIN(AY32*AW32,$D$68) | BA32: =MAX(0,AY32*AX32) | BB32: =IF(BC32>0,-BA32/BC32,-1E+9) | BC32: =AY32*AW32
B33: Cortantes del análisis (t) | AK33: =0.675*$D$15 | AL33: =MIN($D$66*AK33,$D$15) | AM33: =(0.85*$D$11*AL33*$D$14+SUMPRODUCT($AF$8:$AF$17,(ABS(6000*(1-$AE$8:$AE$17/AK33)+$D$12)-ABS(6000*(1-$AE$8:$AE$17/AK33)-$D$12))/2-0.85*$D$11*($AE$8:$AE$17<AL33)))/1000 | AN33: =(0.85*$D$11*AL33*$D$14*($D$15/2-AL33/2)+SUMPRODUCT($AF$8:$AF$17,(ABS(6000*(1-$AE$8:$AE$17/AK33)+$D$12)-ABS(6000*(1-$AE$8:$AE$17/AK33)-$D$12))/2-0.85*$D$11*($AE$8:$AE$17<AL33),$D$15/2-$AE$8:$AE$17))/100000 | AO33: =IF(AM33<=0,0.9,MAX(0.7,0.9/(1+0.2*AM33/$D$71))) | AP33: =MIN(AO33*AM33,$D$68) | AQ33: =MAX(0,AO33*AN33) | AR33: =IF(AS33>0,-AQ33/AS33,-1E+9) | AS33: =AO33*AM33 | AU33: =0.675*$D$14 | AV33: =MIN($D$66*AU33,$D$14) | AW33: =(0.85*$D$11*AV33*$D$15+SUMPRODUCT($AH$8:$AH$17,(ABS(6000*(1-$AG$8:$AG$17/AU33)+$D$12)-ABS(6000*(1-$AG$8:$AG$17/AU33)-$D$12))/2-0.85*$D$11*($AG$8:$AG$17<AV33)))/1000 | AX33: =(0.85*$D$11*AV33*$D$15*($D$14/2-AV33/2)+SUMPRODUCT($AH$8:$AH$17,(ABS(6000*(1-$AG$8:$AG$17/AU33)+$D$12)-ABS(6000*(1-$AG$8:$AG$17/AU33)-$D$12))/2-0.85*$D$11*($AG$8:$AG$17<AV33),$D$14/2-$AG$8:$AG$17))/100000 | AY33: =IF(AW33<=0,0.9,MAX(0.7,0.9/(1+0.2*AW33/$D$72))) | AZ33: =MIN(AY33*AW33,$D$68) | BA33: =MAX(0,AY33*AX33) | BB33: =IF(BC33>0,-BA33/BC33,-1E+9) | BC33: =AY33*AW33
B34: Cortante último en Y (máx. envolvente) | C34: VuY | D34: 6 | E34: t | F34: Asociado a Mux | AK34: =0.7*$D$15 | AL34: =MIN($D$66*AK34,$D$15) | AM34: =(0.85*$D$11*AL34*$D$14+SUMPRODUCT($AF$8:$AF$17,(ABS(6000*(1-$AE$8:$AE$17/AK34)+$D$12)-ABS(6000*(1-$AE$8:$AE$17/AK34)-$D$12))/2-0.85*$D$11*($AE$8:$AE$17<AL34)))/1000 | AN34: =(0.85*$D$11*AL34*$D$14*($D$15/2-AL34/2)+SUMPRODUCT($AF$8:$AF$17,(ABS(6000*(1-$AE$8:$AE$17/AK34)+$D$12)-ABS(6000*(1-$AE$8:$AE$17/AK34)-$D$12))/2-0.85*$D$11*($AE$8:$AE$17<AL34),$D$15/2-$AE$8:$AE$17))/100000 | AO34: =IF(AM34<=0,0.9,MAX(0.7,0.9/(1+0.2*AM34/$D$71))) | AP34: =MIN(AO34*AM34,$D$68) | AQ34: =MAX(0,AO34*AN34) | AR34: =IF(AS34>0,-AQ34/AS34,-1E+9) | AS34: =AO34*AM34 | AU34: =0.7*$D$14 | AV34: =MIN($D$66*AU34,$D$14) | AW34: =(0.85*$D$11*AV34*$D$15+SUMPRODUCT($AH$8:$AH$17,(ABS(6000*(1-$AG$8:$AG$17/AU34)+$D$12)-ABS(6000*(1-$AG$8:$AG$17/AU34)-$D$12))/2-0.85*$D$11*($AG$8:$AG$17<AV34)))/1000 | AX34: =(0.85*$D$11*AV34*$D$15*($D$14/2-AV34/2)+SUMPRODUCT($AH$8:$AH$17,(ABS(6000*(1-$AG$8:$AG$17/AU34)+$D$12)-ABS(6000*(1-$AG$8:$AG$17/AU34)-$D$12))/2-0.85*$D$11*($AG$8:$AG$17<AV34),$D$14/2-$AG$8:$AG$17))/100000 | AY34: =IF(AW34<=0,0.9,MAX(0.7,0.9/(1+0.2*AW34/$D$72))) | AZ34: =MIN(AY34*AW34,$D$68) | BA34: =MAX(0,AY34*AX34) | BB34: =IF(BC34>0,-BA34/BC34,-1E+9) | BC34: =AY34*AW34
B35: Cortante de sismo puro en Y | C35: VSY | D35: 3.5 | E35: t | AK35: =0.75*$D$15 | AL35: =MIN($D$66*AK35,$D$15) | AM35: =(0.85*$D$11*AL35*$D$14+SUMPRODUCT($AF$8:$AF$17,(ABS(6000*(1-$AE$8:$AE$17/AK35)+$D$12)-ABS(6000*(1-$AE$8:$AE$17/AK35)-$D$12))/2-0.85*$D$11*($AE$8:$AE$17<AL35)))/1000 | AN35: =(0.85*$D$11*AL35*$D$14*($D$15/2-AL35/2)+SUMPRODUCT($AF$8:$AF$17,(ABS(6000*(1-$AE$8:$AE$17/AK35)+$D$12)-ABS(6000*(1-$AE$8:$AE$17/AK35)-$D$12))/2-0.85*$D$11*($AE$8:$AE$17<AL35),$D$15/2-$AE$8:$AE$17))/100000 | AO35: =IF(AM35<=0,0.9,MAX(0.7,0.9/(1+0.2*AM35/$D$71))) | AP35: =MIN(AO35*AM35,$D$68) | AQ35: =MAX(0,AO35*AN35) | AR35: =IF(AS35>0,-AQ35/AS35,-1E+9) | AS35: =AO35*AM35 | AU35: =0.75*$D$14 | AV35: =MIN($D$66*AU35,$D$14) | AW35: =(0.85*$D$11*AV35*$D$15+SUMPRODUCT($AH$8:$AH$17,(ABS(6000*(1-$AG$8:$AG$17/AU35)+$D$12)-ABS(6000*(1-$AG$8:$AG$17/AU35)-$D$12))/2-0.85*$D$11*($AG$8:$AG$17<AV35)))/1000 | AX35: =(0.85*$D$11*AV35*$D$15*($D$14/2-AV35/2)+SUMPRODUCT($AH$8:$AH$17,(ABS(6000*(1-$AG$8:$AG$17/AU35)+$D$12)-ABS(6000*(1-$AG$8:$AG$17/AU35)-$D$12))/2-0.85*$D$11*($AG$8:$AG$17<AV35),$D$14/2-$AG$8:$AG$17))/100000 | AY35: =IF(AW35<=0,0.9,MAX(0.7,0.9/(1+0.2*AW35/$D$72))) | AZ35: =MIN(AY35*AW35,$D$68) | BA35: =MAX(0,AY35*AX35) | BB35: =IF(BC35>0,-BA35/BC35,-1E+9) | BC35: =AY35*AW35
B36: Cortante último en X (máx. envolvente) | C36: VuX | D36: 4 | E36: t | F36: Asociado a Muy | AK36: =0.8*$D$15 | AL36: =MIN($D$66*AK36,$D$15) | AM36: =(0.85*$D$11*AL36*$D$14+SUMPRODUCT($AF$8:$AF$17,(ABS(6000*(1-$AE$8:$AE$17/AK36)+$D$12)-ABS(6000*(1-$AE$8:$AE$17/AK36)-$D$12))/2-0.85*$D$11*($AE$8:$AE$17<AL36)))/1000 | AN36: =(0.85*$D$11*AL36*$D$14*($D$15/2-AL36/2)+SUMPRODUCT($AF$8:$AF$17,(ABS(6000*(1-$AE$8:$AE$17/AK36)+$D$12)-ABS(6000*(1-$AE$8:$AE$17/AK36)-$D$12))/2-0.85*$D$11*($AE$8:$AE$17<AL36),$D$15/2-$AE$8:$AE$17))/100000 | AO36: =IF(AM36<=0,0.9,MAX(0.7,0.9/(1+0.2*AM36/$D$71))) | AP36: =MIN(AO36*AM36,$D$68) | AQ36: =MAX(0,AO36*AN36) | AR36: =IF(AS36>0,-AQ36/AS36,-1E+9) | AS36: =AO36*AM36 | AU36: =0.8*$D$14 | AV36: =MIN($D$66*AU36,$D$14) | AW36: =(0.85*$D$11*AV36*$D$15+SUMPRODUCT($AH$8:$AH$17,(ABS(6000*(1-$AG$8:$AG$17/AU36)+$D$12)-ABS(6000*(1-$AG$8:$AG$17/AU36)-$D$12))/2-0.85*$D$11*($AG$8:$AG$17<AV36)))/1000 | AX36: =(0.85*$D$11*AV36*$D$15*($D$14/2-AV36/2)+SUMPRODUCT($AH$8:$AH$17,(ABS(6000*(1-$AG$8:$AG$17/AU36)+$D$12)-ABS(6000*(1-$AG$8:$AG$17/AU36)-$D$12))/2-0.85*$D$11*($AG$8:$AG$17<AV36),$D$14/2-$AG$8:$AG$17))/100000 | AY36: =IF(AW36<=0,0.9,MAX(0.7,0.9/(1+0.2*AW36/$D$72))) | AZ36: =MIN(AY36*AW36,$D$68) | BA36: =MAX(0,AY36*AX36) | BB36: =IF(BC36>0,-BA36/BC36,-1E+9) | BC36: =AY36*AW36
B37: Cortante de sismo puro en X | C37: VSX | D37: 2.5 | E37: t | AK37: =0.85*$D$15 | AL37: =MIN($D$66*AK37,$D$15) | AM37: =(0.85*$D$11*AL37*$D$14+SUMPRODUCT($AF$8:$AF$17,(ABS(6000*(1-$AE$8:$AE$17/AK37)+$D$12)-ABS(6000*(1-$AE$8:$AE$17/AK37)-$D$12))/2-0.85*$D$11*($AE$8:$AE$17<AL37)))/1000 | AN37: =(0.85*$D$11*AL37*$D$14*($D$15/2-AL37/2)+SUMPRODUCT($AF$8:$AF$17,(ABS(6000*(1-$AE$8:$AE$17/AK37)+$D$12)-ABS(6000*(1-$AE$8:$AE$17/AK37)-$D$12))/2-0.85*$D$11*($AE$8:$AE$17<AL37),$D$15/2-$AE$8:$AE$17))/100000 | AO37: =IF(AM37<=0,0.9,MAX(0.7,0.9/(1+0.2*AM37/$D$71))) | AP37: =MIN(AO37*AM37,$D$68) | AQ37: =MAX(0,AO37*AN37) | AR37: =IF(AS37>0,-AQ37/AS37,-1E+9) | AS37: =AO37*AM37 | AU37: =0.85*$D$14 | AV37: =MIN($D$66*AU37,$D$14) | AW37: =(0.85*$D$11*AV37*$D$15+SUMPRODUCT($AH$8:$AH$17,(ABS(6000*(1-$AG$8:$AG$17/AU37)+$D$12)-ABS(6000*(1-$AG$8:$AG$17/AU37)-$D$12))/2-0.85*$D$11*($AG$8:$AG$17<AV37)))/1000 | AX37: =(0.85*$D$11*AV37*$D$15*($D$14/2-AV37/2)+SUMPRODUCT($AH$8:$AH$17,(ABS(6000*(1-$AG$8:$AG$17/AU37)+$D$12)-ABS(6000*(1-$AG$8:$AG$17/AU37)-$D$12))/2-0.85*$D$11*($AG$8:$AG$17<AV37),$D$14/2-$AG$8:$AG$17))/100000 | AY37: =IF(AW37<=0,0.9,MAX(0.7,0.9/(1+0.2*AW37/$D$72))) | AZ37: =MIN(AY37*AW37,$D$68) | BA37: =MAX(0,AY37*AX37) | BB37: =IF(BC37>0,-BA37/BC37,-1E+9) | BC37: =AY37*AW37
B38: Combinaciones de diseño: Mux gira alrededor del eje X (la flexión comprime una cara de longitud B) | AK38: =0.9*$D$15 | AL38: =MIN($D$66*AK38,$D$15) | AM38: =(0.85*$D$11*AL38*$D$14+SUMPRODUCT($AF$8:$AF$17,(ABS(6000*(1-$AE$8:$AE$17/AK38)+$D$12)-ABS(6000*(1-$AE$8:$AE$17/AK38)-$D$12))/2-0.85*$D$11*($AE$8:$AE$17<AL38)))/1000 | AN38: =(0.85*$D$11*AL38*$D$14*($D$15/2-AL38/2)+SUMPRODUCT($AF$8:$AF$17,(ABS(6000*(1-$AE$8:$AE$17/AK38)+$D$12)-ABS(6000*(1-$AE$8:$AE$17/AK38)-$D$12))/2-0.85*$D$11*($AE$8:$AE$17<AL38),$D$15/2-$AE$8:$AE$17))/100000 | AO38: =IF(AM38<=0,0.9,MAX(0.7,0.9/(1+0.2*AM38/$D$71))) | AP38: =MIN(AO38*AM38,$D$68) | AQ38: =MAX(0,AO38*AN38) | AR38: =IF(AS38>0,-AQ38/AS38,-1E+9) | AS38: =AO38*AM38 | AU38: =0.9*$D$14 | AV38: =MIN($D$66*AU38,$D$14) | AW38: =(0.85*$D$11*AV38*$D$15+SUMPRODUCT($AH$8:$AH$17,(ABS(6000*(1-$AG$8:$AG$17/AU38)+$D$12)-ABS(6000*(1-$AG$8:$AG$17/AU38)-$D$12))/2-0.85*$D$11*($AG$8:$AG$17<AV38)))/1000 | AX38: =(0.85*$D$11*AV38*$D$15*($D$14/2-AV38/2)+SUMPRODUCT($AH$8:$AH$17,(ABS(6000*(1-$AG$8:$AG$17/AU38)+$D$12)-ABS(6000*(1-$AG$8:$AG$17/AU38)-$D$12))/2-0.85*$D$11*($AG$8:$AG$17<AV38),$D$14/2-$AG$8:$AG$17))/100000 | AY38: =IF(AW38<=0,0.9,MAX(0.7,0.9/(1+0.2*AW38/$D$72))) | AZ38: =MIN(AY38*AW38,$D$68) | BA38: =MAX(0,AY38*AX38) | BB38: =IF(BC38>0,-BA38/BC38,-1E+9) | BC38: =AY38*AW38
B39: Combinación | C39: Pu (t) | D39: Mux (t·m) | E39: Muy (t·m) | F39: φMnx (t·m) | G39: φMny (t·m) | H39: D/C | AK39: =0.95*$D$15 | AL39: =MIN($D$66*AK39,$D$15) | AM39: =(0.85*$D$11*AL39*$D$14+SUMPRODUCT($AF$8:$AF$17,(ABS(6000*(1-$AE$8:$AE$17/AK39)+$D$12)-ABS(6000*(1-$AE$8:$AE$17/AK39)-$D$12))/2-0.85*$D$11*($AE$8:$AE$17<AL39)))/1000 | AN39: =(0.85*$D$11*AL39*$D$14*($D$15/2-AL39/2)+SUMPRODUCT($AF$8:$AF$17,(ABS(6000*(1-$AE$8:$AE$17/AK39)+$D$12)-ABS(6000*(1-$AE$8:$AE$17/AK39)-$D$12))/2-0.85*$D$11*($AE$8:$AE$17<AL39),$D$15/2-$AE$8:$AE$17))/100000 | AO39: =IF(AM39<=0,0.9,MAX(0.7,0.9/(1+0.2*AM39/$D$71))) | AP39: =MIN(AO39*AM39,$D$68) | AQ39: =MAX(0,AO39*AN39) | AR39: =IF(AS39>0,-AQ39/AS39,-1E+9) | AS39: =AO39*AM39 | AU39: =0.95*$D$14 | AV39: =MIN($D$66*AU39,$D$14) | AW39: =(0.85*$D$11*AV39*$D$15+SUMPRODUCT($AH$8:$AH$17,(ABS(6000*(1-$AG$8:$AG$17/AU39)+$D$12)-ABS(6000*(1-$AG$8:$AG$17/AU39)-$D$12))/2-0.85*$D$11*($AG$8:$AG$17<AV39)))/1000 | AX39: =(0.85*$D$11*AV39*$D$15*($D$14/2-AV39/2)+SUMPRODUCT($AH$8:$AH$17,(ABS(6000*(1-$AG$8:$AG$17/AU39)+$D$12)-ABS(6000*(1-$AG$8:$AG$17/AU39)-$D$12))/2-0.85*$D$11*($AG$8:$AG$17<AV39),$D$14/2-$AG$8:$AG$17))/100000 | AY39: =IF(AW39<=0,0.9,MAX(0.7,0.9/(1+0.2*AW39/$D$72))) | AZ39: =MIN(AY39*AW39,$D$68) | BA39: =MAX(0,AY39*AX39) | BB39: =IF(BC39>0,-BA39/BC39,-1E+9) | BC39: =AY39*AW39 | BE39: |Mux|c | BF39: |Muy|c | BG39: iX | BH39: iY | BI39: φMnx | BJ39: φMny | BK39: eX | BL39: eY | BM39: jX | BN39: jY | BO39: φPnx | BP39: φPny | BQ39: φPni | BR39: D/C | BS39: δx | BT39: δy | BU39: Mnx | BV39: Mny
B40: 1.4CM + 1.7CV | C40: 145 | D40: 3 | E40: 1.5 | F40: =BI40 | G40: =BJ40 | H40: =BR40 | AK40: =1.0*$D$15 | AL40: =MIN($D$66*AK40,$D$15) | AM40: =(0.85*$D$11*AL40*$D$14+SUMPRODUCT($AF$8:$AF$17,(ABS(6000*(1-$AE$8:$AE$17/AK40)+$D$12)-ABS(6000*(1-$AE$8:$AE$17/AK40)-$D$12))/2-0.85*$D$11*($AE$8:$AE$17<AL40)))/1000 | AN40: =(0.85*$D$11*AL40*$D$14*($D$15/2-AL40/2)+SUMPRODUCT($AF$8:$AF$17,(ABS(6000*(1-$AE$8:$AE$17/AK40)+$D$12)-ABS(6000*(1-$AE$8:$AE$17/AK40)-$D$12))/2-0.85*$D$11*($AE$8:$AE$17<AL40),$D$15/2-$AE$8:$AE$17))/100000 | AO40: =IF(AM40<=0,0.9,MAX(0.7,0.9/(1+0.2*AM40/$D$71))) | AP40: =MIN(AO40*AM40,$D$68) | AQ40: =MAX(0,AO40*AN40) | AR40: =IF(AS40>0,-AQ40/AS40,-1E+9) | AS40: =AO40*AM40 | AU40: =1.0*$D$14 | AV40: =MIN($D$66*AU40,$D$14) | AW40: =(0.85*$D$11*AV40*$D$15+SUMPRODUCT($AH$8:$AH$17,(ABS(6000*(1-$AG$8:$AG$17/AU40)+$D$12)-ABS(6000*(1-$AG$8:$AG$17/AU40)-$D$12))/2-0.85*$D$11*($AG$8:$AG$17<AV40)))/1000 | AX40: =(0.85*$D$11*AV40*$D$15*($D$14/2-AV40/2)+SUMPRODUCT($AH$8:$AH$17,(ABS(6000*(1-$AG$8:$AG$17/AU40)+$D$12)-ABS(6000*(1-$AG$8:$AG$17/AU40)-$D$12))/2-0.85*$D$11*($AG$8:$AG$17<AV40),$D$14/2-$AG$8:$AG$17))/100000 | AY40: =IF(AW40<=0,0.9,MAX(0.7,0.9/(1+0.2*AW40/$D$72))) | AZ40: =MIN(AY40*AW40,$D$68) | BA40: =MAX(0,AY40*AX40) | BB40: =IF(BC40>0,-BA40/BC40,-1E+9) | BC40: =AY40*AW40 | BE40: =BS40*IF(AND($D$74>=$D$73,$D$26="Sí"),MAX(ABS($D$40),MAX(0,$C$40)*(1.5+0.03*$D$15)/100),ABS($D$40)) | BF40: =BT40*IF(AND($D$75>=$D$73,$D$26="Sí"),MAX(ABS($E$40),MAX(0,$C$40)*(1.5+0.03*$D$14)/100),ABS($E$40)) | BG40: =IFERROR(MATCH($C$40,$AP$9:$AP$48,1),0) | BH40: =IFERROR(MATCH($C$40,$AZ$9:$AZ$48,1),0) | BI40: =IF(BG40<=0,INDEX($AQ$9:$AQ$48,1),IF(BG40>=40,INDEX($AQ$9:$AQ$48,40),INDEX($AQ$9:$AQ$48,BG40)+(INDEX($AQ$9:$AQ$48,BG40+1)-INDEX($AQ$9:$AQ$48,BG40))*($C$40-INDEX($AP$9:$AP$48,BG40))/MAX(1E-9,INDEX($AP$9:$AP$48,BG40+1)-INDEX($AP$9:$AP$48,BG40)))) | BJ40: =IF(BH40<=0,INDEX($BA$9:$BA$48,1),IF(BH40>=40,INDEX($BA$9:$BA$48,40),INDEX($BA$9:$BA$48,BH40)+(INDEX($BA$9:$BA$48,BH40+1)-INDEX($BA$9:$BA$48,BH40))*($C$40-INDEX($AZ$9:$AZ$48,BH40))/MAX(1E-9,INDEX($AZ$9:$AZ$48,BH40+1)-INDEX($AZ$9:$AZ$48,BH40)))) | BK40: =IF($C$40>0,BE40/$C$40,0) | BL40: =IF($C$40>0,BF40/$C$40,0) | BM40: =IFERROR(MATCH(-BK40,$AR$9:$AR$48,1),0) | BN40: =IFERROR(MATCH(-BL40,$BB$9:$BB$48,1),0) | BO40: =IF(BM40<=0,INDEX($AS$9:$AS$48,1),IF(BM40>=40,INDEX($AS$9:$AS$48,40),INDEX($AS$9:$AS$48,BM40)+(INDEX($AS$9:$AS$48,BM40+1)-INDEX($AS$9:$AS$48,BM40))*(-BK40-INDEX($AR$9:$AR$48,BM40))/MAX(1E-9,INDEX($AR$9:$AR$48,BM40+1)-INDEX($AR$9:$AR$48,BM40)))) | BP40: =IF(BN40<=0,INDEX($BC$9:$BC$48,1),IF(BN40>=40,INDEX($BC$9:$BC$48,40),INDEX($BC$9:$BC$48,BN40)+(INDEX($BC$9:$BC$48,BN40+1)-INDEX($BC$9:$BC$48,BN40))*(-BL40-INDEX($BB$9:$BB$48,BN40))/MAX(1E-9,INDEX($BB$9:$BB$48,BN40+1)-INDEX($BB$9:$BB$48,BN40)))) | BQ40: =IFERROR(1/(1/BO40+1/BP40-1/(0.7*$D$67)),0.0001) | BR40: =IF(AND($C$40=0,$D$40=0,$E$40=0),0,IF($C$40>$D$68,99,IF($C$40>=0.1*$D$11*$D$58/1000,$C$40/MAX(0.0001,MIN(BQ40,$D$68)),BE40/MAX(0.0001,BI40)+BF40/MAX(0.0001,BJ40)))) | BS40: =IF($D$74<$D$73,1,IF($D$26="Sí",IF($C$40>=0.75*$D$77,99,MAX(1,$D$79/(1-MAX(0,$C$40)/(0.75*$D$77)))),$D$80)) | BT40: =IF($D$75<$D$73,1,IF($D$26="Sí",IF($C$40>=0.75*$D$78,99,MAX(1,$D$79/(1-MAX(0,$C$40)/(0.75*$D$78)))),$D$80)) | BU40: =IF(IFERROR(MATCH($C$40,$AM$9:$AM$48,1),0)<=0,INDEX($AN$9:$AN$48,1),IF(IFERROR(MATCH($C$40,$AM$9:$AM$48,1),0)>=40,INDEX($AN$9:$AN$48,40),INDEX($AN$9:$AN$48,IFERROR(MATCH($C$40,$AM$9:$AM$48,1),0))+(INDEX($AN$9:$AN$48,IFERROR(MATCH($C$40,$AM$9:$AM$48,1),0)+1)-INDEX($AN$9:$AN$48,IFERROR(MATCH($C$40,$AM$9:$AM$48,1),0)))*($C$40-INDEX($AM$9:$AM$48,IFERROR(MATCH($C$40,$AM$9:$AM$48,1),0)))/MAX(1E-9,INDEX($AM$9:$AM$48,IFERROR(MATCH($C$40,$AM$9:$AM$48,1),0)+1)-INDEX($AM$9:$AM$48,IFERROR(MATCH($C$40,$AM$9:$AM$48,1),0))))) | BV40: =IF(IFERROR(MATCH($C$40,$AW$9:$AW$48,1),0)<=0,INDEX($AX$9:$AX$48,1),IF(IFERROR(MATCH($C$40,$AW$9:$AW$48,1),0)>=40,INDEX($AX$9:$AX$48,40),INDEX($AX$9:$AX$48,IFERROR(MATCH($C$40,$AW$9:$AW$48,1),0))+(INDEX($AX$9:$AX$48,IFERROR(MATCH($C$40,$AW$9:$AW$48,1),0)+1)-INDEX($AX$9:$AX$48,IFERROR(MATCH($C$40,$AW$9:$AW$48,1),0)))*($C$40-INDEX($AW$9:$AW$48,IFERROR(MATCH($C$40,$AW$9:$AW$48,1),0)))/MAX(1E-9,INDEX($AW$9:$AW$48,IFERROR(MATCH($C$40,$AW$9:$AW$48,1),0)+1)-INDEX($AW$9:$AW$48,IFERROR(MATCH($C$40,$AW$9:$AW$48,1),0)))))
...

Sheet PLACA
B1: DISEÑO DE PLACA (MURO ESTRUCTURAL) · NTE E.060 11.10 Y 21.9
B2: ALF_BIM · Plantilla Excel Estructuras · NTE E.060 Concreto Armado · v2.1.0
B3: Proyecto | C3: =INICIO!$D$7
B4: Ubicación | C4: =INICIO!$D$9
B5: Elemento | C5: Placa PL-1, 1er piso, eje 1
B6: Calculista | C6: =INICIO!$D$10&IF(INICIO!$D$11="",""," · CIP "&INICIO!$D$11) | AD6: Capas (no imprimir)
B7: Fecha | C7: =INICIO!$D$12 | AH7: Diagrama (no imprimir)
AD8: 1 | AE8: =$D$43 | AF8: =$D$26/2*$D$39 | AH8: c (cm) | AI8: a (cm) | AJ8: Pn (t) | AK8: Mn (t·m) | AL8: φ | AM8: φPn (t) | AN8: φMn (t·m) | AO8: −e (m) | AP8: φPn sin tope | BB8: =$D$20 | BC8: =$D$19
AD9: 2 | AE9: =$D$25-$D$43 | AF9: =$D$26/2*$D$39 | AH9: 0 | AI9: 0 | AJ9: =-$D$12*$D$47/1000 | AK9: 0 | AL9: 0.9 | AM9: =AL9*AJ9 | AN9: 0 | AO9: -1000000000 | AP9: =AM9
B10: 1. DATOS DE ENTRADA | AD10: 3 | AE10: =IF(1<=$D$46,$D$25+$D$44*1/($D$46+1),0) | AF10: =IF(1<=$D$46,$D$45*$D$32*$D$40/$D$46,0) | AH10: =0.02*$D$36 | AI10: =MIN($D$49*AH10,$D$36) | AJ10: =(0.85*$D$11*AI10*$D$14+SUMPRODUCT($AF$8:$AF$37,(ABS(6000*(1-$AE$8:$AE$37/AH10)+$D$12)-ABS(6000*(1-$AE$8:$AE$37/AH10)-$D$12))/2-0.85*$D$11*($AE$8:$AE$37<AI10)))/1000 | AK10: =(0.85*$D$11*AI10*$D$14*($D$36/2-AI10/2)+SUMPRODUCT($AF$8:$AF$37,(ABS(6000*(1-$AE$8:$AE$37/AH10)+$D$12)-ABS(6000*(1-$AE$8:$AE$37/AH10)-$D$12))/2-0.85*$D$11*($AE$8:$AE$37<AI10),$D$36/2-$AE$8:$AE$37))/100000 | AL10: =IF(AJ10<=0,0.9,MAX(0.7,0.9/(1+0.2*AJ10/$D$54))) | AM10: =MIN(AL10*AJ10,$D$51) | AN10: =MAX(0,AL10*AK10) | AO10: =IF(AP10>0,-AN10/AP10,-1E+9) | AP10: =AL10*AJ10
